Workbook

Sheet IndiceC
A1: INDICE DE CUADROS
A3: =+EstMuestra!A1 -> CUADRO 1: CARACTERIZACION DE LA POBLACION Y LA MUESTRA
A4: =+Error!A1 -> CUADRO 2: NIVELES DE ERROR DE LAS ESTIMACIONES
A5: =+RatxHoraxLD!A1 -> CUADRO 3: RESUMEN DE RATING POR HORA | AM | LUNES A DOMINGO
A6: =+RatxHoraxLD!A34 -> CUADRO 4: RESUMEN DE RATING POR HORA | FM | LUNES A DOMINGO
A7: =+RatxHoraxLV!A1 -> CUADRO 5: RESUMEN DE RATING POR HORA | AM | LUNES A VIERNES
A8: =+RatxHoraxLV!A34 -> CUADRO 6: RESUMEN DE RATING POR HORA | FM | LUNES A VIERNES
A9: =+RatxHoraxSD!A1 -> CUADRO 7: RESUMEN DE RATING POR HORA | AM | SABADO A DOMINGO
A10: =+RatxHoraxSD!A34 -> CUADRO 8: RESUMEN DE RATING POR HORA | FM | SABADO A DOMINGO
A11: =+RatxLDxABC1!A1 -> CUADRO 9: RESUMEN DE RATING POR HORA - SEGMENTO ABC1 | AM | LUNES A DOMINGO
A12: =+RatxLDxABC1!A34 -> CUADRO 10: RESUMEN DE RATING POR HORA - SEGMENTO ABC1 | FM | LUNES A DOMINGO
A13: =+RatxLDxC2C3D1!A1 -> CUADRO 11: RESUMEN DE RATING POR HORA - SEGMENTO C2C3D1 | AM | LUNES A DOMINGO
A14: =+RatxLDxC2C3D1!A34 -> CUADRO 12: RESUMEN DE RATING POR HORA - SEGMENTO C2C3D1 | FM | LUNES A DOMINGO
A15: =+RatxLDxD2E!A1 -> CUADRO 13: RESUMEN DE RATING POR HORA - SEGMENTO D2E | AM | LUNES A DOMINGO
A16: =+RatxLDxD2E!A34 -> CUADRO 14: RESUMEN DE RATING POR HORA - SEGMENTO D2E | FM | LUNES A DOMINGO
A17: =+RatxNSE!A1 -> CUADROS 15 - 17: RESUMEN DE RATING POR NIVEL SOCIOECONÓMICO | AM
A18: =+RatxNSE!A34 -> CUADROS 18 - 20: RESUMEN DE RATING POR NIVEL SOCIOECONÓMICO | FM
A19: =+RatxEdad!A1 -> CUADROS 21 - 23: RESUMEN DE RATING POR EDAD | AM
A20: =+RatxEdad!A34 -> CUADROS 24 - 26: RESUMEN DE RATING POR EDAD | FM
A21: =+RatxSexo!A1 -> CUADROS 27 - 28: RESUMEN DE RATING POR SEXO | AM - FM
A22: =+RatxLugar!A1 -> CUADRO 29: RESUMEN DE RATING POR LUGAR DE ESCUCHA
A23: =+Cobertura!A1 -> CUADRO 30: COBERTURA SEMANAL POR NIVEL SOCIOECONÓMICO, EDAD Y SEXO | AM | LUNES A DOMINGO
A24: =+Cobertura!A34 -> CUADRO 31: COBERTURA SEMANAL POR NIVEL SOCIOECONÓMICO, EDAD Y SEXO | FM | LUNES A DOMINGO
A25: =+ShaxHoraxLD!A1 -> CUADRO 32: RESUMEN DE SHARE POR HORA | AM | LUNES A DOMINGO
A26: =+ShaxHoraxLD!A34 -> CUADRO 33: RESUMEN DE SHARE POR HORA | FM | LUNES A DOMINGO
A27: =+SharexHoraxLV!A1 -> CUADRO 34: RESUMEN DE SHARE POR HORA | AM | LUNES A VIERNES
A28: =+SharexHoraxLV!A33 -> CUADRO 35: RESUMEN DE SHARE POR HORA | FM | LUNES A VIERNES
A29: =+SharexHoraxSD!A1 -> CUADRO 36: RESUMEN DE SHARE POR HORA | AM | SABADO A DOMINGO
A30: =+SharexHoraxSD!A33 -> CUADRO 37: RESUMEN DE SHARE POR HORA | FM | SABADO A DOMINGO
A31: =+AudienciaxLD!A1 -> CUADRO 38: RESUMEN DE AUDIENCIA POR HORA | AM | LUNES A DOMINGO
A32: =+AudienciaxLD!A34 -> CUADRO 39: RESUMEN DE AUDIENCIA POR HORA | FM | LUNES A DOMINGO
A33: =+AudienciaxLV!A1 -> CUADRO 40: RESUMEN DE AUDIENCIA POR HORA | AM | LUNES A VIERNES
A34: =+AudienciaxLV!A34 -> CUADRO 41: RESUMEN DE AUDIENCIA POR HORA | FM | LUNES A VIERNES
A35: =+AudienciaxSD!A1 -> CUADRO 42: RESUMEN DE AUDIENCIA POR HORA | AM | SABADO A DOMINGO
A36: =+AudienciaxSD!A34 -> CUADRO 43: RESUMEN DE AUDIENCIA POR HORA | FM | SABADO A DOMINGO
A37: =+Perfil!A1 -> CUADRO 44: PERFIL DE AUDIENCIA POR NIVEL SOCIOECONOMICO, EDAD Y SEXO | AM - FM | LUNES A DOMINGO
A38: =+Perfil!A35 -> CUADRO 45: PERFIL DE AUDIENCIA POR NIVEL SOCIOECONOMICO, EDAD Y SEXO | AM - FM | LUNES A VIERNES
A39: =+Perfil!A69 -> CUADRO 46: PERFIL DE AUDIENCIA POR NIVEL SOCIOECONOMICO, EDAD Y SEXO | AM - FM | SABADO A DOMINGO
A40: =+RatxAMxRxD!A1 -> CUADRO 47: RESUMEN DE RATING POR HORA SEGUN RADIO Y DIA | AM
A41: =+RatxAMxRxD!A78 -> CUADRO 48: RESUMEN DE RATING POR HORA SEGUN RADIO Y DIA | AM (CONTINUACION)
...

Sheet InidiceG
A1: INDICE DE GRAFICOS
A3: =+GraxRAM!A1 -> PANEL 1: RESUMEN DE RATING Y COBERTURA | AM
A4: =+GraxRAMxNSE!A1 -> PANEL 2: RESUMEN DE RATING POR NSE | AM | LUNES A DOMINGO | 00:00 - 24:00
A5: =+GraxRFM!A1 -> PANEL 3: RESUMEN DE RATING Y COBERTURA | FM
A6: =+GraxRFMxNSE!A1 -> PANEL 4: RESUMEN DE RATING POR NSE | FM | LUNES A DOMINGO | 00:00 - 24:00
A7: =+EncxLug!A1 -> PANEL 5: RESUMEN DE ENCENDIDO POR LUGAR DE ESCUCHA
A8: =+CrvEncAMxLD!$A$1 -> CURVAS DE ENCENDIDO | AM | LUNES A DOMINGO
A9: =+CrvEncAMxLV!$A$1 -> CURVAS DE ENCENDIDO | AM | LUNES A VIERNES
A10: =+CrvEncAMxSD!A1 -> CURVAS DE ENCENDIDO | AM | SABADO A DOMINGO
A11: =+CrvEncFMxLD!A1 -> CURVAS DE ENCENDIDO | FM | LUNES A DOMINGO
A12: =+CrvEncFMxLV!A1 -> CURVAS DE ENCENDIDO | FM | LUNES A VIERNES
A13: =+CrvEncFMxSD!A1 -> CURVAS DE ENCENDIDO | FM | SABADO A DOMINGO

Sheet EstMuestra
A1: CUADRO 1: CARACTERIZACION DE LA POBLACION Y LA MUESTRA
A3: DIMENSION | B3: POBLACION | D3: MUESTRA
B4: TOTAL | C4: % | D4: TOTAL | E4: % | F4: PANEL | G4: % | H4: ROTATIVA | I4: %
A5: ZONA | B5: 1311422 | C5: 100.04377 | D5: 2503 | E5: 100 | F5: 1239 | G5: 100 | H5: 1264 | I5: 100
A6: Montevideo | B6: 1099709 | C6: 83.9 | D6: 2170 | E6: 86.695965 | F6: 1054 | G6: 85.068604 | H6: 1116 | I6: 88.291139
A7: Estrato 1 | B7: 189149.95 | C7: 17.2 | D7: 447 | E7: 17.85857 | F7: 182 | G7: 14.689266 | H7: 265 | I7: 20.96519
A8: Estrato 2 | B8: 199047.33 | C8: 18.1 | D8: 468 | E8: 18.697563 | F8: 253 | G8: 20.419693 | H8: 215 | I8: 17.009494
A9: Estrato 3 | B9: 236437.43 | C9: 21.5 | D9: 604 | E9: 24.131043 | F9: 290 | G9: 23.405973 | H9: 314 | I9: 24.841772
A10: Estrato 4 | B10: 197947.62 | C10: 18 | D10: 438 | E10: 17.499001 | F10: 218 | G10: 17.594835 | H10: 220 | I10: 17.405063
A11: Estrato 5 | B11: 100073.52 | C11: 9.1 | D11: 213 | E11: 8.5097883 | F11: 111 | G11: 8.9588378 | H11: 102 | I11: 8.0696203
A12: A. Metropolitana | B12: 211713 | C12: 16.143774 | D12: 333 | E12: 13.304035 | F12: 185 | G12: 14.931396 | H12: 148 | I12: 11.708861
A13: C. Costa | B13: 92561 | C13: 7.0580637 | D13: 156 | E13: 6.232521 | F13: 61 | G13: 4.9233253 | H13: 95 | I13: 7.5158228
A14: Las Piedras | B14: 56773 | C14: 4.3291176 | D14: 82 | E14: 3.2760687 | F14: 65 | G14: 5.2461663 | H14: 17 | I14: 1.3449367
A15: C. Plata | B15: 24292 | C15: 1.8523404 | D15: 38 | E15: 1.5181782 | F15: 20 | G15: 1.614205 | H15: 18 | I15: 1.4240506
A16: Pando | B16: 21240 | C16: 1.619616 | D16: 31 | E16: 1.2385138 | F16: 17 | G16: 1.3720743 | H16: 14 | I16: 1.1075949
... A35: B- | B35: 70126.98 | C35: 5.3474 | D35: 198 | E35: 7.9105074 | F35: 96 | G35: 7.748184 | H35: 102 | I35: 8.0696203

Sheet Error
A1: CUADRO 2: NIVELES DE ERROR DE LAS ESTIMACIONES
A2: 95 % DE CONFIANZA
A4: DISEÑO* | B4: MUESTRA | G4: RATING DIARIO
B5: TOTAL | C5: DIARIA | D5: ROTATIVA | E5: PANEL | F5: COEF. CORREL.
G6: 0.005 | H6: 0.01 | I6: 0.02 | J6: 0.03 | K6: 0.05 | L6: 0.1 | M6: 0.15 | N6: 0.2
A7: ANTERIOR TRANSV. | B7: 2503 | C7: 357.57143 | D7: 357.57143 | E7: 0 | F7: 0.89 | G7: 0.0073109062 | H7: 0.010313172 | I7: 0.014511179 | J7: 0.017681584 | K7: 0.022590273 | L7: 0.031095384 | M7: 0.03701091 | N7: 0.041460512
A8: ACTUAL DE PANEL | B8: 2503 | C8: 1419.5714 | D8: 180.57143 | E8: 1239 | F8: 0.887 | G8: 0.0035031477 | H8: 0.0049417355 | I8: 0.0069532835 | J8: 0.008472438 | K8: 0.010824522 | L8: 0.014899893 | M8: 0.01773442 | N8: 0.019866524
A9: Notas: * Se muestran los niveles de error para una metodología de medición con muestra 100% Transversal (único registro por persona - metodología anterior) vs. metodología actual con uso de datos de Panel. Se observa una reducción del orden de 52% en los márgenes de error. Muestra Total = Total de entrevistas realizadas. Muestra diaria = suma de los casos de panel + la muestra rotativa dividida en 7 dias. Muestra rotativa = muestra que no es de panel (hay una observacion de consumo por dia para cada persona). Panel = casos con observaciones en 7 dias. Coef. Correl. = correlación estimada entre mediciones diarias sucesivas de rating.

Sheet RatxHoraxLD
A1: CUADRO 3: RESUMEN DE RATING POR HORA | AM | LUNES A DOMINGO
A3: RADIOS | B3: HORAS | Z3: PROMEDIO
B4: 00:00 - 00:59 | C4: 01:00 - 01:59 | D4: 02:00 - 02:59 | E4: 03:00 - 03:59 | F4: 04:00 - 04:59 | G4: 05:00 - 05:59 | H4: 06:00 - 06:59 | I4: 07:00 - 07:59 | J4: 08:00 - 08:59 | K4: 09:00 - 09:59 | L4: 10:00 - 10:59 | M4: 11:00 - 11:59 | N4: 12:00 - 12:59 | O4: 13:00 - 13:59 | P4: 14:00 - 14:59 | Q4: 15:00 - 15:59 | R4: 16:00 - 16:59 | S4: 17:00 - 17:59 | T4: 18:00 - 18:59 | U4: 19:00 - 19:59 | V4: 20:00 - 20:59 | W4: 21:00 - 21:59 | X4: 22:00 - 22:59 | Y4: 23:00 - 23:59 | Z4: 06:00 - 11:59 | AA4: 12:00 - 17:59 | AB4: 18:00 - 23:59 | AC4: 06:00 - 23:59 | AD4: 00:00 - 24:00
A5: CX4 RURAL | B5: 0.12472569 | C5: 0.086650501 | D5: 0.046828834 | E5: 0 | F5: 0 | G5: 0 | H5: 0.12765409 | I5: 0.18664689 | J5: 0.1432375 | K5: 0.098026702 | L5: 0.13321501 | M5: 0.14180404 | N5: 0.10228181 | O5: 0.15064839 | P5: 0.22751236 | Q5: 0.1867082 | R5: 0.21551824 | S5: 0.11656657 | T5: 0.050239548 | U5: 0.06559387 | V5: 0.044540155 | W5: 0.070437516 | X5: 0.086747374 | Y5: 0.14501629 | Z5: 0.1384307 | AA5: 0.16653926 | AB5: 0.077095792 | AC5: 0.12735525 | AD5: 0.10627498
A6: CX6 CLÁSICA | B6: 0 | C6: 0 | D6: 0 | E6: 0 | F6: 0 | G6: 0 | H6: 0 | I6: 0.035902928 | J6: 0.08600982 | K6: 0.079572927 | L6: 0.043368543 | M6: 0.026478899 | N6: 0.013902508 | O6: 0.083434516 | P6: 0.083434516 | Q6: 0.033327623 | R6: 0.022165191 | S6: 0.013902508 | T6: 0.013902508 | U6: 0.023060218 | V6: 0.020152531 | W6: 0 | X6: 0 | Y6: 0.0091577101 | Z6: 0.045222186 | AA6: 0.041694477 | AB6: 0.011045495 | AC6: 0.032654053 | AD6: 0.024490539
A7: CX8 SARANDI | B7: 0.048256692 | C7: 0.030970488 | D7: 0.02311268 | E7: 0.02311268 | F7: 0.095253809 | G7: 0.32444102 | H7: 1.0337221 | I7: 1.6886568 | J7: 1.9643658 | K7: 1.9865919 | L7: 1.748135 | M7: 1.5393479 | N7: 0.85247056 | O7: 0.49885863 | P7: 0.38448054 | Q7: 0.36683261 | R7: 0.49600254 | S7: 0.41024796 | T7: 0.24170204 | U7: 0.14558252 | V7: 0.11005996 | W7: 0.15468837 | X7: 0.12484172 | Y7: 0.057368497 | Z7: 1.6601366 | AA7: 0.50148214 | AB7: 0.13904052 | AC7: 0.76688641 | AD7: 0.59787928
A8: CX10 CONTINENTE | B8: 0 | C8: 0 | D8: 0 | E8: 0 | F8: 0.011458539 | G8: 0.011458539 | H8: 0.016786156 | I8: 0.048081595 | J8: 0.12633021 | K8: 0.086439515 | L8: 0.079657739 | M8: 0.070309563 | N8: 0.075608256 | O8: 0.050133903 | P8: 0.13368708 | Q8: 0.034758359 | R8: 0.086861771 | S8: 0.018152464 | T8: 0.025168103 | U8: 0.056481795 | V8: 0.13145521 | W8: 0.14042779 | X8: 0.15460339 | Y8: 0.12077612 | Z8: 0.071267463 | AA8: 0.066533638 | AB8: 0.10481873 | AC8: 0.080873279 | AD8: 0.061609837
A9: CX12 ORIENTAL | B9: 0.01131912 | C9: 0 | D9: 0 | E9: 0 | F9: 0.0072594108 | G9: 0.014581683 | H9: 0.076871776 | I9: 0.36201312 | J9: 0.44336016 | K9: 0.48493614 | L9: 0.45733576 | M9: 0.33901143 | N9: 0.20269894 | O9: 0.22592021 | P9: 0.23206708 | Q9: 0.17568018 | R9: 0.18527793 | S9: 0.17788502 | T9: 0.10054311 | U9: 0.17006479 | V9: 0.099496437 | W9: 0.14297711 | X9: 0.10269869 | Y9: 0.14315051 | Z9: 0.36058806 | AA9: 0.19992156 | AB9: 0.12648844 | AC9: 0.22899935 | AD9: 0.17313119
A10: CX14 EL ESPECTADOR | B10: 0.16243926 | C10: 0.035598405 | D10: 0.026972339 | E10: 0 | F10: 0 | G10: 0.076818349 | H10: 0.31549487 | I10: 0.44949076 | J10: 0.56536429 | K10: 0.64964588 | L10: 0.54585279 | M10: 0.50545457 | N10: 0.32762662 | O10: 0.38411616 | P10: 0.15723317 | Q10: 0.20179449 | R10: 0.14728767 | S10: 0.076463662 | T10: 0.066955064 | U10: 0.1458038 | V10: 0.087695203 | W10: 0.11002063 | X10: 0.21185611 | Y10: 0.29490396 | Z10: 0.50521719 | AA10: 0.21575363 | AB10: 0.15287246 | AC10: 0.29128109 | AD10: 0.231037
A11: CX16 CARVE | B11: 0.046200172 | C11: 0.033465568 | D11: 0.026151935 | E11: 0.026151935 | F11: 0.030578372 | G11: 0.052084311 | H11: 0.11750594 | I11: 0.14338834 | J11: 0.19756833 | K11: 0.18367601 | L11: 0.19274455 | M11: 0.13301813 | N11: 0.15371621 | O11: 0.16077925 | P11: 0.2377798 | Q11: 0.19663598 | R11: 0.23790411 | S11: 0.15527595 | T11: 0.16846572 | U11: 0.17371545 | V11: 0.15557136 | W11: 0.16818521 | X11: 0.1021953 | Y11: 0.068649753 | Z11: 0.16131688 | AA11: 0.19034855 | AB11: 0.1394638 | AC11: 0.16370974 | AD11: 0.13172532
A12: CX18 SPORT 890 | B12: 0.041404392 | C12: 0.041404392 | D12: 0.01946465 | E12: 0.053701223 | F12: 0.042472602 | G12: 0.171549 | H12: 0.36024642 | I12: 0.63348858 | J12: 0.81129456 | K12: 0.88416076 | L12: 0.67850144 | M12: 0.76469357 | N12: 0.62914535 | O12: 0.46711871 | P12: 0.51816005 | Q12: 0.56194768 | R12: 0.54982566 | S12: 0.55574078 | T12: 0.33656214 | U12: 0.2922529 | V12: 0.19936219 | W12: 0.11914191 | X12: 0.071642394 | Y12: 0.060068075 | Z12: 0.68873089 | AA12: 0.54698971 | AB12: 0.17983827 | AC12: 0.47185296 | AD12: 0.36930623
A13: CX20 MONTECARLO | B13: 0.26203668 | C13: 0.31789313 | D13: 0.14672455 | E13: 0.13787973 | F13: 0.14354183 | G13: 0.58401666 | H13: 1.533459 | I13: 2.7716798 | J13: 3.0346838 | K13: 3.4794457 | L13: 3.2025539 | M13: 3.3925785 | N13: 2.6124603 | O13: 1.6052952 | P13: 1.4752571 | Q13: 1.1850659 | R13: 0.99751449 | S13: 0.92630467 | T13: 0.84812663 | U13: 0.62554384 | V13: 0.47811958 | W13: 0.42517945 | X13: 0.24143284 | Y13: 0.12684374 | Z13: 2.9024001 | AA13: 1.4669829 | AB13: 0.45754101 | AC13: 1.6089747 | AD13: 1.2730682
A14: CX22 UNIVERSAL | B14: 0.040534247 | C14: 0.040534247 | D14: 0.032837253 | E14: 0.048399102 | F14: 0.041326004 | G14: 0.031931487 | H14: 0.032385781 | I14: 0.076509971 | J14: 0.09344998 | K14: 0.12513049 | L14: 0.18109864 | M14: 0.25457171 | N14: 0.26458473 | O14: 0.15459968 | P14: 0.086946721 | Q14: 0.1145035 | R14: 0.18567269 | S14: 0.17963636 | T14: 0.10908528 | U14: 0.10090115 | V14: 0.11595097 | W14: 0.12780953 | X14: 0.09373098 | Y14: 0.032176767 | Z14: 0.1271911 | AA14: 0.16432394 | AB14: 0.096609113 | AC14: 0.12937472 | AD14: 0.10684614
A15: CX24 RADIO 1010 AM | B15: 0.023803057 | C15: 0 | D15: 0 | E15: 0 | F15: 0 | G15: 0 | H15: 0.03446191 | I15: 0.057076612 | J15: 0.12385344 | K15: 0.14005833 | L15: 0.10866715 | M15: 0.15723553 | N15: 0.19495314 | O15: 0.1172048 | P15: 0.12208741 | Q15: 0.12015155 | R15: 0.16723062 | S15: 0.091079814 | T15: 0.07315694 | U15: 0.060043987 | V15: 0.029979437 | W15: 0.0087764854 | X15: 0.0087764854 | Y15: 0.0079409608 | Z15: 0.10355883 | AA15: 0.13545122 | AB15: 0.031445716 | AC15: 0.090151923 | AD15: 0.068605736
A16: CX26 RADIO URUGUAY | B16: 0.035217217 | C16: 0.043468832 | D16: 0.051480791 | E16: 0.052235795 | F16: 0.052861299 | G16: 0.040980057 | H16: 0.065911024 | I16: 0.1270732 | J16: 0.22063165 | K16: 0.24414866 | L16: 0.25704089 | M16: 0.2653549 | N16: 0.17628434 | O16: 0.11777226 | P16: 0.20640343 | Q16: 0.19970443 | R16: 0.12730319 | S16: 0.079792513 | T16: 0.058741547 | U16: 0.044698768 | V16: 0.08246091 | W16: 0.073693947 | X16: 0.028353304 | Y16: 0.024804591 | Z16: 0.19669339 | AA16: 0.15121003 | AB16: 0.052125511 | AC16: 0.13334298 | AD16: 0.1115174
... A32: RATING GENERAL | B32: 2.1648392 | C32: 1.7583889 | D32: 1.4352191 | E32: 1.3136207 | F32: 1.6787642 | G32: 3.7508866 | H32: 9.7088923 | I32: 19.513297 | J32: 27.030863 | K32: 31.272413 | L32: 30.724227 | M32: 31.02506 | N32: 26.884158 | O32: 24.418685 | P32: 24.815587 | Q32: 23.813355 | R32: 23.57176 | S32: 21.473674 | T32: 18.255745 | U32: 13.672951 | V32: 10.141779 | W32: 8.7076795 | X32: 6.3453534 | Y32: 4.5222545 | Z32: 24.879125 | AA32: 24.16287 | AB32: 10.274294 | AC32: 19.772096 | AD32: 15.33331
A34: CUADRO 4: RESUMEN DE RATING POR HORA | FM | LUNES A DOMINGO
A36: RADIOS | B36: HORAS | Z36: PROMEDIO
B37: 00:00 - 00:59 | C37: 01:00 - 01:59 | D37: 02:00 - 02:59 | E37: 03:00 - 03:59 | F37: 04:00 - 04:59 | G37: 05:00 - 05:59 | H37: 06:00 - 06:59 | I37: 07:00 - 07:59 | J37: 08:00 - 08:59 | K37: 09:00 - 09:59 | L37: 10:00 - 10:59 | M37: 11:00 - 11:59 | N37: 12:00 - 12:59 | O37: 13:00 - 13:59 | P37: 14:00 - 14:59 | Q37: 15:00 - 15:59 | R37: 16:00 - 16:59 | S37: 17:00 - 17:59 | T37: 18:00 - 18:59 | U37: 19:00 - 19:59 | V37: 20:00 - 20:59 | W37: 21:00 - 21:59 | X37: 22:00 - 22:59 | Y37: 23:00 - 23:59 | Z37: 06:00 - 11:59 | AA37: 12:00 - 17:59 | AB37: 18:00 - 23:59 | AC37: 06:00 - 23:59 | AD37: 00:00 - 24:00
A38: 88.3 LACOSTA | B38: 0.074204583 | C38: 0.066999615 | D38: 0.066999615 | E38: 0.066999615 | F38: 0.050260595 | G38: 0.089236214 | H38: 0.08191725 | I38: 0.22901426 | J38: 0.26060203 | K38: 0.2288449 | L38: 0.16712865 | M38: 0.0719604 | N38: 0.1895216 | O38: 0.26727049 | P38: 0.20911436 | Q38: 0.26539144 | R38: 0.27281573 | S38: 0.38601312 | T38: 0.16604298 | U38: 0.25675311 | V38: 0.23021107 | W38: 0.18686694 | X38: 0.19300049 | Y38: 0.051129524 | Z38: 0.17324458 | AA38: 0.26502112 | AB38: 0.18066735 | AC38: 0.20631102 | AD38: 0.17201244
A39: 90.3 OLDIES | B39: 0.065853874 | C39: 0.065853874 | D39: 0.079981712 | E39: 0.075642326 | F39: 0.013796112 | G39: 0.022731393 | H39: 0.11243648 | I39: 0.30817558 | J39: 0.57999535 | K39: 0.65997876 | L39: 0.86528046 | M39: 0.85692199 | N39: 0.94244069 | O39: 0.91681108 | P39: 0.8487505 | Q39: 0.74295373 | R39: 0.64986757 | S39: 0.62112192 | T39: 0.56912264 | U39: 0.25765829 | V39: 0.18348724 | W39: 0.1899849 | X39: 0.24048715 | Y39: 0.25176011 | Z39: 0.5637981 | AA39: 0.78699091 | AB39: 0.28208339 | AC39: 0.5442908 | AD39: 0.42171224
A40: 91.1 RADIOFUTURA | B40: 0.025146328 | C40: 0.025146328 | D40: 0.012737801 | E40: 0.020757225 | F40: 0.026300191 | G40: 0.042999881 | H40: 0.11386937 | I40: 0.16729577 | J40: 0.3638266 | K40: 0.65593444 | L40: 0.71718753 | M40: 0.84836428 | N40: 0.6434891 | O40: 0.68087765 | P40: 0.63754469 | Q40: 0.59410271 | R40: 0.62916037 | S40: 0.58613561 | T40: 0.72105424 | U40: 0.6593241 | V40: 0.5332358 | W40: 0.36025226 | X40: 0.26165339 | Y40: 0.15184482 | Z40: 0.47774633 | AA40: 0.62855169 | AB40: 0.4478941 | AC40: 0.51806404 | AD40: 0.39492669
A41: 91.9 DISNEY | B41: 0.047828421 | C41: 0.034132258 | D41: 0.017697357 | E41: 0.0093006887 | F41: 0.04218801 | G41: 0.17973479 | H41: 0.50352498 | I41: 1.0816434 | J41: 1.4496355 | K41: 2.0010974 | L41: 2.0972631 | M41: 2.3348083 | N41: 2.1120885 | O41: 2.2146538 | P41: 1.9938191 | Q41: 2.0326623 | R41: 1.8616134 | S41: 1.7202412 | T41: 1.3331414 | U41: 1.0778688 | V41: 0.69319627 | W41: 0.44492987 | X41: 0.2888788 | Y41: 0.18672193 | Z41: 1.5779955 | AA41: 1.9891797 | AB41: 0.67078951 | AC41: 1.4126549 | AD41: 1.0732779
A42: 92.5 CONCIERTO URBANA | B42: 0.0046493221 | C42: 0.0046493221 | D42: 0.0086063547 | E42: 0 | F42: 0 | G42: 0 | H42: 0.021773288 | I42: 0.1325673 | J42: 0.26800062 | K42: 0.29313492 | L42: 0.18475198 | M42: 0.18434301 | N42: 0.16064302 | O42: 0.16808315 | P42: 0.20545979 | Q42: 0.17277345 | R42: 0.20384654 | S42: 0.18947129 | T42: 0.2124995 | U42: 0.13831146 | V42: 0.13566248 | W42: 0.058309439 | X42: 0 | Y42: 0.0078339839 | Z42: 0.18076185 | AA42: 0.18337954 | AB42: 0.09210281 | AC42: 0.1520814 | AD42: 0.11480709
A43: 93.1 INOLVIDABLE | B43: 0.058665239 | C43: 0.015937947 | D43: 0.024907083 | E43: 0.024580376 | F43: 0.034150722 | G43: 0.040497754 | H43: 0.25206625 | I43: 0.48759957 | J43: 0.95964052 | K43: 1.0576488 | L43: 1.3115946 | M43: 1.3740944 | N43: 1.4351441 | O43: 1.4534839 | P43: 1.5519632 | Q43: 1.2034901 | R43: 1.3355045 | S43: 0.99873183 | T43: 1.0314441 | U43: 1.091299 | V43: 0.90952662 | W43: 0.75897819 | X43: 0.32456464 | Y43: 0.10542118 | Z43: 0.90710736 | AA43: 1.3297196 | AB43: 0.70353896 | AC43: 0.98012198 | AD43: 0.74337228
A44: 93.9 OCEANO | B44: 0.0071307132 | C44: 0.0071307132 | D44: 0.0084156277 | E44: 0 | F44: 0 | G44: 0.0236 | H44: 0.10817067 | I44: 0.4981145 | J44: 0.736503 | K44: 0.75812894 | L44: 0.81567672 | M44: 0.85652417 | N44: 1.1282581 | O44: 1.0895079 | P44: 1.0487942 | Q44: 0.86675879 | R44: 0.79905191 | S44: 0.67623686 | T44: 0.34119627 | U44: 0.24374051 | V44: 0.11927665 | W44: 0.13001836 | X44: 0.04694033 | Y44: 0.036200688 | Z44: 0.628853 | AA44: 0.93476797 | AB44: 0.15289547 | AC44: 0.57217215 | AD44: 0.43105732
A45: 94.7 E. DEL SUR | B45: 0.010103633 | C45: 0.010103633 | D45: 0.027679123 | E45: 0 | F45: 0 | G45: 0.032382985 | H45: 0.054104125 | I45: 0.095676772 | J45: 0.073742905 | K45: 0.19130343 | L45: 0.1597396 | M45: 0.15301578 | N45: 0.05765856 | O45: 0.072363987 | P45: 0.079935124 | Q45: 0.10634819 | R45: 0.12410884 | S45: 0.16893253 | T45: 0.096524392 | U45: 0.06767955 | V45: 0.050593149 | W45: 0.068363661 | X45: 0.038976924 | Y45: 0.061956529 | Z45: 0.12126377 | AA45: 0.10155787 | AB45: 0.064015701 | AC45: 0.095612447 | AD45: 0.075053893
A46: 95.5 DEL PLATA | B46: 0.13124574 | C46: 0.11259508 | D46: 0.10622121 | E46: 0.088382584 | F46: 0.0099608388 | G46: 0 | H46: 0.042018254 | I46: 0.12934706 | J46: 0.39490058 | K46: 0.64017148 | L46: 0.60009883 | M46: 0.72157057 | N46: 0.71152512 | O46: 0.70089673 | P46: 0.6898889 | Q46: 0.6963799 | R46: 0.80467087 | S46: 0.82463543 | T46: 0.61506358 | U46: 0.3792669 | V46: 0.31175603 | W46: 0.22873736 | X46: 0.21156531 | Y46: 0.22400127 | Z46: 0.42135113 | AA46: 0.73799949 | AB46: 0.32839841 | AC46: 0.49591634 | AD46: 0.39062082
A47: 96.3 ALFA | B47: 0 | C47: 0 | D47: 0 | E47: 0 | F47: 0 | G47: 0 | H47: 0 | I47: 0 | J47: 0.092861458 | K47: 0.094143695 | L47: 0.18943776 | M47: 0.11561188 | N47: 0.18301939 | O47: 0.25122256 | P47: 0.18887991 | Q47: 0.1505055 | R47: 0.12709164 | S47: 0.11459105 | T47: 0.070537298 | U47: 0.11855679 | V47: 0.11869364 | W47: 0.12582854 | X47: 0.093874691 | Y47: 0.037820905 | Z47: 0.082009132 | AA47: 0.16921834 | AB47: 0.094218644 | AC47: 0.11514871 | AD47: 0.08636153
A48: 97.1 BABEL | B48: 0 | C48: 0 | D48: 0.011669801 | E48: 0.0086424293 | F48: 0.055124307 | G48: 0.075584038 | H48: 0.13737728 | I48: 0.15816992 | J48: 0.16948303 | K48: 0.3221846 | L48: 0.27939581 | M48: 0.30697937 | N48: 0.21922956 | O48: 0.20611866 | P48: 0.1829775 | Q48: 0.20437488 | R48: 0.2587299 | S48: 0.31324142 | T48: 0.33982328 | U48: 0.41588046 | V48: 0.27498536 | W48: 0.23049909 | X48: 0.15623129 | Y48: 0.061950443 | Z48: 0.22893167 | AA48: 0.23077865 | AB48: 0.24656165 | AC48: 0.23542399 | AD48: 0.18286052
A49: 97.9 M24 | B49: 0.0099393186 | C49: 0 | D49: 0 | E49: 0 | F49: 0.01354623 | G49: 0.134292 | H49: 0.16013786 | I49: 0.22380524 | J49: 0.30543859 | K49: 0.31646501 | L49: 0.27510237 | M49: 0.25443195 | N49: 0.17332 | O49: 0.13851342 | P49: 0.11686457 | Q49: 0.17539003 | R49: 0.16896115 | S49: 0.10154303 | T49: 0.10105106 | U49: 0.10072019 | V49: 0.044817711 | W49: 0.088864062 | X49: 0.051414261 | Y49: 0.051414261 | Z49: 0.25589684 | AA49: 0.14576537 | AB49: 0.073046925 | AC49: 0.15823638 | AD49: 0.12525135
... A65: RATING GENERAL | B65: 2.1648392 | C65: 1.7583889 | D65: 1.4352191 | E65: 1.3136207 | F65: 1.6787642 | G65: 3.7508866 | H65: 9.7088923 | I65: 19.513297 | J65: 27.030863 | K65: 31.272413 | L65: 30.724227 | M65: 31.02506 | N65: 26.884158 | O65: 24.418685 | P65: 24.815587 | Q65: 23.813355 | R65: 23.57176 | S65: 21.473674 | T65: 18.255745 | U65: 13.672951 | V65: 10.141779 | W65: 8.7076795 | X65: 6.3453534 | Y65: 4.5222545 | Z65: 24.879125 | AA65: 24.16287 | AB65: 10.274294 | AC65: 19.772096 | AD65: 15.33331

Sheet RatxHoraxLV
A1: CUADRO 5: RESUMEN DE RATING POR HORA | AM | LUNES A VIERNES
A3: RADIOS | B3: HORAS | Z3: PROMEDIO
B4: 00:00 - 00:59 | C4: 01:00 - 01:59 | D4: 02:00 - 02:59 | E4: 03:00 - 03:59 | F4: 04:00 - 04:59 | G4: 05:00 - 05:59 | H4: 06:00 - 06:59 | I4: 07:00 - 07:59 | J4: 08:00 - 08:59 | K4: 09:00 - 09:59 | L4: 10:00 - 10:59 | M4: 11:00 - 11:59 | N4: 12:00 - 12:59 | O4: 13:00 - 13:59 | P4: 14:00 - 14:59 | Q4: 15:00 - 15:59 | R4: 16:00 - 16:59 | S4: 17:00 - 17:59 | T4: 18:00 - 18:59 | U4: 19:00 - 19:59 | V4: 20:00 - 20:59 | W4: 21:00 - 21:59 | X4: 22:00 - 22:59 | Y4: 23:00 - 23:59 | Z4: 06:00 - 11:59 | AA4: 12:00 - 17:59 | AB4: 18:00 - 23:59 | AC4: 06:00 - 23:59 | AD4: 00:00 - 24:00
A5: CX4 RURAL | B5: 0.13487773 | C5: 0.081572454 | D5: 0.049935373 | E5: 0 | F5: 0 | G5: 0 | H5: 0.13717582 | I5: 0.18530991 | J5: 0.13562023 | K5: 0.098169175 | L5: 0.13366832 | M5: 0.14569296 | N5: 0.12547765 | O5: 0.18218993 | P5: 0.2574823 | Q5: 0.23280986 | R5: 0.25169145 | S5: 0.12662447 | T5: 0.062348266 | U5: 0.065895989 | V5: 0.036420788 | W5: 0.075662058 | X5: 0.1111596 | Y5: 0.16444734 | Z5: 0.13927274 | AA5: 0.19604594 | AB5: 0.085989007 | AC5: 0.1404359 | AD5: 0.11642632
A6: CX6 CLÁSICA | B6: 0 | C6: 0 | D6: 0 | E6: 0 | F6: 0 | G6: 0 | H6: 0 | I6: 0.050264099 | J6: 0.096431054 | K6: 0.075851647 | L6: 0.029684692 | M6: 0.017606947 | N6: 0 | O6: 0.073362116 | P6: 0.073362116 | Q6: 0.027195161 | R6: 0 | S6: 0 | T6: 0 | U6: 0 | V6: 0.0087500327 | W6: 0 | X6: 0 | Y6: 0 | Z6: 0.044973073 | AA6: 0.028986566 | AB6: 0.0014583388 | AC6: 0.025139326 | AD6: 0.018854494
A7: CX8 SARANDI | B7: 0.040649208 | C7: 0.017734671 | D7: 0.017734671 | E7: 0.017734671 | F7: 0.082197691 | G7: 0.35582781 | H7: 1.1248027 | I7: 1.8705685 | J7: 2.1517821 | K7: 2.1478479 | L7: 1.9139002 | M7: 1.674831 | N7: 0.96079712 | O7: 0.53219598 | P7: 0.44157594 | Q7: 0.42803692 | R7: 0.56347808 | S7: 0.45925573 | T7: 0.2685774 | U7: 0.15612011 | V7: 0.10709707 | W7: 0.11231822 | X7: 0.08958329 | Y7: 0.026856082 | Z7: 1.8139554 | AA7: 0.56422329 | AB7: 0.12675869 | AC7: 0.83497913 | AD7: 0.64839596
A8: CX10 CONTINENTE | B8: 0 | C8: 0 | D8: 0 | E8: 0 | F8: 0 | G8: 0 | H8: 0.012417155 | I8: 0.056230769 | J8: 0.14838865 | K8: 0.087320416 | L8: 0.10043737 | M8: 0.088611493 | N8: 0.10585156 | O8: 0.070187464 | P8: 0.15407253 | Q8: 0.035378216 | R8: 0.089788347 | S8: 0.012129963 | T8: 0.012129963 | U8: 0.049486982 | V8: 0.12258693 | W8: 0.13479582 | X8: 0.15464166 | Y8: 0.1174581 | Z8: 0.082234309 | AA8: 0.077901346 | AB8: 0.098516576 | AC8: 0.08621741 | AD8: 0.064663058
A9: CX12 ORIENTAL | B9: 0 | C9: 0 | D9: 0 | E9: 0 | F9: 0.010163175 | G9: 0.010163175 | H9: 0.10762049 | I9: 0.43063651 | J9: 0.50718184 | K9: 0.57053186 | L9: 0.49207602 | M9: 0.37935364 | N9: 0.22585545 | O9: 0.21282968 | P9: 0.19760663 | Q9: 0.15213216 | R9: 0.15213216 | S9: 0.16720314 | T9: 0.06353214 | U9: 0.15876761 | V9: 0.11349349 | W9: 0.16759406 | X9: 0.13763739 | Y9: 0.15577417 | Z9: 0.41456673 | AA9: 0.18462654 | AB9: 0.13279981 | AC9: 0.24399769 | AD9: 0.1838452
A10: CX14 EL ESPECTADOR | B10: 0.15696632 | C10: 0.024900548 | D10: 0.02494048 | E10: 0 | F10: 0 | G10: 0.081513773 | H10: 0.39448687 | I10: 0.52792627 | J10: 0.67874783 | K10: 0.78496633 | L10: 0.62546164 | M10: 0.57216397 | N10: 0.40460153 | O10: 0.44776778 | P10: 0.18643506 | Q10: 0.22047374 | R10: 0.15742935 | S10: 0.073704567 | T10: 0.053109247 | U10: 0.13297403 | V10: 0.064285733 | W10: 0.080300332 | X10: 0.19095592 | Y10: 0.29932079 | Z10: 0.59729215 | AA10: 0.248402 | AB10: 0.13682434 | AC10: 0.32750617 | AD10: 0.25764301
A11: CX16 CARVE | B11: 0.051557999 | C11: 0.022696178 | D11: 0 | E11: 0 | F11: 0.017230386 | G11: 0.059795793 | H11: 0.14485893 | I11: 0.1409633 | J11: 0.14997106 | K11: 0.12820286 | L11: 0.17417753 | M11: 0.11824525 | N11: 0.20208045 | O11: 0.22509095 | P11: 0.27661433 | Q11: 0.21796316 | R11: 0.25354365 | S11: 0.17244385 | T11: 0.17842628 | U11: 0.18577592 | V11: 0.16037418 | W11: 0.17803358 | X11: 0.12535653 | Y11: 0.078392765 | Z11: 0.14273649 | AA11: 0.22462273 | AB11: 0.15105988 | AC11: 0.17280637 | AD11: 0.13590812
A12: CX18 SPORT 890 | B12: 0.057966149 | C12: 0.057966149 | D12: 0.02725051 | E12: 0.053441764 | F12: 0.049287014 | G12: 0.17497111 | H12: 0.42265838 | I12: 0.73006374 | J12: 0.96508946 | K12: 1.0481803 | L12: 0.81981972 | M12: 0.85958667 | N12: 0.66918914 | O12: 0.53361242 | P12: 0.57835774 | Q12: 0.62718292 | R12: 0.59415034 | S12: 0.55944873 | T12: 0.28249814 | U12: 0.21575175 | V12: 0.177124 | W12: 0.08521337 | X12: 0.089233662 | Y12: 0.084095305 | Z12: 0.80756638 | AA12: 0.59365688 | AB12: 0.15565271 | AC12: 0.51895865 | AD12: 0.40675577
A13: CX20 MONTECARLO | B13: 0.28219242 | C13: 0.34086722 | D13: 0.16415479 | E13: 0.12218134 | F13: 0.17700268 | G13: 0.66237203 | H13: 1.5902935 | I13: 2.9534478 | J13: 3.2364152 | K13: 3.64602 | L13: 3.4274193 | M13: 3.6356067 | N13: 2.8179769 | O13: 1.6826125 | P13: 1.5146723 | Q13: 1.1213118 | R13: 0.87663025 | S13: 0.80511045 | T13: 0.88081953 | U13: 0.68513873 | V13: 0.57224692 | W13: 0.47556822 | X13: 0.28088342 | Y13: 0.14260956 | Z13: 3.0815338 | AA13: 1.469719 | AB13: 0.50621106 | AC13: 1.6858213 | AD13: 1.3372314
A14: CX22 UNIVERSAL | B14: 0.056747946 | C14: 0.056747946 | D14: 0.045972154 | E14: 0.067758742 | F14: 0.057856405 | G14: 0.044704082 | H14: 0.045340094 | I14: 0.070695057 | J14: 0.094646366 | K14: 0.11857164 | L14: 0.20860918 | M14: 0.28397321 | N14: 0.27894216 | O14: 0.14996664 | P14: 0.087404749 | Q14: 0.10353364 | R14: 0.15406758 | S14: 0.1683082 | T14: 0.060905578 | U14: 0.093897991 | V14: 0.13994475 | W14: 0.13069784 | X14: 0.094627243 | Y14: 0.020241864 | Z14: 0.13697259 | AA14: 0.15703716 | AB14: 0.090052545 | AC14: 0.12802077 | AD14: 0.10975671
A15: CX24 RADIO 1010 AM | B15: 0.033324279 | C15: 0 | D15: 0 | E15: 0 | F15: 0 | G15: 0 | H15: 0.035959594 | I15: 0.079907257 | J15: 0.15087053 | K15: 0.17355739 | L15: 0.12960972 | M15: 0.17568454 | N15: 0.25041012 | O15: 0.16408672 | P15: 0.14900146 | Q15: 0.15737366 | R15: 0.2126496 | S15: 0.10603846 | T15: 0.10241972 | U15: 0.071774502 | V15: 0.029684132 | W15: 0 | X15: 0 | Y15: 0.011117345 | Z15: 0.12426484 | AA15: 0.17326 | AB15: 0.035832616 | AC15: 0.11111915 | AD15: 0.084727876
A16: CX26 RADIO URUGUAY | B16: 0.024219249 | C16: 0.035771509 | D16: 0.046988252 | E16: 0.035771509 | F16: 0.048934293 | G16: 0.040450038 | H16: 0.063603036 | I16: 0.10929034 | J16: 0.20278125 | K16: 0.22896091 | L16: 0.27691592 | M16: 0.28876945 | N16: 0.20494035 | O16: 0.10893004 | P16: 0.18600679 | Q16: 0.19328303 | R16: 0.13394757 | S16: 0.083278836 | T16: 0.058531568 | U16: 0.023025458 | V16: 0.091738677 | W16: 0.091738677 | X16: 0.028261776 | Y16: 0.023293578 | Z16: 0.19505348 | AA16: 0.1517311 | AB16: 0.052764956 | AC16: 0.13318318 | AD16: 0.10955967
... A32: RATING GENERAL | B32: 2.0940512 | C32: 1.7042605 | D32: 1.3474499 | E32: 1.2566093 | F32: 1.6911294 | G32: 4.0222796 | H32: 10.571871 | I32: 21.121997 | J32: 29.490126 | K32: 33.772658 | L32: 32.734626 | M32: 33.367768 | N32: 29.026581 | O32: 26.528951 | P32: 27.301199 | Q32: 26.433651 | R32: 25.861463 | S32: 23.577808 | T32: 20.015946 | U32: 14.632453 | V32: 10.810167 | W32: 9.0232714 | X32: 6.5743296 | Y32: 4.6052294 | Z32: 26.843174 | AA32: 26.454942 | AB32: 10.943566 | AC32: 21.413894 | AD32: 16.565245
A34: CUADRO 6: RESUMEN DE RATING POR HORA | FM | LUNES A VIERNES
A36: RADIOS | B36: HORAS | Z36: PROMEDIO
B37: 00:00 - 00:59 | C37: 01:00 - 01:59 | D37: 02:00 - 02:59 | E37: 03:00 - 03:59 | F37: 04:00 - 04:59 | G37: 05:00 - 05:59 | H37: 06:00 - 06:59 | I37: 07:00 - 07:59 | J37: 08:00 - 08:59 | K37: 09:00 - 09:59 | L37: 10:00 - 10:59 | M37: 11:00 - 11:59 | N37: 12:00 - 12:59 | O37: 13:00 - 13:59 | P37: 14:00 - 14:59 | Q37: 15:00 - 15:59 | R37: 16:00 - 16:59 | S37: 17:00 - 17:59 | T37: 18:00 - 18:59 | U37: 19:00 - 19:59 | V37: 20:00 - 20:59 | W37: 21:00 - 21:59 | X37: 22:00 - 22:59 | Y37: 23:00 - 23:59 | Z37: 06:00 - 11:59 | AA37: 12:00 - 17:59 | AB37: 18:00 - 23:59 | AC37: 06:00 - 23:59 | AD37: 00:00 - 24:00
A38: 88.3 LACOSTA | B38: 0.069641039 | C38: 0.069641039 | D38: 0.069641039 | E38: 0.069641039 | F38: 0.046206412 | G38: 0.10077228 | H38: 0.065065474 | I38: 0.22929337 | J38: 0.20969194 | K38: 0.20981791 | L38: 0.17357776 | M38: 0.076818096 | N38: 0.24564324 | O38: 0.35360584 | P38: 0.22965394 | Q38: 0.28000743 | R38: 0.29140303 | S38: 0.44482515 | T38: 0.1900426 | U38: 0.30594823 | V38: 0.29085073 | W38: 0.2190804 | X38: 0.27020069 | Y38: 0.071581333 | Z38: 0.16071076 | AA38: 0.30752311 | AB38: 0.22461733 | AC38: 0.2309504 | AD38: 0.19094375
A39: 90.3 OLDIES | B39: 0.050710751 | C39: 0.050710751 | D39: 0.081945315 | E39: 0.070025308 | F39: 0.019314557 | G39: 0.03182395 | H39: 0.14163469 | I39: 0.40330965 | J39: 0.67146637 | K39: 0.74293043 | L39: 0.95870018 | M39: 0.91194172 | N39: 0.97494057 | O39: 0.97625977 | P39: 0.89852404 | Q39: 0.82998172 | R39: 0.73245147 | S39: 0.70346893 | T39: 0.64218357 | U39: 0.28843787 | V39: 0.21376782 | W39: 0.20087016 | X39: 0.23352911 | Y39: 0.24070092 | Z39: 0.63833051 | AA39: 0.85260442 | AB39: 0.30324824 | AC39: 0.59806105 | AD39: 0.46123457
A40: 91.1 RADIOFUTURA | B40: 0.017832921 | C40: 0.017832921 | D40: 0.017832921 | E40: 0.017832921 | F40: 0.025593073 | G40: 0.027538638 | H40: 0.15941711 | I40: 0.20951078 | J40: 0.40022624 | K40: 0.73197805 | L40: 0.76085071 | M40: 0.95041933 | N40: 0.7402811 | O40: 0.78388231 | P40: 0.69709746 | Q40: 0.62415349 | R40: 0.65415018 | S40: 0.63299545 | T40: 0.81581182 | U40: 0.75915164 | V40: 0.60610595 | W40: 0.38776828 | X40: 0.27548566 | Y40: 0.18370807 | Z40: 0.53540037 | AA40: 0.68876 | AB40: 0.5046719 | AC40: 0.57627742 | AD40: 0.43739404
A41: 91.9 DISNEY | B41: 0.034386624 | C41: 0.047785161 | D41: 0.0247763 | E41: 0.013020964 | F41: 0.033156054 | G41: 0.17198029 | H41: 0.59150991 | I41: 1.2449637 | J41: 1.5367974 | K41: 2.0967027 | L41: 2.1662547 | M41: 2.523795 | N41: 2.2762145 | O41: 2.407479 | P41: 2.3057395 | Q41: 2.372532 | R41: 2.2287852 | S41: 2.0548681 | T41: 1.616145 | U41: 1.2337413 | V41: 0.76471013 | W41: 0.48013616 | X41: 0.30268906 | Y41: 0.20589064 | Z41: 1.6933372 | AA41: 2.2742697 | AB41: 0.76721871 | AC41: 1.5782752 | AD41: 1.1972525
A42: 92.5 CONCIERTO URBANA | B42: 0.0065090509 | C42: 0.0065090509 | D42: 0 | E42: 0 | F42: 0 | G42: 0 | H42: 0 | I42: 0.10206438 | J42: 0.25483538 | K42: 0.32513669 | L42: 0.22412075 | M42: 0.20902818 | N42: 0.1799665 | O42: 0.17575091 | P42: 0.25311168 | Q42: 0.18633548 | R42: 0.18741291 | S42: 0.17933646 | T42: 0.24039981 | U42: 0.14932338 | V42: 0.11123613 | W42: 0.020774608 | X42: 0 | Y42: 0.010967577 | Z42: 0.18586423 | AA42: 0.19365233 | AB42: 0.088783583 | AC42: 0.15610005 | AD42: 0.11761746
A43: 93.1 INOLVIDABLE | B43: 0.053973476 | C43: 0.022313126 | D43: 0.034869917 | E43: 0.034412527 | F43: 0.038902981 | G43: 0.047788826 | H43: 0.23803003 | I43: 0.49827501 | J43: 1.0562682 | K43: 1.1168204 | L43: 1.4018793 | M43: 1.5082853 | N43: 1.5896909 | O43: 1.5402114 | P43: 1.7573757 | Q43: 1.3115085 | R43: 1.4467056 | S43: 1.0434514 | T43: 1.0604668 | U43: 1.0437388 | V43: 0.88201068 | W43: 0.78665216 | X43: 0.30103503 | Y43: 0.090311426 | Z43: 0.96992637 | AA43: 1.4481573 | AB43: 0.69403581 | AC43: 1.0373731 | AD43: 0.7877074
A44: 93.9 OCEANO | B44: 0.0099829984 | C44: 0.0099829984 | D44: 0 | E44: 0 | F44: 0 | G44: 0.033039999 | H44: 0.1265232 | I44: 0.56033164 | J44: 0.94014574 | K44: 0.89576994 | L44: 0.86192718 | M44: 0.93517072 | N44: 1.3075939 | O44: 1.2856345 | P44: 1.263581 | Q44: 0.98754435 | R44: 0.91064729 | S44: 0.77346151 | T44: 0.35694342 | U44: 0.29619463 | V44: 0.12065849 | W44: 0.13119891 | X44: 0.045372279 | Y44: 0.03033678 | Z44: 0.71997807 | AA44: 1.0880771 | AB44: 0.16345075 | AC44: 0.65716864 | AD44: 0.49508507
A45: 94.7 E. DEL SUR | B45: 0 | C45: 0 | D45: 0.012556791 | E45: 0 | F45: 0 | G45: 0.028684961 | H45: 0.059094556 | I45: 0.11729626 | J45: 0.077433554 | K45: 0.18544457 | L45: 0.13880912 | M45: 0.15961458 | N45: 0.035059333 | O45: 0.055646931 | P45: 0.082756714 | Q45: 0.085558818 | R45: 0.11520035 | S45: 0.19000242 | T45: 0.09176139 | U45: 0.047535557 | V45: 0.040390821 | W45: 0.057386568 | X45: 0.027333684 | Y45: 0.05950513 | Z45: 0.12294877 | AA45: 0.094037428 | AB45: 0.053985525 | AC45: 0.090323909 | AD45: 0.069461338
A46: 95.5 DEL PLATA | B46: 0.12024565 | C46: 0.094134714 | D46: 0.078069957 | E46: 0.078069957 | F46: 0.013945174 | G46: 0 | H46: 0.033472338 | I46: 0.11832718 | J46: 0.45908097 | K46: 0.72053196 | L46: 0.6063378 | M46: 0.75630484 | N46: 0.69688749 | O46: 0.702528 | P46: 0.7542994 | Q46: 0.82510244 | R46: 0.90938928 | S46: 0.95301381 | T46: 0.70121642 | U46: 0.42773599 | V46: 0.34340196 | W46: 0.26531389 | X46: 0.21887856 | Y46: 0.19633204 | Z46: 0.44900918 | AA46: 0.80687007 | AB46: 0.35881314 | AC46: 0.5382308 | AD46: 0.41969249
A47: 96.3 ALFA | B47: 0 | C47: 0 | D47: 0 | E47: 0 | F47: 0 | G47: 0 | H47: 0 | I47: 0 | J47: 0.094013548 | K47: 0.11579978 | L47: 0.18690815 | M47: 0.126444 | N47: 0.17033758 | O47: 0.23018221 | P47: 0.19673678 | Q47: 0.15498896 | R47: 0.12220957 | S47: 0.12469984 | T47: 0.063024587 | U47: 0.12424545 | V47: 0.12443703 | W47: 0.13442589 | X47: 0.089625707 | Y47: 0.041375077 | Z47: 0.087194248 | AA47: 0.16652582 | AB47: 0.096188956 | AC47: 0.11663634 | AD47: 0.087477257
A48: 97.1 BABEL | B48: 0 | C48: 0 | D48: 0.016337722 | E48: 0.012099401 | F48: 0.04937675 | G48: 0.04937675 | H48: 0.13588729 | I48: 0.16702616 | J48: 0.19240155 | K48: 0.33431884 | L48: 0.20139994 | M48: 0.28317449 | N48: 0.22068526 | O48: 0.21662076 | P48: 0.17923504 | Q48: 0.16689317 | R48: 0.23130117 | S48: 0.30086368 | T48: 0.31941486 | U48: 0.38661587 | V48: 0.23600021 | W48: 0.19341135 | X48: 0.13054266 | Y48: 0.057941888 | Z48: 0.21903471 | AA48: 0.21926651 | AB48: 0.22065447 | AC48: 0.2196519 | AD48: 0.17003853
A49: 97.9 M24 | B49: 0.013915046 | C49: 0 | D49: 0 | E49: 0 | F49: 0.0090740772 | G49: 0.16711723 | H49: 0.16396339 | I49: 0.20255763 | J49: 0.27658183 | K49: 0.28129876 | L49: 0.26276698 | M49: 0.23005184 | N49: 0.16616242 | O49: 0.11177039 | P49: 0.095400096 | Q49: 0.17733575 | R49: 0.17549119 | S49: 0.10642854 | T49: 0.088367845 | U49: 0.087904628 | V49: 0.045372858 | W49: 0.11366244 | X49: 0.071979965 | Y49: 0.071979965 | Z49: 0.23620341 | AA49: 0.13876473 | AB49: 0.079877951 | AC49: 0.15161536 | AD49: 0.12163262
... A65: RATING GENERAL | B65: 2.0940512 | C65: 1.7042605 | D65: 1.3474499 | E65: 1.2566093 | F65: 1.6911294 | G65: 4.0222796 | H65: 10.571871 | I65: 21.121997 | J65: 29.490126 | K65: 33.772658 | L65: 32.734626 | M65: 33.367768 | N65: 29.026581 | O65: 26.528951 | P65: 27.301199 | Q65: 26.433651 | R65: 25.861463 | S65: 23.577808 | T65: 20.015946 | U65: 14.632453 | V65: 10.810167 | W65: 9.0232714 | X65: 6.5743296 | Y65: 4.6052294 | Z65: 26.843174 | AA65: 26.454942 | AB65: 10.943566 | AC65: 21.413894 | AD65: 16.565245

Sheet RatxHoraxSD
A1: CUADRO 7: RESUMEN DE RATING POR HORA | AM | SABADO A DOMINGO
A3: RADIOS | B3: HORAS | Z3: PROMEDIO
B4: 00:00 - 00:59 | C4: 01:00 - 01:59 | D4: 02:00 - 02:59 | E4: 03:00 - 03:59 | F4: 04:00 - 04:59 | G4: 05:00 - 05:59 | H4: 06:00 - 06:59 | I4: 07:00 - 07:59 | J4: 08:00 - 08:59 | K4: 09:00 - 09:59 | L4: 10:00 - 10:59 | M4: 11:00 - 11:59 | N4: 12:00 - 12:59 | O4: 13:00 - 13:59 | P4: 14:00 - 14:59 | Q4: 15:00 - 15:59 | R4: 16:00 - 16:59 | S4: 17:00 - 17:59 | T4: 18:00 - 18:59 | U4: 19:00 - 19:59 | V4: 20:00 - 20:59 | W4: 21:00 - 21:59 | X4: 22:00 - 22:59 | Y4: 23:00 - 23:59 | Z4: 06:00 - 11:59 | AA4: 12:00 - 17:59 | AB4: 18:00 - 23:59 | AC4: 06:00 - 23:59 | AD4: 00:00 - 24:00
A5: CX4 RURAL | B5: 0.099345616 | C5: 0.099345616 | D5: 0.039062487 | E5: 0 | F5: 0 | G5: 0 | H5: 0.10384976 | I5: 0.18998933 | J5: 0.16228068 | K5: 0.097670518 | L5: 0.13208173 | M5: 0.13208173 | N5: 0.044292222 | O5: 0.071794549 | P5: 0.15258754 | Q5: 0.07145406 | R5: 0.12508521 | S5: 0.091421813 | T5: 0.019967752 | U5: 0.064838574 | V5: 0.064838574 | W5: 0.057376162 | X5: 0.025716815 | Y5: 0.096438649 | Z5: 0.13632562 | AA5: 0.092772565 | AB5: 0.054862754 | AC5: 0.094653648 | AD5: 0.080896641
A6: CX6 CLÁSICA | B6: 0 | C6: 0 | D6: 0 | E6: 0 | F6: 0 | G6: 0 | H6: 0 | I6: 0 | J6: 0.059956736 | K6: 0.088876127 | L6: 0.077578169 | M6: 0.048658778 | N6: 0.048658778 | O6: 0.10861551 | P6: 0.10861551 | Q6: 0.048658778 | R6: 0.077578169 | S6: 0.048658778 | T6: 0.048658778 | U6: 0.080710763 | V6: 0.048658778 | W6: 0 | X6: 0 | Y6: 0.032051985 | Z6: 0.045844968 | AA6: 0.073464255 | AB6: 0.035013384 | AC6: 0.051440869 | AD6: 0.038580652
A7: CX8 SARANDI | B7: 0.067275403 | C7: 0.064060031 | D7: 0.036557704 | E7: 0.036557704 | F7: 0.1278941 | G7: 0.24597405 | H7: 0.80602054 | I7: 1.2338777 | J7: 1.495825 | K7: 1.5834518 | L7: 1.3337219 | M7: 1.2006401 | N7: 0.58165415 | O7: 0.41551527 | P7: 0.24174203 | Q7: 0.21382184 | R7: 0.3273137 | S7: 0.28772855 | T7: 0.17451363 | U7: 0.11923854 | V7: 0.11746718 | W7: 0.26061375 | X7: 0.2129878 | Y7: 0.13364953 | Z7: 1.2755895 | AA7: 0.34462926 | AB7: 0.16974507 | AC7: 0.59665461 | AD7: 0.47158758
A8: CX10 CONTINENTE | B8: 0 | C8: 0 | D8: 0 | E8: 0 | F8: 0.040104888 | G8: 0.040104888 | H8: 0.027708659 | I8: 0.027708659 | J8: 0.071184118 | K8: 0.084237265 | L8: 0.027708659 | M8: 0.024554738 | N8: 0 | O8: 0 | P8: 0.082723457 | Q8: 0.033208715 | R8: 0.079545333 | S8: 0.033208715 | T8: 0.057763453 | U8: 0.073968828 | V8: 0.15362589 | W8: 0.15450772 | X8: 0.15450772 | Y8: 0.12907115 | Z8: 0.04385035 | AA8: 0.03811437 | AB8: 0.12057413 | AC8: 0.067512949 | AD8: 0.053976786
A9: CX12 ORIENTAL | B9: 0.039616921 | C9: 0 | D9: 0 | E9: 0 | F9: 0 | G9: 0.025627954 | H9: 0 | I9: 0.19045464 | J9: 0.28380595 | K9: 0.27094685 | L9: 0.3704851 | M9: 0.23815589 | N9: 0.14480768 | O9: 0.25864655 | P9: 0.3182182 | Q9: 0.23455021 | R9: 0.26814236 | S9: 0.20458972 | T9: 0.19307053 | U9: 0.19830773 | V9: 0.064503813 | W9: 0.081434733 | X9: 0.015351927 | Y9: 0.11159134 | Z9: 0.2256414 | AA9: 0.23815912 | AB9: 0.11071001 | AC9: 0.19150351 | AD9: 0.14634617
A10: CX14 EL ESPECTADOR | B10: 0.17612163 | C10: 0.062343049 | D10: 0.032051985 | E10: 0 | F10: 0 | G10: 0.065079788 | H10: 0.11801485 | I10: 0.253402 | J10: 0.28190543 | K10: 0.31134475 | L10: 0.34683065 | M10: 0.33868107 | N10: 0.13518935 | O10: 0.22498713 | P10: 0.084228438 | Q10: 0.15509636 | R10: 0.12193347 | S10: 0.0833614 | T10: 0.1015696 | U10: 0.17787823 | V10: 0.14621888 | W10: 0.18432137 | X10: 0.26410659 | Y10: 0.28386188 | Z10: 0.27502979 | AA10: 0.13413269 | AB10: 0.19299276 | AC10: 0.20071841 | AD10: 0.164522
A11: CX16 CARVE | B11: 0.032805607 | C11: 0.060389042 | D11: 0.091531772 | E11: 0.091531772 | F11: 0.063948337 | G11: 0.032805607 | H11: 0.049123445 | I11: 0.14945095 | J11: 0.31656151 | K11: 0.32235888 | L11: 0.23916211 | M11: 0.16995033 | N11: 0.032805607 | O11: 0 | P11: 0.14069348 | Q11: 0.14331803 | R11: 0.19880526 | S11: 0.11235622 | T11: 0.1435643 | U11: 0.1435643 | V11: 0.1435643 | W11: 0.1435643 | X11: 0.044292222 | Y11: 0.044292222 | Z11: 0.20776787 | AA11: 0.1046631 | AB11: 0.11047361 | AC11: 0.14096819 | AD11: 0.12126832
A12: CX18 SPORT 890 | B12: 0 | C12: 0 | D12: 0 | E12: 0.05434987 | F12: 0.025436572 | G12: 0.16299372 | H12: 0.20421654 | I12: 0.39205067 | J12: 0.42680731 | K12: 0.47411194 | L12: 0.32520575 | M12: 0.52746082 | N12: 0.52903589 | O12: 0.30088443 | P12: 0.36766585 | Q12: 0.39885957 | R12: 0.43901395 | S12: 0.54647091 | T12: 0.47172213 | U12: 0.48350577 | V12: 0.25495769 | W12: 0.20396327 | X12: 0.027664225 | Y12: 0 | Z12: 0.39164217 | AA12: 0.43032177 | AB12: 0.24030218 | AC12: 0.35408871 | AD12: 0.27568237
A13: CX20 MONTECARLO | B13: 0.21164733 | C13: 0.2604579 | D13: 0.10314895 | E13: 0.17712568 | F13: 0.059889706 | G13: 0.38812824 | H13: 1.3913727 | I13: 2.3172599 | J13: 2.5303552 | K13: 3.0630099 | L13: 2.6403905 | M13: 2.7850079 | N13: 2.0986689 | O13: 1.4120019 | P13: 1.3767189 | Q13: 1.3444512 | R13: 1.2997251 | S13: 1.2292902 | T13: 0.7663944 | U13: 0.4765566 | V13: 0.24280122 | W13: 0.29920752 | X13: 0.14280639 | Y13: 0.087429197 | Z13: 2.454566 | AA13: 1.4601427 | AB13: 0.33586589 | AC13: 1.4168582 | AD13: 1.1126602
A14: CX22 UNIVERSAL | B14: 0 | C14: 0 | D14: 0 | E14: 0 | F14: 0 | G14: 0 | H14: 0 | I14: 0.091047254 | J14: 0.090459016 | K14: 0.14152763 | L14: 0.1123223 | M14: 0.18106796 | N14: 0.22869113 | O14: 0.16618227 | P14: 0.085801653 | Q14: 0.14192816 | R14: 0.26468545 | S14: 0.20795675 | T14: 0.22953454 | U14: 0.11840905 | V14: 0.055966531 | W14: 0.12058875 | X14: 0.091490322 | Y14: 0.062014025 | Z14: 0.10273736 | AA14: 0.1825409 | AB14: 0.11300053 | AC14: 0.1327596 | AD14: 0.099569699
A15: CX24 RADIO 1010 AM | B15: 0 | C15: 0 | D15: 0 | E15: 0 | F15: 0 | G15: 0 | H15: 0.030717699 | I15: 0 | J15: 0.0563107 | K15: 0.0563107 | L15: 0.0563107 | M15: 0.11111299 | N15: 0.0563107 | O15: 0 | P15: 0.054802293 | Q15: 0.027096299 | R15: 0.053683189 | S15: 0.053683189 | T15: 0 | U15: 0.030717699 | V15: 0.030717699 | W15: 0.030717699 | X15: 0.030717699 | Y15: 0 | Z15: 0.051793799 | AA15: 0.040929278 | AB15: 0.020478466 | AC15: 0.037733848 | AD15: 0.028300386
A16: CX26 RADIO URUGUAY | B16: 0.062712138 | C16: 0.062712138 | D16: 0.062712138 | E16: 0.093396512 | F16: 0.062678813 | G16: 0.042305105 | H16: 0.071680993 | I16: 0.17153037 | J16: 0.26525765 | K16: 0.28211804 | L16: 0.20735332 | M16: 0.20681853 | N16: 0.10464432 | O16: 0.13987782 | P16: 0.25739504 | Q16: 0.21575795 | R16: 0.11069225 | S16: 0.071076706 | T16: 0.059266495 | U16: 0.098882044 | V16: 0.059266495 | W16: 0.028582122 | X16: 0.028582122 | Y16: 0.028582122 | Z16: 0.20079315 | AA16: 0.14990735 | AB16: 0.0505269 | AC16: 0.13374247 | AD16: 0.11641172
... A32: RATING GENERAL | B32: 2.3418094 | C32: 1.8937098 | D32: 1.6546421 | E32: 1.4561491 | F32: 1.6478512 | G32: 3.0724042 | H32: 7.5514462 | I32: 15.491547 | J32: 20.882704 | K32: 25.021801 | L32: 25.69823 | M32: 25.168289 | N32: 21.528099 | O32: 19.143019 | P32: 18.601559 | Q32: 17.262614 | R32: 17.847502 | S32: 16.213338 | T32: 13.855241 | U32: 11.274196 | V32: 8.4708108 | W32: 7.9186999 | X32: 5.7729131 | Y32: 4.3148172 | Z32: 19.969003 | AA32: 18.432688 | AB32: 8.6011129 | AC32: 15.667601 | AD32: 12.253475
A34: CUADRO 8: RESUMEN DE RATING POR HORA | FM | SABADO A DOMINGO
A36: RADIOS | B36: HORAS | Z36: PROMEDIO
B37: 00:00 - 00:59 | C37: 01:00 - 01:59 | D37: 02:00 - 02:59 | E37: 03:00 - 03:59 | F37: 04:00 - 04:59 | G37: 05:00 - 05:59 | H37: 06:00 - 06:59 | I37: 07:00 - 07:59 | J37: 08:00 - 08:59 | K37: 09:00 - 09:59 | L37: 10:00 - 10:59 | M37: 11:00 - 11:59 | N37: 12:00 - 12:59 | O37: 13:00 - 13:59 | P37: 14:00 - 14:59 | Q37: 15:00 - 15:59 | R37: 16:00 - 16:59 | S37: 17:00 - 17:59 | T37: 18:00 - 18:59 | U37: 19:00 - 19:59 | V37: 20:00 - 20:59 | W37: 21:00 - 21:59 | X37: 22:00 - 22:59 | Y37: 23:00 - 23:59 | Z37: 06:00 - 11:59 | AA37: 12:00 - 17:59 | AB37: 18:00 - 23:59 | AC37: 06:00 - 23:59 | AD37: 00:00 - 24:00
A38: 88.3 LACOSTA | B38: 0.085613441 | C38: 0.060396052 | D38: 0.060396052 | E38: 0.060396052 | F38: 0.060396052 | G38: 0.060396052 | H38: 0.12404669 | I38: 0.22831646 | J38: 0.38787726 | K38: 0.27641237 | L38: 0.15100587 | M38: 0.059816162 | N38: 0.049217506 | O38: 0.051432126 | P38: 0.15776542 | Q38: 0.22885146 | R38: 0.22634748 | S38: 0.23898306 | T38: 0.10604393 | U38: 0.1337653 | V38: 0.078611924 | W38: 0.10633329 | X38: 0 | Y38: 0 | Z38: 0.20457914 | AA38: 0.15876617 | AB38: 0.070792409 | AC38: 0.14471257 | AD38: 0.12468417
A39: 90.3 OLDIES | B39: 0.10371168 | C39: 0.10371168 | D39: 0.075072706 | E39: 0.089684873 | F39: 0 | G39: 0 | H39: 0.039440958 | I39: 0.070340404 | J39: 0.3513178 | K39: 0.45259959 | L39: 0.63173115 | M39: 0.71937266 | N39: 0.86119097 | O39: 0.76818936 | P39: 0.72431667 | Q39: 0.52538377 | R39: 0.44340781 | S39: 0.41525439 | T39: 0.38647032 | U39: 0.18070933 | V39: 0.10778579 | W39: 0.16277177 | X39: 0.25788225 | Y39: 0.27940807 | Z39: 0.37746709 | AA39: 0.62295716 | AB39: 0.22917125 | AC39: 0.40986517 | AD39: 0.32290642
A40: 91.1 RADIOFUTURA | B40: 0.043429844 | C40: 0.043429844 | D40: 0 | E40: 0.028067986 | F40: 0.028067986 | G40: 0.081652989 | H40: 0 | I40: 0.061758262 | J40: 0.2728275 | K40: 0.46582542 | L40: 0.60802956 | M40: 0.59322665 | N40: 0.4015091 | O40: 0.42336598 | P40: 0.48866277 | Q40: 0.51897575 | R40: 0.56668587 | S40: 0.468986 | T40: 0.48416026 | U40: 0.40975526 | V40: 0.35106044 | W40: 0.29146221 | X40: 0.22707271 | Y40: 0.072186693 | Z40: 0.33361123 | AA40: 0.47803091 | AB40: 0.3059496 | AC40: 0.37253058 | AD40: 0.28875829
A41: 91.9 DISNEY | B41: 0.081432913 | C41: 0 | D41: 0 | E41: 0 | F41: 0.064767899 | G41: 0.19912103 | H41: 0.28356266 | I41: 0.67334283 | J41: 1.2317308 | K41: 1.7620842 | L41: 1.9247844 | M41: 1.8623415 | N41: 1.7017736 | O41: 1.7325906 | P41: 1.2140182 | Q41: 1.1829878 | R41: 0.94368388 | S41: 0.88367401 | T41: 0.62563241 | U41: 0.6881876 | V41: 0.51441163 | W41: 0.35691414 | X41: 0.25435316 | Y41: 0.13880015 | Z41: 1.289641 | AA41: 1.2764547 | AB41: 0.42971652 | AC41: 0.99860408 | AD41: 0.76334147
A42: 92.5 CONCIERTO URBANA | B42: 0 | C42: 0 | D42: 0.030122241 | E42: 0 | F42: 0 | G42: 0 | H42: 0.076206509 | I42: 0.2088246 | J42: 0.30091374 | K42: 0.21313051 | L42: 0.086330047 | M42: 0.1226301 | N42: 0.11233432 | O42: 0.14891374 | P42: 0.086330047 | Q42: 0.13886837 | R42: 0.24493062 | S42: 0.21480838 | T42: 0.14274874 | U42: 0.11078165 | V42: 0.19672835 | W42: 0.15214651 | X42: 0 | Y42: 0 | Z42: 0.16800592 | AA42: 0.15769758 | AB42: 0.10040088 | AC42: 0.14203479 | AD42: 0.10778119
A43: 93.1 INOLVIDABLE | B43: 0.070394647 | C43: 0 | D43: 0 | E43: 0 | F43: 0.022270072 | G43: 0.022270072 | H43: 0.28715679 | I43: 0.46091099 | J43: 0.71807142 | K43: 0.90971982 | L43: 1.085883 | M43: 1.0386171 | N43: 1.048777 | O43: 1.2366652 | P43: 1.0384317 | Q43: 0.93344409 | R43: 1.0575018 | S43: 0.88693287 | T43: 0.95888738 | U43: 1.2101998 | V43: 0.97831644 | W43: 0.68979326 | X43: 0.38338865 | Y43: 0.14319555 | Z43: 0.75005985 | AA43: 1.0336254 | AB43: 0.72729684 | AC43: 0.83699405 | AD43: 0.63253449
A44: 93.9 OCEANO | B44: 0 | C44: 0 | D44: 0.029454697 | E44: 0 | F44: 0 | G44: 0 | H44: 0.062289334 | I44: 0.34257164 | J44: 0.22739614 | K44: 0.41402643 | L44: 0.70005059 | M44: 0.65990781 | N44: 0.67991856 | O44: 0.59919144 | P44: 0.51182707 | Q44: 0.56479488 | R44: 0.52006347 | S44: 0.43317525 | T44: 0.3018284 | U44: 0.11260522 | V44: 0.11582206 | W44: 0.12706697 | X44: 0.050860457 | Y44: 0.050860457 | Z44: 0.40104032 | AA44: 0.55149511 | AB44: 0.12650726 | AC44: 0.3596809 | AD44: 0.27098795
A45: 94.7 E. DEL SUR | B45: 0.035362714 | C45: 0.035362714 | D45: 0.065484955 | E45: 0 | F45: 0 | G45: 0.041628046 | H45: 0.041628046 | I45: 0.041628046 | J45: 0.064516284 | K45: 0.20595058 | L45: 0.2120658 | M45: 0.13651876 | N45: 0.11415663 | O45: 0.11415663 | P45: 0.072881147 | Q45: 0.15832164 | R45: 0.14638004 | S45: 0.1162578 | T45: 0.1084319 | U45: 0.11803953 | V45: 0.076098967 | W45: 0.095806394 | X45: 0.068085024 | Y45: 0.068085024 | Z45: 0.11705125 | AA45: 0.12035898 | AB45: 0.08909114 | AC45: 0.10883379 | AD45: 0.089035279
A46: 95.5 DEL PLATA | B46: 0.15874598 | C46: 0.15874598 | D46: 0.17659934 | E46: 0.11416415 | F46: 0 | G46: 0 | H46: 0.063383045 | I46: 0.15689674 | J46: 0.23444961 | K46: 0.4392703 | L46: 0.58450142 | M46: 0.6347349 | N46: 0.74811919 | O46: 0.69681854 | P46: 0.52886265 | Q46: 0.37457353 | R46: 0.54287485 | S46: 0.5036895 | T46: 0.39968149 | U46: 0.25809416 | V46: 0.2326412 | W46: 0.13729604 | X46: 0.19328217 | Y46: 0.29317436 | Z46: 0.352206 | AA46: 0.56582304 | AB46: 0.25236157 | AC46: 0.39013021 | AD46: 0.31794163
A47: 96.3 ALFA | B47: 0 | C47: 0 | D47: 0 | E47: 0 | F47: 0 | G47: 0 | H47: 0 | I47: 0 | J47: 0.089981234 | K47: 0.040003471 | L47: 0.19576178 | M47: 0.088531585 | N47: 0.21472392 | O47: 0.30382344 | P47: 0.16923776 | Q47: 0.13929684 | R47: 0.13929684 | S47: 0.089319076 | T47: 0.089319076 | U47: 0.10433516 | V47: 0.10433516 | W47: 0.10433516 | X47: 0.10449715 | Y47: 0.028935473 | Z47: 0.069046344 | AA47: 0.17594964 | AB47: 0.089292865 | AC47: 0.11142962 | AD47: 0.083572213
A48: 97.1 BABEL | B48: 0 | C48: 0 | D48: 0 | E48: 0 | F48: 0.069493197 | G48: 0.14110226 | H48: 0.14110226 | I48: 0.13602933 | J48: 0.11218673 | K48: 0.29184901 | L48: 0.47438549 | M48: 0.36649156 | N48: 0.21559032 | O48: 0.17986342 | P48: 0.19233366 | Q48: 0.29807918 | R48: 0.32730174 | S48: 0.34418577 | T48: 0.39084433 | U48: 0.48904194 | V48: 0.37244823 | W48: 0.32321842 | X48: 0.22045287 | Y48: 0.071971831 | Z48: 0.25367406 | AA48: 0.25955901 | AB48: 0.3113296 | AC48: 0.27485423 | AD48: 0.21491548
A49: 97.9 M24 | B49: 0 | C49: 0 | D49: 0 | E49: 0 | F49: 0.024726612 | G49: 0.052228939 | H49: 0.15057405 | I49: 0.27692425 | J49: 0.37758049 | K49: 0.40438064 | L49: 0.30594085 | M49: 0.31538222 | N49: 0.19121394 | O49: 0.20537102 | P49: 0.17052575 | Q49: 0.17052575 | R49: 0.15263606 | S49: 0.089329265 | T49: 0.13275911 | U49: 0.13275911 | V49: 0.043429844 | W49: 0.026868106 | X49: 0 | Y49: 0 | Z49: 0.30513042 | AA49: 0.16326696 | AB49: 0.055969361 | AC49: 0.17478892 | AD49: 0.13429817
... A65: RATING GENERAL | B65: 2.3418094 | C65: 1.8937098 | D65: 1.6546421 | E65: 1.4561491 | F65: 1.6478512 | G65: 3.0724042 | H65: 7.5514462 | I65: 15.491547 | J65: 20.882704 | K65: 25.021801 | L65: 25.69823 | M65: 25.168289 | N65: 21.528099 | O65: 19.143019 | P65: 18.601559 | Q65: 17.262614 | R65: 17.847502 | S65: 16.213338 | T65: 13.855241 | U65: 11.274196 | V65: 8.4708108 | W65: 7.9186999 | X65: 5.7729131 | Y65: 4.3148172 | Z65: 19.969003 | AA65: 18.432688 | AB65: 8.6011129 | AC65: 15.667601 | AD65: 12.253475

Sheet RatxLDxABC1
A1: CUADRO 9: RESUMEN DE RATING POR HORA - SEGMENTO ABC1 | AM | LUNES A DOMINGO
A3: RADIOS | B3: HORAS | Z3: PROMEDIO
B4: 00:00 - 00:59 | C4: 01:00 - 01:59 | D4: 02:00 - 02:59 | E4: 03:00 - 03:59 | F4: 04:00 - 04:59 | G4: 05:00 - 05:59 | H4: 06:00 - 06:59 | I4: 07:00 - 07:59 | J4: 08:00 - 08:59 | K4: 09:00 - 09:59 | L4: 10:00 - 10:59 | M4: 11:00 - 11:59 | N4: 12:00 - 12:59 | O4: 13:00 - 13:59 | P4: 14:00 - 14:59 | Q4: 15:00 - 15:59 | R4: 16:00 - 16:59 | S4: 17:00 - 17:59 | T4: 18:00 - 18:59 | U4: 19:00 - 19:59 | V4: 20:00 - 20:59 | W4: 21:00 - 21:59 | X4: 22:00 - 22:59 | Y4: 23:00 - 23:59 | Z4: 06:00 - 11:59 | AA4: 12:00 - 17:59 | AB4: 18:00 - 23:59 | AC4: 06:00 - 23:59 | AD4: 00:00 - 24:00
A5: CX4 RURAL | B5: 0.079371587 | C5: 0 | D5: 0 | E5: 0 | F5: 0 | G5: 0 | H5: 0.28193646 | I5: 0.32811072 | J5: 0.32811072 | K5: 0.28193646 | L5: 0.41552334 | M5: 0.3783906 | N5: 0.3336483 | O5: 0.3336483 | P5: 0.28193646 | Q5: 0.28193646 | R5: 0.28193646 | S5: 0.28193646 | T5: 0.059805269 | U5: 0.10677017 | V5: 0.093160561 | W5: 0.046195664 | X5: 0.18779913 | Y5: 0.14229594 | Z5: 0.33566805 | AA5: 0.29917374 | AB5: 0.10600445 | AC5: 0.24694875 | AD5: 0.18851871
A6: CX6 CLÁSICA | B6: 0 | C6: 0 | D6: 0 | E6: 0 | F6: 0 | G6: 0 | H6: 0 | I6: 0.086489594 | J6: 0.086489594 | K6: 0.052841978 | L6: 0.11125588 | M6: 0.11125588 | N6: 0.058413899 | O6: 0.058413899 | P6: 0.058413899 | Q6: 0.058413899 | R6: 0.058413899 | S6: 0.058413899 | T6: 0.058413899 | U6: 0.058413899 | V6: 0.058413899 | W6: 0 | X6: 0 | Y6: 0 | Z6: 0.074722154 | AA6: 0.058413899 | AB6: 0.029206949 | AC6: 0.054114334 | AD6: 0.040585751
A7: CX8 SARANDI | B7: 0.053225303 | C7: 0.053225303 | D7: 0.053225303 | E7: 0.053225303 | F7: 0.32332329 | G7: 0.91603383 | H7: 2.4451054 | I7: 3.781733 | J7: 3.6145892 | K7: 3.7167753 | L7: 3.2911227 | M7: 2.8199927 | N7: 1.4820875 | O7: 0.34449871 | P7: 0.33561108 | Q7: 0.609042 | R7: 1.0547528 | S7: 0.91199734 | T7: 0.59442471 | U7: 0.36519112 | V7: 0.15855914 | W7: 0.41075713 | X7: 0.37233286 | Y7: 0.1416642 | Z7: 3.2782197 | AA7: 0.7896649 | AB7: 0.34048819 | AC7: 1.4694576 | AD7: 1.162604
A8: CX10 CONTINENTE | B8: 0 | C8: 0 | D8: 0 | E8: 0 | F8: 0 | G8: 0 | H8: 0 | I8: 0 | J8: 0 | K8: 0 | L8: 0 | M8: 0 | N8: 0 | O8: 0 | P8: 0 | Q8: 0.039866405 | R8: 0.039866405 | S8: 0.039866405 | T8: 0.039866405 | U8: 0.039866405 | V8: 0.039866405 | W8: 0.039866405 | X8: 0.098080715 | Y8: 0.039866405 | Z8: 0 | AA8: 0.019933202 | AB8: 0.04956879 | AC8: 0.023167331 | AD8: 0.017375498
A9: CX12 ORIENTAL | B9: 0 | C9: 0 | D9: 0 | E9: 0 | F9: 0 | G9: 0 | H9: 0.068875711 | I9: 0.85231248 | J9: 0.81901428 | K9: 1.3973363 | L9: 1.2114424 | M9: 0.75700303 | N9: 0.27482575 | O9: 0.36518952 | P9: 0.2820318 | Q9: 0.21183753 | R9: 0.25216425 | S9: 0.06591216 | T9: 0.1873454 | U9: 0.14701868 | V9: 0.081106524 | W9: 0.074322251 | X9: 0.19138537 | Y9: 0.37853435 | Z9: 0.85099738 | AA9: 0.2419935 | AB9: 0.17661876 | AC9: 0.42320321 | AD9: 0.31740241
A10: CX14 EL ESPECTADOR | B10: 0.14294031 | C10: 0 | D10: 0 | E10: 0 | F10: 0 | G10: 0.040892547 | H10: 0.82423223 | I10: 1.3035998 | J10: 1.6166386 | K10: 1.85894 | L10: 1.6965756 | M10: 1.2295605 | N10: 1.0663067 | O10: 0.71173785 | P10: 0.085697613 | Q10: 0.095146247 | R10: 0.1035039 | S10: 0.081894795 | T10: 0.1909842 | U10: 0.15197996 | V10: 0.11207887 | W10: 0.10175649 | X10: 0.56977857 | Y10: 0.9082799 | Z10: 1.4215911 | AA10: 0.35738118 | AB10: 0.339143 | AC10: 0.70603843 | AD10: 0.53718852
A11: CX16 CARVE | B11: 0 | C11: 0 | D11: 0 | E11: 0 | F11: 0.051711844 | G11: 0.051711844 | H11: 0.14307409 | I11: 0.28035415 | J11: 0.36837064 | K11: 0.3133889 | L11: 0.37476921 | M11: 0.22689589 | N11: 0.21748907 | O11: 0.14047575 | P11: 0.14610179 | Q11: 0.10327079 | R11: 0.10327079 | S11: 0.051558943 | T11: 0.47928923 | U11: 0.47928923 | V11: 0.47928923 | W11: 0.58613464 | X11: 0.16001734 | Y11: 0.053171935 | Z11: 0.28447548 | AA11: 0.12702786 | AB11: 0.37286527 | AC11: 0.2614562 | AD11: 0.20040147
A12: CX18 SPORT 890 | B12: 0 | C12: 0 | D12: 0 | E12: 0 | F12: 0 | G12: 0 | H12: 0.61381322 | I12: 0.76318068 | J12: 1.0174815 | K12: 1.1193306 | L12: 0.93659373 | M12: 0.89718241 | N12: 0.33827195 | O12: 0.28491581 | P12: 0.41937077 | Q12: 0.65401251 | R12: 0.56111891 | S12: 0.57559034 | T12: 0.20406334 | U12: 0.47795889 | V12: 0.50730567 | W12: 0.35487624 | X12: 0.17477658 | Y12: 0.1272743 | Z12: 0.89126368 | AA12: 0.47221338 | AB12: 0.30770917 | AC12: 0.55706208 | AD12: 0.41779656
A13: CX20 MONTECARLO | B13: 0.72333813 | C13: 0.65872061 | D13: 0.06759988 | E13: 0.06759988 | F13: 0.1178996 | G13: 0.30892158 | H13: 1.5753647 | I13: 3.0871811 | J13: 3.0267043 | K13: 3.1021937 | L13: 3.0349575 | M13: 2.8974928 | N13: 2.6791962 | O13: 1.3369335 | P13: 1.7678565 | Q13: 1.3899174 | R13: 0.7845261 | S13: 0.67292449 | T13: 1.1037065 | U13: 0.35006373 | V13: 0.48556128 | W13: 0.38536599 | X13: 0.23146911 | Y13: 0.042286239 | Z13: 2.7873157 | AA13: 1.438559 | AB13: 0.43307547 | AC13: 1.5529834 | AD13: 1.2457409
A14: CX22 UNIVERSAL | B14: 0 | C14: 0 | D14: 0 | E14: 0 | F14: 0 | G14: 0 | H14: 0 | I14: 0 | J14: 0.070686643 | K14: 0.070686643 | L14: 0.26968972 | M14: 0.38691392 | N14: 0.25444755 | O14: 0.036288861 | P14: 0.06353433 | Q14: 0.21135471 | R14: 0.2903878 | S14: 0.32164885 | T14: 0.19935044 | U14: 0.10363548 | V14: 0.037691534 | W14: 0.037691534 | X14: 0.037691534 | Y14: 0 | Z14: 0.13299615 | AA14: 0.19627702 | AB14: 0.069343421 | AC14: 0.1328722 | AD14: 0.099654148
A15: CX24 RADIO 1010 AM | B15: 0 | C15: 0 | D15: 0 | E15: 0 | F15: 0 | G15: 0 | H15: 0 | I15: 0 | J15: 0.38849685 | K15: 0.38954805 | L15: 0.38954805 | M15: 0.38954805 | N15: 0.63391397 | O15: 0.26756439 | P15: 0.12448657 | Q15: 0 | R15: 0.12509938 | S15: 0.061234273 | T15: 0.061234273 | U15: 0.061234273 | V15: 0.061234273 | W15: 0 | X15: 0 | Y15: 0 | Z15: 0.2595235 | AA15: 0.20204976 | AB15: 0.030617136 | AC15: 0.16406347 | AD15: 0.1230476
A16: CX26 RADIO URUGUAY | B16: 0 | C16: 0 | D16: 0 | E16: 0 | F16: 0 | G16: 0.095629132 | H16: 0.16571044 | I16: 0.46872734 | J16: 0.57908314 | K16: 0.53061224 | L16: 0.36941555 | M16: 0.32675889 | N16: 0.1798857 | O16: 0.20782437 | P16: 0.5625352 | Q16: 0.65222169 | R16: 0.3206725 | S16: 0.23153818 | T16: 0.071907651 | U16: 0 | V16: 0 | W16: 0 | X16: 0 | Y16: 0.039574105 | Z16: 0.40671793 | AA16: 0.35911294 | AB16: 0.018580293 | AC16: 0.26147039 | AD16: 0.20008734
... A32: RATING GENERAL | B32: 1.4354057 | C32: 1.0755746 | D32: 0.49730308 | E32: 0.57073428 | F32: 1.2980455 | G32: 3.2988831 | H32: 11.130713 | I32: 21.752671 | J32: 30.862634 | K32: 35.588366 | L32: 34.585628 | M32: 32.992028 | N32: 27.801299 | O32: 21.475339 | P32: 21.648205 | Q32: 22.141799 | R32: 22.880562 | S32: 20.793289 | T32: 18.52795 | U32: 13.167374 | V32: 9.1713621 | W32: 7.1620429 | X32: 5.6410947 | Y32: 4.4912099 | Z32: 27.818673 | AA32: 22.790082 | AB32: 9.6935055 | AC32: 20.100754 | AD32: 15.41623
A34: CUADRO 10: RESUMEN DE RATING POR HORA - SEGMENTO ABC1 | FM | LUNES A DOMINGO
A36: RADIOS | B36: HORAS | Z36: PROMEDIO
B37: 00:00 - 00:59 | C37: 01:00 - 01:59 | D37: 02:00 - 02:59 | E37: 03:00 - 03:59 | F37: 04:00 - 04:59 | G37: 05:00 - 05:59 | H37: 06:00 - 06:59 | I37: 07:00 - 07:59 | J37: 08:00 - 08:59 | K37: 09:00 - 09:59 | L37: 10:00 - 10:59 | M37: 11:00 - 11:59 | N37: 12:00 - 12:59 | O37: 13:00 - 13:59 | P37: 14:00 - 14:59 | Q37: 15:00 - 15:59 | R37: 16:00 - 16:59 | S37: 17:00 - 17:59 | T37: 18:00 - 18:59 | U37: 19:00 - 19:59 | V37: 20:00 - 20:59 | W37: 21:00 - 21:59 | X37: 22:00 - 22:59 | Y37: 23:00 - 23:59 | Z37: 06:00 - 11:59 | AA37: 12:00 - 17:59 | AB37: 18:00 - 23:59 | AC37: 06:00 - 23:59 | AD37: 00:00 - 24:00
