Workbook

Sheet INDICE CUADROS
A1: INDICE DE CUADROS
A3: =+RatABC1LV!A1 -> CUADRO 54: RESUMEN DE RATING POR HORA - SEGMENTO ABC1 | AM | LUNES A VIERNES
A4: =+RatABC1LV!A34 -> CUADRO 55: RESUMEN DE RATING POR HORA - SEGMENTO ABC1 | FM | LUNES A VIERNES
A5: =+RatABC1SD!A1 -> CUADRO 56: RESUMEN DE RATING POR HORA - SEGMENTO ABC1 | AM | SABADO A DOMINGO
A6: =+RatABC1SD!A34 -> CUADRO 57: RESUMEN DE RATING POR HORA - SEGMENTO ABC1 | FM | SABADO A DOMINGO
A7: =+RatC2C3D1LV!A1 -> CUADRO 58: RESUMEN DE RATING POR HORA - SEGMENTO C2C3D1 | AM | LUNES A VIERNES
A8: =+RatC2C3D1LV!A34 -> CUADRO 59: RESUMEN DE RATING POR HORA - SEGMENTO C2C3D1 | FM | LUNES A VIERNES
A9: =+RatC2C3D1SD!A1 -> CUADRO 60: RESUMEN DE RATING POR HORA - SEGMENTO C2C3D1 | AM | SABADO A DOMINGO
A10: =+RatC2C3D1SD!A34 -> CUADRO 61: RESUMEN DE RATING POR HORA - SEGMENTO C2C3D1 | FM | SABADO A DOMINGO
A11: =+RatD2ELV!A1 -> CUADRO 62: RESUMEN DE RATING POR HORA - SEGMENTO D2E | AM | LUNES A VIERNES
A12: =+RatD2ELV!A34 -> CUADRO 63: RESUMEN DE RATING POR HORA - SEGMENTO D2E | FM | LUNES A VIERNES
A13: =+RatD2ESD!A1 -> CUADRO 64: RESUMEN DE RATING POR HORA - SEGMENTO D2E | AM | SABADO A DOMINGO
A14: =+RatD2ESD!A34 -> CUADRO 65: RESUMEN DE RATING POR HORA - SEGMENTO D2E | FM | SABADO A DOMINGO
A15: =+RatxEdadxLVxAM!A1 -> CUADRO 66: RESUMEN DE RATING POR HORA SEGUN RADIO Y EDAD | AM | LUNES A VIERNES
A16: =+RatxEdadxSDxAM!A1 -> CUADRO 67: RESUMEN DE RATING POR HORA SEGUN RADIO Y EDAD | AM | SABADO A DOMINGO
A17: =+RatxEdadxLVxFM!A1 -> CUADRO 68: RESUMEN DE RATING POR HORA SEGUN RADIO Y EDAD | FM | LUNES A VIERNES
A18: =+RatxEdadxSDxFM!A1 -> CUADRO 69: RESUMEN DE RATING POR HORA SEGUN RADIO Y EDAD | FM | SABADO A DOMINGO
A19: =+RatxSexoxLV!A1 -> CUADRO 70: RESUMEN DE RATING POR HORA SEGUN RADIO Y SEXO | AM | LUNES A VIERNES
A20: =+RatxSexoxLV!A87 -> CUADRO 71: RESUMEN DE RATING POR HORA SEGUN RADIO Y SEXO | FM | LUNES A VIERNES
A21: =+RatxSexoxSD!A1 -> CUADRO 72: RESUMEN DE RATING POR HORA SEGUN RADIO Y SEXO | AM | SABADO A DOMINGO
A22: =+RatxSexoxSD!A87 -> CUADRO 73: RESUMEN DE RATING POR HORA SEGUN RADIO Y SEXO | FM | SABADO A DOMINGO
A23: =+PerfilNSExAM!A1 -> CUADROS 74 - 75: PERFIL POR NIVEL SOCIOECONOMICO SEGUN HORA | AM
A24: =+PerfilNSExFM!A1 -> CUADROS 76 - 77: PERFIL POR NIVEL SOCIOECONOMICO SEGUN HORA | FM
A25: =+PerfilEdadxAM!A1 -> CUADROS 78 - 79: PERFIL POR EDAD SEGUN HORA | AM
A26: =+PerfilEdadxFM!A1 -> CUADROS 80 - 81: PERFIL POR EDAD SEGUN HORA | FM
A27: =+PerfilSexoxAM!A1 -> CUADROS 82 - 83: PERFIL POR SEXO SEGUN HORA | AM
A28: =+PerfilSexoxFM!A1 -> CUADROS 84 - 85: PERFIL POR SEXO SEGUN HORA | FM

Sheet RatABC1LV
A1: CUADRO 54: RESUMEN DE RATING POR HORA - SEGMENTO ABC1 | AM | LUNES A VIERNES
A3: RADIOS | B3: HORAS | Z3: PROMEDIO
B4: 00:00 - 00:59 | C4: 01:00 - 01:59 | D4: 02:00 - 02:59 | E4: 03:00 - 03:59 | F4: 04:00 - 04:59 | G4: 05:00 - 05:59 | H4: 06:00 - 06:59 | I4: 07:00 - 07:59 | J4: 08:00 - 08:59 | K4: 09:00 - 09:59 | L4: 10:00 - 10:59 | M4: 11:00 - 11:59 | N4: 12:00 - 12:59 | O4: 13:00 - 13:59 | P4: 14:00 - 14:59 | Q4: 15:00 - 15:59 | R4: 16:00 - 16:59 | S4: 17:00 - 17:59 | T4: 18:00 - 18:59 | U4: 19:00 - 19:59 | V4: 20:00 - 20:59 | W4: 21:00 - 21:59 | X4: 22:00 - 22:59 | Y4: 23:00 - 23:59 | Z4: 06:00 - 11:59 | AA4: 12:00 - 17:59 | AB4: 18:00 - 23:59 | AC4: 06:00 - 23:59 | AD4: 00:00 - 24:00
A5: CX4 RURAL | B5: 0.11112022 | C5: 0 | D5: 0 | E5: 0 | F5: 0 | G5: 0 | H5: 0.32027033 | I5: 0.32027033 | J5: 0.32027033 | K5: 0.32027033 | L5: 0.50729196 | M5: 0.45530613 | N5: 0.39266691 | O5: 0.39266691 | P5: 0.32027033 | Q5: 0.32027033 | R5: 0.32027033 | S5: 0.32027033 | T5: 0.083727377 | U5: 0.083727377 | V5: 0.06467393 | W5: 0.06467393 | X5: 0.26291878 | Y5: 0.19921432 | Z5: 0.37394657 | AA5: 0.34440253 | AB5: 0.12648928 | AC5: 0.28161279 | AD5: 0.2158396
A6: CX6 CLÁSICA | B6: 0 | C6: 0 | D6: 0 | E6: 0 | F6: 0 | G6: 0 | H6: 0 | I6: 0.12108543 | J6: 0.12108543 | K6: 0.07397877 | L6: 0.07397877 | M6: 0.07397877 | N6: 0 | O6: 0 | P6: 0 | Q6: 0 | R6: 0 | S6: 0 | T6: 0 | U6: 0 | V6: 0 | W6: 0 | X6: 0 | Y6: 0 | Z6: 0.077351195 | AA6: 0 | AB6: 0 | AC6: 0.025783732 | AD6: 0.019337799
A7: CX8 SARANDI | B7: 0.074515425 | C7: 0.074515425 | D7: 0.074515425 | E7: 0.074515425 | F7: 0.34536845 | G7: 1.0355147 | H7: 2.5205422 | I7: 4.1174143 | J7: 3.8428652 | K7: 3.8749425 | L7: 3.326192 | M7: 2.8882754 | N7: 1.5489018 | O7: 0.19347989 | P7: 0.25995192 | Q7: 0.6427552 | R7: 1.0760077 | S7: 0.95216302 | T7: 0.60220117 | U7: 0.3517625 | V7: 0.063686005 | W7: 0.2199421 | X7: 0.16330331 | Y7: 0 | Z7: 3.4283719 | AA7: 0.77887659 | AB7: 0.23348251 | AC7: 1.4802437 | AD7: 1.1801388
A8: CX10 CONTINENTE | B8: 0 | C8: 0 | D8: 0 | E8: 0 | F8: 0 | G8: 0 | H8: 0 | I8: 0 | J8: 0 | K8: 0 | L8: 0 | M8: 0 | N8: 0 | O8: 0 | P8: 0 | Q8: 0 | R8: 0 | S8: 0 | T8: 0 | U8: 0 | V8: 0 | W8: 0 | X8: 0.081500034 | Y8: 0 | Z8: 0 | AA8: 0 | AB8: 0.013583339 | AC8: 0.0045277797 | AD8: 0.0033958348
A9: CX12 ORIENTAL | B9: 0 | C9: 0 | D9: 0 | E9: 0 | F9: 0 | G9: 0 | H9: 0.096425995 | I9: 0.98895738 | J9: 0.89066559 | K9: 1.6167098 | L9: 1.2415079 | M9: 0.8282319 | N9: 0.14138179 | O9: 0.19740272 | P9: 0.13743932 | Q9: 0.10965569 | R9: 0.10965569 | S9: 0 | T9: 0.056299567 | U9: 0.056299567 | V9: 0.056299567 | W9: 0.10405115 | X9: 0.26793952 | Y9: 0.43478423 | Z9: 0.94374975 | AA9: 0.11592253 | AB9: 0.16261227 | AC9: 0.40742818 | AD9: 0.30557114
A10: CX14 EL ESPECTADOR | B10: 0.13288371 | C10: 0 | D10: 0 | E10: 0 | F10: 0 | G10: 0 | H10: 1.009353 | I10: 1.5728844 | J10: 2.01225 | K10: 2.3337931 | L10: 1.9053511 | M10: 1.3026277 | N10: 1.3193925 | O10: 0.91031871 | P10: 0.11997666 | Q10: 0.13320475 | R10: 0.058791191 | S10: 0.11465271 | T10: 0.17273804 | U10: 0.21277194 | V10: 0.15691042 | W10: 0.14245908 | X10: 0.60890929 | Y10: 0.93379724 | Z10: 1.6893765 | AA10: 0.44272276 | AB10: 0.37126434 | AC10: 0.83445455 | AD10: 0.63137773
A11: CX16 CARVE | B11: 0 | C11: 0 | D11: 0 | E11: 0 | F11: 0.072396581 | G11: 0.072396581 | H11: 0.20030373 | I11: 0.26665247 | J11: 0.32517962 | K11: 0.19727247 | L11: 0.34440426 | M11: 0.20207755 | N11: 0.3044847 | O11: 0.19666605 | P11: 0.13235999 | Q11: 0.072396581 | R11: 0.072396581 | S11: 0 | T11: 0.42972039 | U11: 0.42972039 | V11: 0.42972039 | W11: 0.57930396 | X11: 0.14958357 | Y11: 0 | Z11: 0.25598168 | AA11: 0.12971732 | AB11: 0.33634145 | AC11: 0.24068015 | AD11: 0.18654316
A12: CX18 SPORT 890 | B12: 0 | C12: 0 | D12: 0 | E12: 0 | F12: 0 | G12: 0 | H12: 0.74376182 | I12: 0.8908639 | J12: 1.2263966 | K12: 1.2474374 | L12: 1.1896832 | M12: 0.94315512 | N12: 0.26174004 | O12: 0.39888214 | P12: 0.51493656 | Q12: 0.843435 | R12: 0.71338395 | S12: 0.56454194 | T12: 0.21350616 | U12: 0.43227466 | V12: 0.47336014 | W12: 0.25995894 | X12: 0.24468721 | Y12: 0.17818402 | Z12: 1.0402163 | AA12: 0.5494866 | AB12: 0.30032852 | AC12: 0.63001049 | AD12: 0.47250787
A13: CX20 MONTECARLO | B13: 0.79103912 | C13: 0.60593476 | D13: 0 | E13: 0 | F13: 0.16505944 | G13: 0.43249022 | H13: 1.6861017 | I13: 3.0716737 | J13: 2.9747164 | K13: 3.1647507 | L13: 3.2547658 | M13: 3.1650941 | N13: 2.9285969 | O13: 1.405578 | P13: 1.8139782 | Q13: 1.1890961 | R13: 0.50036555 | S13: 0.3640589 | T13: 1.0593999 | U13: 0.44096602 | V13: 0.61001477 | W13: 0.39530066 | X13: 0.32405676 | Y13: 0.059200735 | Z13: 2.8861837 | AA13: 1.3669456 | AB13: 0.48148981 | AC13: 1.5782064 | AD13: 1.2667599
A14: CX22 UNIVERSAL | B14: 0 | C14: 0 | D14: 0 | E14: 0 | F14: 0 | G14: 0 | H14: 0 | I14: 0 | J14: 0.0989613 | K14: 0.0989613 | L14: 0.37756561 | M14: 0.47754104 | N14: 0.24128371 | O14: 0 | P14: 0.088948061 | Q14: 0.29589659 | R14: 0.31991891 | S14: 0.36368438 | T14: 0.1885471 | U14: 0.054546157 | V14: 0.052768148 | W14: 0.052768148 | X14: 0.052768148 | Y14: 0 | Z14: 0.17550487 | AA14: 0.21828861 | AB14: 0.066899617 | AC14: 0.15356437 | AD14: 0.11517327
A15: CX24 RADIO 1010 AM | B15: 0 | C15: 0 | D15: 0 | E15: 0 | F15: 0 | G15: 0 | H15: 0 | I15: 0 | J15: 0.44925576 | K15: 0.45072743 | L15: 0.45072743 | M15: 0.45072743 | N15: 0.79283973 | O15: 0.37459014 | P15: 0.1742812 | Q15: 0 | R15: 0.17513914 | S15: 0.085727982 | T15: 0.085727982 | U15: 0.085727982 | V15: 0.085727982 | W15: 0 | X15: 0 | Y15: 0 | Z15: 0.30023968 | AA15: 0.26709637 | AB15: 0.042863991 | AC15: 0.20340001 | AD15: 0.15255001
A16: CX26 RADIO URUGUAY | B16: 0 | C16: 0 | D16: 0 | E16: 0 | F16: 0 | G16: 0.062779769 | H16: 0.11152236 | I16: 0.39741228 | J16: 0.50146343 | K16: 0.56806961 | L16: 0.46394224 | M16: 0.45746245 | N16: 0.25183998 | O16: 0.22975474 | P16: 0.47650125 | Q16: 0.60206234 | R16: 0.38105523 | S16: 0.25626718 | T16: 0.10067071 | U16: 0 | V16: 0 | W16: 0 | X16: 0 | Y16: 0.055403747 | Z16: 0.4166454 | AA16: 0.36624679 | AB16: 0.02601241 | AC16: 0.26963486 | AD16: 0.20484197
... A32: RATING GENERAL | B32: 1.3981113 | C32: 0.92371721 | D32: 0.28711027 | E32: 0.40388729 | F32: 1.3990931 | G32: 3.6328118 | H32: 12.081573 | I32: 23.917986 | J32: 34.072172 | K32: 39.296163 | L32: 37.400628 | M32: 36.246975 | N32: 30.506344 | O32: 23.765825 | P32: 23.99117 | Q32: 25.136621 | R32: 25.161099 | S32: 22.634374 | T32: 19.623433 | U32: 13.570832 | V32: 8.7310685 | W32: 6.3190906 | X32: 5.5682354 | Y32: 4.2671769 | Z32: 30.502583 | AA32: 25.199239 | AB32: 9.6799727 | AC32: 21.793931 | AD32: 16.680646
A34: CUADRO 55: RESUMEN DE RATING POR HORA - SEGMENTO ABC1 | FM | LUNES A VIERNES
A36: RADIOS | B36: HORAS | Z36: PROMEDIO
B37: 00:00 - 00:59 | C37: 01:00 - 01:59 | D37: 02:00 - 02:59 | E37: 03:00 - 03:59 | F37: 04:00 - 04:59 | G37: 05:00 - 05:59 | H37: 06:00 - 06:59 | I37: 07:00 - 07:59 | J37: 08:00 - 08:59 | K37: 09:00 - 09:59 | L37: 10:00 - 10:59 | M37: 11:00 - 11:59 | N37: 12:00 - 12:59 | O37: 13:00 - 13:59 | P37: 14:00 - 14:59 | Q37: 15:00 - 15:59 | R37: 16:00 - 16:59 | S37: 17:00 - 17:59 | T37: 18:00 - 18:59 | U37: 19:00 - 19:59 | V37: 20:00 - 20:59 | W37: 21:00 - 21:59 | X37: 22:00 - 22:59 | Y37: 23:00 - 23:59 | Z37: 06:00 - 11:59 | AA37: 12:00 - 17:59 | AB37: 18:00 - 23:59 | AC37: 06:00 - 23:59 | AD37: 00:00 - 24:00
A38: 88.3 LACOSTA | B38: 0 | C38: 0 | D38: 0 | E38: 0 | F38: 0 | G38: 0 | H38: 0 | I38: 0.55069064 | J38: 0.47695211 | K38: 0.47695211 | L38: 0.25606459 | M38: 0.18935736 | N38: 0.31310891 | O38: 0.31310891 | P38: 0.18935736 | Q38: 0.33559531 | R38: 0.48242399 | S38: 0.54382936 | T38: 0.2699895 | U38: 0 | V38: 0.12375155 | W38: 0 | X38: 0.12375155 | Y38: 0 | Z38: 0.3250028 | AA38: 0.36290397 | AB38: 0.086248767 | AC38: 0.25805185 | AD38: 0.19353888
A39: 90.3 OLDIES | B39: 0 | C39: 0 | D39: 0 | E39: 0 | F39: 0 | G39: 0 | H39: 0 | I39: 0.07609942 | J39: 0.33167677 | K39: 0.77402758 | L39: 1.4876666 | M39: 1.9867594 | N39: 2.3814278 | O39: 2.2345762 | P39: 1.6805714 | Q39: 1.601731 | R39: 1.3808303 | S39: 1.4558243 | T39: 1.1150304 | U39: 0.77695232 | V39: 0.5114957 | W39: 0.34599029 | X39: 0.38253759 | Y39: 0.22477986 | Z39: 0.77603828 | AA39: 1.7891602 | AB39: 0.55946435 | AC39: 1.0415543 | AD39: 0.7811657
A40: 91.1 RADIOFUTURA | B40: 0 | C40: 0 | D40: 0 | E40: 0 | F40: 0 | G40: 0 | H40: 0.3734592 | I40: 0.34474964 | J40: 0.31040279 | K40: 0.63244737 | L40: 0.40673344 | M40: 0.55127787 | N40: 0.17617816 | O40: 0.21097298 | P40: 0.41197718 | Q40: 0.11363361 | R40: 0.11363361 | S40: 0.05730429 | T40: 0.52180666 | U40: 1.0105079 | V40: 0.98381839 | W40: 0.54015877 | X40: 0.33710583 | Y40: 0.1699904 | Z40: 0.43651172 | AA40: 0.18061664 | AB40: 0.593898 | AC40: 0.40367545 | AD40: 0.30275659
A41: 91.9 DISNEY | B41: 0 | C41: 0 | D41: 0 | E41: 0 | F41: 0 | G41: 0 | H41: 0.31542549 | I41: 0.87971382 | J41: 1.2016164 | K41: 1.598212 | L41: 1.9951894 | M41: 2.2968884 | N41: 2.2037973 | O41: 2.4011486 | P41: 2.6387577 | Q41: 2.8692513 | R41: 2.6012368 | S41: 2.6043391 | T41: 2.4559365 | U41: 1.3967146 | V41: 0.65569205 | W41: 0.37462446 | X41: 0.22117394 | Y41: 0.15161375 | Z41: 1.3811743 | AA41: 2.5530885 | AB41: 0.87595922 | AC41: 1.6034073 | AD41: 1.2025555
A42: 92.5 CONCIERTO URBANA | B42: 0 | C42: 0 | D42: 0 | E42: 0 | F42: 0 | G42: 0 | H42: 0 | I42: 0.38026384 | J42: 1.0457008 | K42: 0.9906214 | L42: 0.5661847 | M42: 0.43876432 | N42: 0.30129128 | O42: 0.3213594 | P42: 0.60862399 | Q42: 0.52000432 | R42: 0.575847 | S42: 0.32513199 | T42: 0.56163201 | U42: 0.41580694 | V42: 0.30227305 | W42: 0 | X42: 0 | Y42: 0 | Z42: 0.57025584 | AA42: 0.442043 | AB42: 0.21328533 | AC42: 0.40852805 | AD42: 0.30639604
A43: 93.1 INOLVIDABLE | B43: 0 | C43: 0 | D43: 0 | E43: 0 | F43: 0 | G43: 0 | H43: 0.28238063 | I43: 0.32202164 | J43: 0.9640593 | K43: 1.2096782 | L43: 1.5016313 | M43: 1.9756435 | N43: 1.6828366 | O43: 1.3495933 | P43: 1.4761463 | Q43: 1.5774314 | R43: 1.5342836 | S43: 1.2470368 | T43: 1.0656465 | U43: 0.40667608 | V43: 0.47318458 | W43: 0.17299257 | X43: 0.11565513 | Y43: 0.22173042 | Z43: 1.0425691 | AA43: 1.477888 | AB43: 0.40931422 | AC43: 0.97659044 | AD43: 0.73244283
A44: 93.9 OCEANO | B44: 0 | C44: 0 | D44: 0 | E44: 0 | F44: 0 | G44: 0 | H44: 0.10304213 | I44: 0.64424952 | J44: 1.7054074 | K44: 1.7011494 | L44: 1.5078027 | M44: 1.2122845 | N44: 1.5798054 | O44: 1.4701223 | P44: 1.878582 | Q44: 1.5616292 | R44: 1.4852294 | S44: 1.1929897 | T44: 0.44226835 | U44: 0.52368673 | V44: 0.086568864 | W44: 0.18890357 | X44: 0.12140459 | Y44: 0.058230223 | Z44: 1.1456559 | AA44: 1.5280597 | AB44: 0.23684372 | AC44: 0.97018644 | AD44: 0.72763983
A45: 94.7 E. DEL SUR | B45: 0 | C45: 0 | D45: 0 | E45: 0 | F45: 0 | G45: 0 | H45: 0 | I45: 0.14422908 | J45: 0.14422908 | K45: 0.43058487 | L45: 0.3628122 | M45: 0.11263216 | N45: 0.049084302 | O45: 0.049084302 | P45: 0.10273625 | Q45: 0 | R45: 0.34533095 | S45: 0.44258276 | T45: 0.1851972 | U45: 0.088532074 | V45: 0.047106662 | W45: 0.14509939 | X45: 0 | Y45: 0 | Z45: 0.19908123 | AA45: 0.16480309 | AB45: 0.077655887 | AC45: 0.14718007 | AD45: 0.11038505
A46: 95.5 DEL PLATA | B46: 0.12629017 | C46: 0.067498977 | D46: 0 | E46: 0 | F46: 0 | G46: 0 | H46: 0.086348381 | I46: 0.26008794 | J46: 0.64104291 | K46: 0.76846111 | L46: 0.65705782 | M46: 0.79671488 | N46: 0.83038269 | O46: 0.74101613 | P46: 1.0433991 | Q46: 0.93302177 | R46: 1.0009668 | S46: 0.87678062 | T46: 1.0657685 | U46: 0.94471805 | V46: 0.46743295 | W46: 0.38498548 | X46: 0.26052678 | Y46: 0.16348592 | Z46: 0.53495217 | AA46: 0.90426118 | AB46: 0.54781961 | AC46: 0.66234432 | AD46: 0.50483279
A47: 96.3 ALFA | B47: 0 | C47: 0 | D47: 0 | E47: 0 | F47: 0 | G47: 0 | H47: 0 | I47: 0 | J47: 0.32094824 | K47: 0.19294151 | L47: 0.46000733 | M47: 0.17699409 | N47: 0.17699409 | O47: 0.16896109 | P47: 0.10618132 | Q47: 0.1944893 | R47: 0.1944893 | S47: 0.25726907 | T47: 0.11873472 | U47: 0.36623715 | V47: 0.3102822 | W47: 0.3102822 | X47: 0.3102822 | Y47: 0.12590362 | Z47: 0.1918152 | AA47: 0.18306403 | AB47: 0.25695368 | AC47: 0.21061097 | AD47: 0.15795823
A48: 97.1 BABEL | B48: 0 | C48: 0 | D48: 0.068645889 | E48: 0 | F48: 0 | G48: 0 | H48: 0 | I48: 0 | J48: 0 | K48: 0.5133963 | L48: 0.19852671 | M48: 0.43312467 | N48: 0.27006496 | O48: 0.13511792 | P48: 0.066472031 | Q48: 0.089811064 | R48: 0.41537449 | S48: 0.49293981 | T48: 0.56716814 | U48: 0.66751766 | V48: 0.28634236 | W48: 0.28634236 | X48: 0.23359236 | Y48: 0.069736963 | Z48: 0.19084128 | AA48: 0.24496338 | AB48: 0.35178331 | AC48: 0.26252932 | AD48: 0.19975724
A49: 97.9 M24 | B49: 0 | C49: 0 | D49: 0 | E49: 0 | F49: 0 | G49: 0 | H49: 0.066381425 | I49: 0.21251673 | J49: 0.26174072 | K49: 0.3716929 | L49: 0.3716929 | M49: 0.27465204 | N49: 0.31249216 | O49: 0.20827061 | P49: 0.059200735 | Q49: 0.1174601 | R49: 0.1174601 | S49: 0.058259369 | T49: 0.058259369 | U49: 0 | V49: 0 | W49: 0 | X49: 0 | Y49: 0 | Z49: 0.25977945 | AA49: 0.14552385 | AB49: 0.0097098949 | AC49: 0.13833773 | AD49: 0.1037533
... A65: RATING GENERAL | B65: 1.3981113 | C65: 0.92371721 | D65: 0.28711027 | E65: 0.40388729 | F65: 1.3990931 | G65: 3.6328118 | H65: 12.081573 | I65: 23.917986 | J65: 34.072172 | K65: 39.296163 | L65: 37.400628 | M65: 36.246975 | N65: 30.506344 | O65: 23.765825 | P65: 23.99117 | Q65: 25.136621 | R65: 25.161099 | S65: 22.634374 | T65: 19.623433 | U65: 13.570832 | V65: 8.7310685 | W65: 6.3190906 | X65: 5.5682354 | Y65: 4.2671769 | Z65: 30.502583 | AA65: 25.199239 | AB65: 9.6799727 | AC65: 21.793931 | AD65: 16.680646

Sheet RatABC1SD
A1: CUADRO 56: RESUMEN DE RATING POR HORA - SEGMENTO ABC1 | AM | SABADO A DOMINGO
A3: RADIOS | B3: HORAS | Z3: PROMEDIO
B4: 00:00 - 00:59 | C4: 01:00 - 01:59 | D4: 02:00 - 02:59 | E4: 03:00 - 03:59 | F4: 04:00 - 04:59 | G4: 05:00 - 05:59 | H4: 06:00 - 06:59 | I4: 07:00 - 07:59 | J4: 08:00 - 08:59 | K4: 09:00 - 09:59 | L4: 10:00 - 10:59 | M4: 11:00 - 11:59 | N4: 12:00 - 12:59 | O4: 13:00 - 13:59 | P4: 14:00 - 14:59 | Q4: 15:00 - 15:59 | R4: 16:00 - 16:59 | S4: 17:00 - 17:59 | T4: 18:00 - 18:59 | U4: 19:00 - 19:59 | V4: 20:00 - 20:59 | W4: 21:00 - 21:59 | X4: 22:00 - 22:59 | Y4: 23:00 - 23:59 | Z4: 06:00 - 11:59 | AA4: 12:00 - 17:59 | AB4: 18:00 - 23:59 | AC4: 06:00 - 23:59 | AD4: 00:00 - 24:00
A5: CX4 RURAL | B5: 0 | C5: 0 | D5: 0 | E5: 0 | F5: 0 | G5: 0 | H5: 0.18610177 | I5: 0.34771169 | J5: 0.34771169 | K5: 0.18610177 | L5: 0.18610177 | M5: 0.18610177 | N5: 0.18610177 | O5: 0.18610177 | P5: 0.18610177 | Q5: 0.18610177 | R5: 0.18610177 | S5: 0.18610177 | T5: 0 | U5: 0.16437714 | V5: 0.16437714 | W5: 0 | X5: 0 | Y5: 0 | Z5: 0.23997174 | AA5: 0.18610177 | AB5: 0.054792379 | AC5: 0.16028863 | AD5: 0.12021647
A6: CX6 CLÁSICA | B6: 0 | C6: 0 | D6: 0 | E6: 0 | F6: 0 | G6: 0 | H6: 0 | I6: 0 | J6: 0 | K6: 0 | L6: 0.20444865 | M6: 0.20444865 | N6: 0.20444865 | O6: 0.20444865 | P6: 0.20444865 | Q6: 0.20444865 | R6: 0.20444865 | S6: 0.20444865 | T6: 0.20444865 | U6: 0.20444865 | V6: 0.20444865 | W6: 0 | X6: 0 | Y6: 0 | Z6: 0.068149549 | AA6: 0.20444865 | AB6: 0.10222432 | AC6: 0.12494084 | AD6: 0.09370563
A7: CX8 SARANDI | B7: 0 | C7: 0 | D7: 0 | E7: 0 | F7: 0.26821039 | G7: 0.61733173 | H7: 2.2565132 | I7: 2.9425297 | J7: 3.0438994 | K7: 3.3213574 | L7: 3.2034496 | M7: 2.6492861 | N7: 1.3150518 | O7: 0.72204577 | P7: 0.52475898 | Q7: 0.52475898 | R7: 1.0016155 | S7: 0.81158314 | T7: 0.57498356 | U7: 0.39876269 | V7: 0.39574198 | W7: 0.88779471 | X7: 0.89490674 | Y7: 0.49582471 | Z7: 2.9028392 | AA7: 0.81663569 | AB7: 0.6080024 | AC7: 1.4424924 | AD7: 1.1187669
A8: CX10 CONTINENTE | B8: 0 | C8: 0 | D8: 0 | E8: 0 | F8: 0 | G8: 0 | H8: 0 | I8: 0 | J8: 0 | K8: 0 | L8: 0 | M8: 0 | N8: 0 | O8: 0 | P8: 0 | Q8: 0.13953242 | R8: 0.13953242 | S8: 0.13953242 | T8: 0.13953242 | U8: 0.13953242 | V8: 0.13953242 | W8: 0.13953242 | X8: 0.13953242 | Y8: 0.13953242 | Z8: 0 | AA8: 0.069766208 | AB8: 0.13953242 | AC8: 0.069766208 | AD8: 0.052324656
A9: CX12 ORIENTAL | B9: 0 | C9: 0 | D9: 0 | E9: 0 | F9: 0 | G9: 0 | H9: 0 | I9: 0.5107002 | J9: 0.63988601 | K9: 0.84890278 | L9: 1.1362789 | M9: 0.57893085 | N9: 0.60843565 | O9: 0.78465652 | P9: 0.64351301 | Q9: 0.46729214 | R9: 0.60843565 | S9: 0.23069256 | T9: 0.51495999 | U9: 0.37381648 | V9: 0.14312392 | W9: 0 | X9: 0 | Y9: 0.23790964 | Z9: 0.61911646 | AA9: 0.55717092 | AB9: 0.211635 | AC9: 0.46264079 | AD9: 0.3469806
A10: CX14 EL ESPECTADOR | B10: 0.16808181 | C10: 0 | D10: 0 | E10: 0 | F10: 0 | G10: 0.14312392 | H10: 0.3614303 | I10: 0.6303882 | J10: 0.62761016 | K10: 0.67180728 | L10: 1.1746367 | M10: 1.0468923 | N10: 0.43359206 | O10: 0.21528568 | P10: 0 | Q10: 0 | R10: 0.21528568 | S10: 0 | T10: 0.23659958 | U10: 0 | V10: 0 | W10: 0 | X10: 0.47195178 | Y10: 0.84448656 | Z10: 0.7521275 | AA10: 0.14402724 | AB10: 0.25883965 | AC10: 0.38499813 | AD10: 0.3017155
A11: CX16 CARVE | B11: 0 | C11: 0 | D11: 0 | E11: 0 | F11: 0 | G11: 0 | H11: 0 | I11: 0.31460835 | J11: 0.47634818 | K11: 0.60367999 | L11: 0.45068156 | M11: 0.28894172 | N11: 0 | O11: 0 | P11: 0.1804563 | Q11: 0.1804563 | R11: 0.1804563 | S11: 0.1804563 | T11: 0.60321133 | U11: 0.60321133 | V11: 0.60321133 | W11: 0.60321133 | X11: 0.18610177 | Y11: 0.18610177 | Z11: 0.35570997 | AA11: 0.1203042 | AB11: 0.46417481 | AC11: 0.31339633 | AD11: 0.23504725
A12: CX18 SPORT 890 | B12: 0 | C12: 0 | D12: 0 | E12: 0 | F12: 0 | G12: 0 | H12: 0.28894172 | I12: 0.44397263 | J12: 0.49519368 | K12: 0.79906365 | L12: 0.30386997 | M12: 0.78225063 | N12: 0.52960171 | O12: 0 | P12: 0.1804563 | Q12: 0.1804563 | R12: 0.1804563 | S12: 0.60321133 | T12: 0.1804563 | U12: 0.59216948 | V12: 0.59216948 | W12: 0.59216948 | X12: 0 | Y12: 0 | Z12: 0.51888205 | AA12: 0.27903032 | AB12: 0.32616079 | AC12: 0.37469105 | AD12: 0.28101829
A13: CX20 MONTECARLO | B13: 0.55408563 | C13: 0.79068521 | D13: 0.23659958 | E13: 0.23659958 | F13: 0 | G13: 0 | H13: 1.2985221 | I13: 3.1259496 | J13: 3.156674 | K13: 2.9458011 | L13: 2.4854368 | M13: 2.2284897 | N13: 2.0556944 | O13: 1.1653221 | P13: 1.6525525 | Q13: 1.8919707 | R13: 1.4949275 | S13: 1.4450885 | T13: 1.2144728 | U13: 0.12280802 | V13: 0.17442757 | W13: 0.36052934 | X13: 0 | Y13: 0 | Z13: 2.5401456 | AA13: 1.6175926 | AB13: 0.31203962 | AC13: 1.4899259 | AD13: 1.1931932
A14: CX22 UNIVERSAL | B14: 0 | C14: 0 | D14: 0 | E14: 0 | F14: 0 | G14: 0 | H14: 0 | I14: 0 | J14: 0 | K14: 0 | L14: 0 | M14: 0.16034614 | N14: 0.28735716 | O14: 0.12701101 | P14: 0 | Q14: 0 | R14: 0.21656003 | S14: 0.21656003 | T14: 0.22635879 | U14: 0.22635879 | V14: 0 | W14: 0 | X14: 0 | Y14: 0 | Z14: 0.026724357 | AA14: 0.14124804 | AB14: 0.075452931 | AC14: 0.081141776 | AD14: 0.060856332
A15: CX24 RADIO 1010 AM | B15: 0 | C15: 0 | D15: 0 | E15: 0 | F15: 0 | G15: 0 | H15: 0 | I15: 0 | J15: 0.23659958 | K15: 0.23659958 | L15: 0.23659958 | M15: 0.23659958 | N15: 0.23659958 | O15: 0 | P15: 0 | Q15: 0 | R15: 0 | S15: 0 | T15: 0 | U15: 0 | V15: 0 | W15: 0 | X15: 0 | Y15: 0 | Z15: 0.15773305 | AA15: 0.039433263 | AB15: 0 | AC15: 0.065722105 | AD15: 0.049291579
A16: CX26 RADIO URUGUAY | B16: 0 | C16: 0 | D16: 0 | E16: 0 | F16: 0 | G16: 0.17775254 | H16: 0.30118064 | I16: 0.647015 | J16: 0.77313243 | K16: 0.4369688 | L16: 0.13309883 | M16: 0 | N16: 0 | O16: 0.15299843 | P16: 0.77762008 | Q16: 0.77762008 | R16: 0.16971568 | S16: 0.16971568 | T16: 0 | U16: 0 | V16: 0 | W16: 0 | X16: 0 | Y16: 0 | Z16: 0.38189928 | AA16: 0.34127833 | AB16: 0 | AC16: 0.2410592 | AD16: 0.18820076
... A32: RATING GENERAL | B32: 1.5286417 | C32: 1.455218 | D32: 1.0227851 | E32: 0.98785176 | F32: 0.91350636 | G32: 2.4640613 | H32: 8.6216409 | I32: 16.339381 | J32: 22.690989 | K32: 26.186955 | L32: 27.548129 | M32: 24.854663 | N32: 21.038685 | O32: 15.749124 | P32: 15.790792 | Q32: 14.654745 | R32: 17.179219 | S32: 16.190577 | T32: 15.789244 | U32: 12.158728 | V32: 10.272096 | W32: 9.2694235 | X32: 5.8232428 | Y32: 5.0512924 | Z32: 21.040293 | AA32: 16.76719 | AB32: 9.7273377 | AC32: 15.84494 | AD32: 12.232541
A34: CUADRO 57: RESUMEN DE RATING POR HORA - SEGMENTO ABC1 | FM | SABADO A DOMINGO
A36: RADIOS | B36: HORAS | Z36: PROMEDIO
B37: 00:00 - 00:59 | C37: 01:00 - 01:59 | D37: 02:00 - 02:59 | E37: 03:00 - 03:59 | F37: 04:00 - 04:59 | G37: 05:00 - 05:59 | H37: 06:00 - 06:59 | I37: 07:00 - 07:59 | J37: 08:00 - 08:59 | K37: 09:00 - 09:59 | L37: 10:00 - 10:59 | M37: 11:00 - 11:59 | N37: 12:00 - 12:59 | O37: 13:00 - 13:59 | P37: 14:00 - 14:59 | Q37: 15:00 - 15:59 | R37: 16:00 - 16:59 | S37: 17:00 - 17:59 | T37: 18:00 - 18:59 | U37: 19:00 - 19:59 | V37: 20:00 - 20:59 | W37: 21:00 - 21:59 | X37: 22:00 - 22:59 | Y37: 23:00 - 23:59 | Z37: 06:00 - 11:59 | AA37: 12:00 - 17:59 | AB37: 18:00 - 23:59 | AC37: 06:00 - 23:59 | AD37: 00:00 - 24:00
A38: 88.3 LACOSTA | B38: 0 | C38: 0 | D38: 0 | E38: 0 | F38: 0 | G38: 0 | H38: 0 | I38: 0 | J38: 0.70378151 | K38: 0.70378151 | L38: 0 | M38: 0 | N38: 0 | O38: 0 | P38: 0.3303022 | Q38: 0.3303022 | R38: 0.3303022 | S38: 0.3303022 | T38: 0.3303022 | U38: 0.3303022 | V38: 0.3303022 | W38: 0.3303022 | X38: 0 | Y38: 0 | Z38: 0.23459384 | AA38: 0.22020147 | AB38: 0.22020147 | AC38: 0.22499892 | AD38: 0.16874919
A39: 90.3 OLDIES | B39: 0 | C39: 0 | D39: 0 | E39: 0 | F39: 0 | G39: 0 | H39: 0 | I39: 0 | J39: 0.28828446 | K39: 0.55049513 | L39: 1.366263 | M39: 1.8004403 | N39: 2.3667886 | O39: 2.0379832 | P39: 1.7460235 | Q39: 1.0635337 | R39: 0.84983425 | S39: 0.8723901 | T39: 0.71570554 | U39: 0.29658732 | V39: 0 | W39: 0.14264476 | X39: 0.426457 | Y39: 0.426457 | Z39: 0.66758048 | AA39: 1.4894256 | AB39: 0.33464194 | AC39: 0.83054933 | AD39: 0.622912
A40: 91.1 RADIOFUTURA | B40: 0 | C40: 0 | D40: 0 | E40: 0 | F40: 0 | G40: 0 | H40: 0 | I40: 0.12315809 | J40: 0.39735708 | K40: 0.274199 | L40: 0.274199 | M40: 0.41373141 | N40: 0.14835717 | O40: 0.14835717 | P40: 0.14835717 | Q40: 0 | R40: 0.17568706 | S40: 0.41300576 | T40: 0.58869283 | U40: 0.46598156 | V40: 0 | W40: 0 | X40: 0 | Y40: 0 | Z40: 0.24710743 | AA40: 0.17229405 | AB40: 0.17577906 | AC40: 0.19839352 | AD40: 0.14879514
A41: 91.9 DISNEY | B41: 0 | C41: 0 | D41: 0 | E41: 0 | F41: 0 | G41: 0 | H41: 0 | I41: 0.39345029 | J41: 0.95509862 | K41: 1.5481772 | L41: 1.8332113 | M41: 1.6634956 | N41: 1.7183868 | O41: 1.6429394 | P41: 1.0488755 | Q41: 0.89325727 | R41: 0.89325727 | S41: 0.9719903 | T41: 1.3543663 | U41: 1.3719692 | V41: 0.80173513 | W41: 0.33060426 | X41: 0.16034614 | Y41: 0 | Z41: 1.0655722 | AA41: 1.1947844 | AB41: 0.66983683 | AC41: 0.97673113 | AD41: 0.73254835
A42: 92.5 CONCIERTO URBANA | B42: 0 | C42: 0 | D42: 0 | E42: 0 | F42: 0 | G42: 0 | H42: 0.32019542 | I42: 0.69661951 | J42: 1.0835487 | K42: 0.76335326 | L42: 0.23057821 | M42: 0.38309945 | N42: 0.33983986 | O42: 0.49353488 | P42: 0.23057821 | Q42: 0.1399273 | R42: 0.45900295 | S42: 0.45900295 | T42: 0.15252124 | U42: 0.15252124 | V42: 0.82658969 | W42: 0.63927107 | X42: 0 | Y42: 0 | Z42: 0.57956575 | AA42: 0.35364769 | AB42: 0.29515054 | AC42: 0.40945466 | AD42: 0.307091
A43: 93.1 INOLVIDABLE | B43: 0.13152607 | C43: 0 | D43: 0 | E43: 0 | F43: 0 | G43: 0 | H43: 0.30087841 | I43: 0.31596435 | J43: 0.61886646 | K43: 0.61886646 | L43: 0.94436175 | M43: 0.78778879 | N43: 0.64159409 | O43: 1.3312989 | P43: 1.0597217 | Q43: 1.0555649 | R43: 1.2252234 | S43: 1.0924655 | T43: 1.4383569 | U43: 1.6071036 | V43: 1.1953297 | W43: 0.54617938 | X43: 0.32549528 | Y43: 0.3004484 | Z43: 0.5977877 | AA43: 1.0676448 | AB43: 0.90215222 | AC43: 0.85586156 | AD43: 0.64737642
A44: 93.9 OCEANO | B44: 0 | C44: 0 | D44: 0 | E44: 0 | F44: 0 | G44: 0 | H44: 0 | I44: 0 | J44: 0 | K44: 0 | L44: 0.94352854 | M44: 0.72305073 | N44: 0.71575219 | O44: 0.54305388 | P44: 0.60608829 | Q44: 0.5422705 | R44: 0.60608829 | S44: 0.38561048 | T44: 0 | U44: 0 | V44: 0.32019542 | W44: 0.53389481 | X44: 0.2136994 | Y44: 0.2136994 | Z44: 0.27776321 | AA44: 0.56647727 | AB44: 0.2135815 | AC44: 0.35260733 | AD44: 0.2644555
A45: 94.7 E. DEL SUR | B45: 0 | C45: 0 | D45: 0 | E45: 0 | F45: 0 | G45: 0 | H45: 0 | I45: 0 | J45: 0 | K45: 0.46948289 | L45: 0.30056056 | M45: 0.17775254 | N45: 0 | O45: 0 | P45: 0 | Q45: 0.16437714 | R45: 0 | S45: 0 | T45: 0.19864041 | U45: 0.17622087 | V45: 0 | W45: 0 | X45: 0 | Y45: 0 | Z45: 0.157966 | AA45: 0.02739619 | AB45: 0.062476881 | AC45: 0.082613023 | AD45: 0.061959767
A46: 95.5 DEL PLATA | B46: 0.18731862 | C46: 0.18731862 | D46: 0 | E46: 0 | F46: 0 | G46: 0 | H46: 0 | I46: 0 | J46: 0 | K46: 0.28303415 | L46: 0.62692572 | M46: 0.48578221 | N46: 0.90251297 | O46: 0.3781651 | P46: 0.47529497 | Q46: 0.26839848 | R46: 0.81328587 | S46: 0.80642356 | T46: 0.48482375 | U46: 0.27641353 | V46: 0.45686983 | W46: 0.46373215 | X46: 0.5951235 | Y46: 0.64697916 | Z46: 0.23262368 | AA46: 0.60734683 | AB46: 0.48732365 | AC46: 0.44243139 | AD46: 0.34743342
A47: 96.3 ALFA | B47: 0 | C47: 0 | D47: 0 | E47: 0 | F47: 0 | G47: 0 | H47: 0 | I47: 0 | J47: 0.37807241 | K47: 0.16808181 | L47: 0.61862884 | M47: 0.16808181 | N47: 0.38855962 | O47: 0.76292736 | P47: 0.37436774 | Q47: 0.2099906 | R47: 0.2099906 | S47: 0 | T47: 0 | U47: 0.31748605 | V47: 0.31748605 | W47: 0.31748605 | X47: 0.31748605 | Y47: 0 | Z47: 0.22214415 | AA47: 0.32430599 | AB47: 0.21165737 | AC47: 0.2527025 | AD47: 0.18952687
A48: 97.1 BABEL | B48: 0 | C48: 0 | D48: 0 | E48: 0 | F48: 0 | G48: 0.30087841 | H48: 0.30087841 | I48: 0.30087841 | J48: 0.15252124 | K48: 0.64430603 | L48: 0.73310464 | M48: 0.29239382 | N48: 0.23659958 | O48: 0.16808181 | P48: 0.22047781 | Q48: 0.36239942 | R48: 0.45707739 | S48: 0.22047781 | T48: 0.2711253 | U48: 0.41304691 | V48: 0.87763369 | W48: 0.92181385 | X48: 0.64898354 | Y48: 0.18610177 | Z48: 0.40401376 | AA48: 0.27751897 | AB48: 0.55311751 | AC48: 0.41155008 | AD48: 0.32119916
A49: 97.9 M24 | B49: 0 | C49: 0 | D49: 0 | E49: 0 | F49: 0 | G49: 0 | H49: 0 | I49: 0 | J49: 0.34602297 | K49: 0.36293637 | L49: 0.36293637 | M49: 0.36293637 | N49: 0.17952059 | O49: 0.34400641 | P49: 0.34400641 | Q49: 0.34400641 | R49: 0 | S49: 0 | T49: 0 | U49: 0 | V49: 0 | W49: 0 | X49: 0 | Y49: 0 | Z49: 0.23913868 | AA49: 0.2019233 | AB49: 0 | AC49: 0.14702066 | AD49: 0.1102655
... A65: RATING GENERAL | B65: 1.5286417 | C65: 1.455218 | D65: 1.0227851 | E65: 0.98785176 | F65: 0.91350636 | G65: 2.4640613 | H65: 8.6216409 | I65: 16.339381 | J65: 22.690989 | K65: 26.186955 | L65: 27.548129 | M65: 24.854663 | N65: 21.038685 | O65: 15.749124 | P65: 15.790792 | Q65: 14.654745 | R65: 17.179219 | S65: 16.190577 | T65: 15.789244 | U65: 12.158728 | V65: 10.272096 | W65: 9.2694235 | X65: 5.8232428 | Y65: 5.0512924 | Z65: 21.040293 | AA65: 16.76719 | AB65: 9.7273377 | AC65: 15.84494 | AD65: 12.232541

Sheet RatC2C3D1LV
A1: CUADRO 58: RESUMEN DE RATING POR HORA - SEGMENTO C2C3D1 | AM | LUNES A VIERNES
A3: RADIOS | B3: HORAS | Z3: PROMEDIO
B4: 00:00 - 00:59 | C4: 01:00 - 01:59 | D4: 02:00 - 02:59 | E4: 03:00 - 03:59 | F4: 04:00 - 04:59 | G4: 05:00 - 05:59 | H4: 06:00 - 06:59 | I4: 07:00 - 07:59 | J4: 08:00 - 08:59 | K4: 09:00 - 09:59 | L4: 10:00 - 10:59 | M4: 11:00 - 11:59 | N4: 12:00 - 12:59 | O4: 13:00 - 13:59 | P4: 14:00 - 14:59 | Q4: 15:00 - 15:59 | R4: 16:00 - 16:59 | S4: 17:00 - 17:59 | T4: 18:00 - 18:59 | U4: 19:00 - 19:59 | V4: 20:00 - 20:59 | W4: 21:00 - 21:59 | X4: 22:00 - 22:59 | Y4: 23:00 - 23:59 | Z4: 06:00 - 11:59 | AA4: 12:00 - 17:59 | AB4: 18:00 - 23:59 | AC4: 06:00 - 23:59 | AD4: 00:00 - 24:00
A5: CX4 RURAL | B5: 0.16262303 | C5: 0.13572788 | D5: 0.083087143 | E5: 0 | F5: 0 | G5: 0 | H5: 0.10141678 | I5: 0.11919221 | J5: 0.03651387 | K5: 0.03651387 | L5: 0.021518863 | M5: 0.062113318 | N5: 0.041930351 | O5: 0.12708875 | P5: 0.24683845 | Q5: 0.17639751 | R5: 0.20996205 | S5: 0.05093453 | T5: 0.037658353 | U5: 0.076487309 | V5: 0.034989007 | W5: 0.090318932 | X5: 0.070876779 | Y5: 0.174945 | Z5: 0.062878152 | AA5: 0.14219194 | AB5: 0.08087923 | AC5: 0.095316441 | AD5: 0.087380583
A6: CX6 CLÁSICA | B6: 0 | C6: 0 | D6: 0 | E6: 0 | F6: 0 | G6: 0 | H6: 0 | I6: 0.035683471 | J6: 0.11250037 | K6: 0.096912979 | L6: 0.020096081 | M6: 0 | N6: 0 | O6: 0.12206675 | P6: 0.12206675 | Q6: 0.045249852 | R6: 0 | S6: 0 | T6: 0 | U6: 0 | V6: 0.014559123 | W6: 0 | X6: 0 | Y6: 0 | Z6: 0.044198817 | AA6: 0.048230559 | AB6: 0.0024265204 | AC6: 0.031618632 | AD6: 0.023713974
A7: CX8 SARANDI | B7: 0.025409455 | C7: 0 | D7: 0 | E7: 0 | F7: 0 | G7: 0.14968859 | H7: 0.82276689 | I7: 1.3902873 | J7: 2.0224693 | K7: 1.9912057 | L7: 1.797263 | M7: 1.5625825 | N7: 0.97277036 | O7: 0.79503374 | P7: 0.61792828 | Q7: 0.44380815 | R7: 0.49759697 | S7: 0.37322537 | T7: 0.19454416 | U7: 0.10660258 | V7: 0.13911367 | W7: 0.073204757 | X7: 0.084387857 | Y7: 0.044685661 | Z7: 1.5977624 | AA7: 0.61672714 | AB7: 0.10708978 | AC7: 0.77385979 | AD7: 0.58769059
A8: CX10 CONTINENTE | B8: 0 | C8: 0 | D8: 0 | E8: 0 | F8: 0 | G8: 0 | H8: 0.020660823 | I8: 0.093562012 | J8: 0.18732264 | K8: 0.14529187 | L8: 0.16711709 | M8: 0.14744009 | N8: 0.16719229 | O8: 0.095325238 | P8: 0.20037238 | Q8: 0.049932156 | R8: 0.14046482 | S8: 0.020182967 | T8: 0.020182967 | U8: 0.055207688 | V8: 0.17683822 | W8: 0.19715251 | X8: 0.19789931 | Y8: 0.16830439 | Z8: 0.12689909 | AA8: 0.11224498 | AB8: 0.13593085 | AC8: 0.12502497 | AD8: 0.093768728
A9: CX12 ORIENTAL | B9: 0 | C9: 0 | D9: 0 | E9: 0 | F9: 0.016910441 | G9: 0.016910441 | H9: 0.14088369 | I9: 0.32489958 | J9: 0.49118708 | K9: 0.30907644 | L9: 0.3163598 | M9: 0.20704345 | N9: 0.23439294 | O9: 0.22720112 | P9: 0.2642863 | Q9: 0.18387739 | R9: 0.18387739 | S9: 0.21383822 | T9: 0.019045707 | U9: 0.18404933 | V9: 0.14725807 | W9: 0.21836571 | X9: 0.10362013 | Y9: 0.055790529 | Z9: 0.29824167 | AA9: 0.21791223 | AB9: 0.12135491 | AC9: 0.21250294 | AD9: 0.16078641
A10: CX14 EL ESPECTADOR | B10: 0.11174529 | C10: 0.018125165 | D10: 0.041498303 | E10: 0 | F10: 0 | G10: 0.13563024 | H10: 0.23959076 | I10: 0.24590433 | J10: 0.30617967 | K10: 0.34026469 | L10: 0.17470699 | M10: 0.38136874 | N10: 0.11872361 | O10: 0.36786162 | P10: 0.23832437 | Q10: 0.30640669 | R10: 0.23097581 | S10: 0.020572401 | T10: 0.019962718 | U10: 0.13699553 | V10: 0.022034466 | W10: 0.043328124 | X10: 0.043328124 | Y10: 0.040624374 | Z10: 0.28133586 | AA10: 0.21381075 | AB10: 0.051045555 | AC10: 0.18206406 | AD10: 0.14933967
A11: CX16 CARVE | B11: 0.08578702 | C11: 0.037764023 | D11: 0 | E11: 0 | F11: 0 | G11: 0.070824303 | H11: 0.15104237 | I11: 0.11828591 | J11: 0.10029669 | K11: 0.11472881 | L11: 0.11987502 | M11: 0.080880631 | N11: 0.17982058 | O11: 0.26080451 | P11: 0.37199956 | Q11: 0.32333312 | R11: 0.38253527 | S11: 0.26469068 | T11: 0.10478558 | U11: 0.1059003 | V11: 0.063634517 | W11: 0.044896075 | X11: 0.12741921 | Y11: 0.10851259 | Z11: 0.11418491 | AA11: 0.29719728 | AB11: 0.092524713 | AC11: 0.16796897 | AD11: 0.1340757
A12: CX18 SPORT 890 | B12: 0.096449499 | C12: 0.096449499 | D12: 0.045341947 | E12: 0.088921405 | F12: 0.082008343 | G12: 0.28344514 | H12: 0.35822306 | I12: 0.76298022 | J12: 0.98679567 | K12: 1.111847 | L12: 0.75475032 | M12: 0.91854506 | N12: 0.87433037 | O12: 0.65920226 | P12: 0.70924443 | Q12: 0.70187157 | R12: 0.69840994 | S12: 0.69961258 | T12: 0.37780881 | U12: 0.1878043 | V12: 0.1072617 | W12: 0.038840504 | X12: 0.051577548 | Y12: 0.069363573 | Z12: 0.81552355 | AA12: 0.72377852 | AB12: 0.13877607 | AC12: 0.55935938 | AD12: 0.44837853
A13: CX20 MONTECARLO | B13: 0.14859322 | C13: 0.31952439 | D13: 0.26544792 | E13: 0.20329674 | F13: 0.18459068 | G13: 0.77885775 | H13: 1.7538491 | I13: 3.2678557 | J13: 3.7232242 | K13: 4.1087784 | L13: 3.7093398 | M13: 4.1047822 | N13: 2.8801366 | O13: 1.7072195 | P13: 1.325863 | Q13: 0.96131204 | R13: 0.82692996 | S13: 0.7752372 | T13: 0.73798058 | U13: 0.68240223 | V13: 0.40898484 | W13: 0.32550699 | X13: 0.30606507 | Y13: 0.21384323 | Z13: 3.4446382 | AA13: 1.412783 | AB13: 0.44579716 | AC13: 1.7677395 | AD13: 1.4049842
A14: CX22 UNIVERSAL | B14: 0.094422539 | C14: 0.094422539 | D14: 0.076492769 | E14: 0.11274333 | F14: 0.096266897 | G14: 0.074382832 | H14: 0.075441088 | I14: 0.11762905 | J14: 0.11829214 | K14: 0.15810124 | L14: 0.18649787 | M14: 0.27263483 | N14: 0.31522426 | O14: 0.18160592 | P14: 0.057653077 | Q14: 0.055091931 | R14: 0.11857493 | S14: 0.12493839 | T14: 0.015587389 | U14: 0.12354852 | V14: 0.20086952 | W14: 0.18548366 | X14: 0.12546602 | Y14: 0.033680306 | Z14: 0.15476604 | AA14: 0.14218142 | AB14: 0.1141059 | AC14: 0.13701779 | AD14: 0.12562713
A15: CX24 RADIO 1010 AM | B15: 0.055448052 | C15: 0 | D15: 0 | E15: 0 | F15: 0 | G15: 0 | H15: 0.059832935 | I15: 0.13295717 | J15: 0.073124232 | K15: 0.11028995 | L15: 0.037165715 | M15: 0.1138293 | N15: 0.056365489 | O15: 0.078362171 | P15: 0.11801882 | Q15: 0.18187209 | R15: 0.25080958 | S15: 0.10882742 | T15: 0.10280621 | U15: 0.085476276 | V15: 0.015442382 | W15: 0 | X15: 0 | Y15: 0.018498078 | Z15: 0.08786655 | AA15: 0.13237593 | AB15: 0.037037158 | AC15: 0.085759878 | AD15: 0.066630244
A16: CX26 RADIO URUGUAY | B16: 0.040298251 | C16: 0.059519982 | D16: 0.078183448 | E16: 0.059519982 | F16: 0.081421453 | G16: 0.04244335 | H16: 0.061665081 | I16: 0 | J16: 0.11435397 | K16: 0.13153765 | L16: 0.25256481 | M16: 0.27485387 | N16: 0.24126861 | O16: 0.090263572 | P16: 0.12079782 | Q16: 0.083181682 | R16: 0.071974081 | S16: 0.037083605 | T16: 0.057524025 | U16: 0.03831191 | V16: 0.15264339 | W16: 0.15264339 | X16: 0.047024586 | Y16: 0.016817781 | Z16: 0.13916256 | AA16: 0.10742823 | AB16: 0.07749418 | AC16: 0.10802832 | AD16: 0.096079012
... A31: SUB TOTAL AM | B31: 1.0764197 | C31: 0.99577898 | D31: 0.79046813 | E31: 0.76954045 | F31: 0.90587219 | G31: 2.2183429 | H31: 4.723335 | I31: 7.900959 | J31: 9.9280419 | K31: 10.31994 | L31: 9.0636646 | M31: 9.6670822 | N31: 6.7220321 | O31: 5.3777984 | P31: 5.139759 | Q31: 4.3195367 | R31: 4.5485627 | S31: 3.4644459 | T31: 2.3895073 | U31: 2.4059297 | V31: 2.0778951 | W31: 1.8223303 | X31: 1.4771159 | Y31: 1.1827051 | Z31: 8.6005037 | AA31: 4.9286891 | AB31: 1.8925805 | AC31: 5.1405911 | AD31: 4.1369609
A32: RATING GENERAL
A34: CUADRO 59: RESUMEN DE RATING POR HORA - SEGMENTO C2C3D1 | FM | LUNES A VIERNES
A36: RADIOS | B36: HORAS | Z36: PROMEDIO
B37: 00:00 - 00:59 | C37: 01:00 - 01:59 | D37: 02:00 - 02:59 | E37: 03:00 - 03:59 | F37: 04:00 - 04:59 | G37: 05:00 - 05:59 | H37: 06:00 - 06:59 | I37: 07:00 - 07:59 | J37: 08:00 - 08:59 | K37: 09:00 - 09:59 | L37: 10:00 - 10:59 | M37: 11:00 - 11:59 | N37: 12:00 - 12:59 | O37: 13:00 - 13:59 | P37: 14:00 - 14:59 | Q37: 15:00 - 15:59 | R37: 16:00 - 16:59 | S37: 17:00 - 17:59 | T37: 18:00 - 18:59 | U37: 19:00 - 19:59 | V37: 20:00 - 20:59 | W37: 21:00 - 21:59 | X37: 22:00 - 22:59 | Y37: 23:00 - 23:59 | Z37: 06:00 - 11:59 | AA37: 12:00 - 17:59 | AB37: 18:00 - 23:59 | AC37: 06:00 - 23:59 | AD37: 00:00 - 24:00
A38: 88.3 LACOSTA | B38: 0 | C38: 0 | D38: 0 | E38: 0 | F38: 0 | G38: 0.09079179 | H38: 0.03137947 | I38: 0.018479333 | J38: 0.091003905 | K38: 0.092157737 | L38: 0.17245001 | M38: 0.037868738 | N38: 0.2702198 | O38: 0.44985806 | P38: 0.2918149 | Q38: 0.20131415 | R38: 0.2045542 | S38: 0.33122663 | T38: 0.13211042 | U38: 0.41171011 | V38: 0.32984269 | W38: 0.32984269 | X38: 0.32984269 | Y38: 0.09079179 | Z38: 0.073889865 | AA38: 0.29149796 | AB38: 0.27069007 | AC38: 0.21202596 | AD38: 0.16280246
A39: 90.3 OLDIES | B39: 0.084377289 | C39: 0.084377289 | D39: 0.11651465 | E39: 0.11651465 | F39: 0.032137366 | G39: 0.052951665 | H39: 0.19410452 | I39: 0.62426162 | J39: 0.92767499 | K39: 0.87213881 | L39: 0.94801733 | M39: 0.68451607 | N39: 0.60374812 | O39: 0.69577924 | P39: 0.7442721 | Q39: 0.5731172 | R39: 0.47553138 | S39: 0.38192639 | T39: 0.48864304 | U39: 0.17225161 | V39: 0.15313119 | W39: 0.18756582 | X39: 0.23708013 | Y39: 0.31148639 | Z39: 0.70845222 | AA39: 0.57906241 | AB39: 0.2583597 | AC39: 0.51529144 | AD39: 0.40675495
A40: 91.1 RADIOFUTURA | B40: 0.029672081 | C40: 0.029672081 | D40: 0.029672081 | E40: 0.029672081 | F40: 0.029672081 | G40: 0.017321346 | H40: 0.080825991 | I40: 0.17020867 | J40: 0.49076974 | K40: 0.9413161 | L40: 1.0787414 | M40: 1.336803 | N40: 1.1053862 | O40: 1.1233106 | P40: 0.79384009 | Q40: 0.83334836 | R40: 0.92228342 | S40: 0.93908244 | T40: 0.96987157 | U40: 0.79597122 | V40: 0.55188872 | W40: 0.3798782 | X40: 0.32488265 | Y40: 0.23835334 | Z40: 0.68311081 | AA40: 0.95287518 | AB40: 0.54347428 | AC40: 0.72648676 | AD40: 0.55176848
A41: 91.9 DISNEY | B41: 0.05721568 | C41: 0.079509419 | D41: 0.041225125 | E41: 0.021665498 | F41: 0.041628216 | G41: 0.27261696 | H41: 0.775217 | I41: 1.4760633 | J41: 1.8294966 | K41: 2.5263728 | L41: 2.5077431 | M41: 2.9795405 | N41: 2.6467103 | O41: 2.4851524 | P41: 2.3265949 | Q41: 2.2647664 | R41: 2.2679379 | S41: 2.0676259 | T41: 1.5011732 | U41: 1.2115949 | V41: 0.78115118 | W41: 0.40335637 | X41: 0.39952841 | Y41: 0.26601244 | Z41: 2.0157389 | AA41: 2.3431313 | AB41: 0.76046942 | AC41: 1.7064465 | AD41: 1.3012458
A42: 92.5 CONCIERTO URBANA | B42: 0 | C42: 0 | D42: 0 | E42: 0 | F42: 0 | G42: 0 | H42: 0 | I42: 0.019237255 | J42: 0 | K42: 0.12382429 | L42: 0.12382429 | M42: 0.12382429 | N42: 0.083795889 | O42: 0.083795889 | P42: 0.083795889 | Q42: 0.083795889 | R42: 0.083795889 | S42: 0.16964234 | T42: 0.17758966 | U42: 0.083795889 | V42: 0.050912282 | W42: 0.020096081 | X42: 0 | Y42: 0.018248881 | Z42: 0.065118354 | AA42: 0.09810363 | AB42: 0.058440466 | AC42: 0.073887483 | AD42: 0.055415613
A43: 93.1 INOLVIDABLE | B43: 0.037126666 | C43: 0.037126666 | D43: 0.058019828 | E43: 0.05725878 | F43: 0.037126666 | G43: 0.037126666 | H43: 0.26667845 | I43: 0.61522823 | J43: 1.1773112 | K43: 1.1327509 | L43: 1.4308717 | M43: 1.3734418 | N43: 1.6060323 | O43: 1.6470223 | P43: 1.7432382 | Q43: 1.0171591 | R43: 1.207005 | S43: 0.80491144 | T43: 0.96272923 | U43: 1.2961717 | V43: 1.0969376 | W43: 1.0295969 | X43: 0.41802682 | Y43: 0.040556197 | Z43: 0.99938036 | AA43: 1.3375614 | AB43: 0.8073364 | AC43: 1.0480927 | AD43: 0.79706059
A44: 93.9 OCEANO | B44: 0.016610646 | C44: 0.016610646 | D44: 0 | E44: 0 | F44: 0 | G44: 0.039883754 | H44: 0.15462447 | I44: 0.62146301 | J44: 0.83109247 | K44: 0.74777127 | L44: 0.76850289 | M44: 1.0544498 | N44: 1.5221371 | O44: 1.505045 | P44: 1.3065975 | Q44: 0.94271928 | R44: 0.85619638 | S44: 0.7436627 | T44: 0.34791161 | U44: 0.27464592 | V44: 0.15567406 | W44: 0.13268698 | X44: 0.016610646 | Y44: 0.016610646 | Z44: 0.69631732 | AA44: 1.1460597 | AB44: 0.15735664 | AC44: 0.66657787 | AD44: 0.50297945
A45: 94.7 E. DEL SUR | B45: 0 | C45: 0 | D45: 0.020893163 | E45: 0 | F45: 0 | G45: 0.020967516 | H45: 0.040696036 | I45: 0.080421804 | J45: 0.056168192 | K45: 0.12248823 | L45: 0.087287552 | M45: 0.22097858 | N45: 0.038897286 | O45: 0.073152856 | P45: 0.09701412 | Q45: 0.13226178 | R45: 0.04482878 | S45: 0.1307791 | T45: 0.069242876 | U45: 0.044034814 | V45: 0.048551474 | W45: 0.038024814 | X45: 0.04548034 | Y45: 0.0990102 | Z45: 0.10134007 | AA45: 0.086155653 | AB45: 0.057390753 | AC45: 0.081628824 | AD45: 0.062965813
A46: 95.5 DEL PLATA | B46: 0.097384751 | C46: 0.077220645 | D46: 0.077220645 | E46: 0.077220645 | F46: 0.023203285 | G46: 0 | H46: 0.021499873 | I46: 0.093887276 | J46: 0.40054218 | K46: 0.78511032 | L46: 0.63921984 | M46: 0.8334439 | N46: 0.8079828 | O46: 0.84240768 | P46: 0.80845921 | Q46: 0.90076913 | R46: 0.95359758 | S46: 1.1568834 | T46: 0.733986 | U46: 0.3375925 | V46: 0.38627773 | W46: 0.28899724 | X46: 0.26102028 | Y46: 0.26193409 | Z46: 0.4622839 | AA46: 0.9116833 | AB46: 0.37830131 | AC46: 0.5840895 | AD46: 0.45274421
A47: 96.3 ALFA | B47: 0 | C47: 0 | D47: 0 | E47: 0 | F47: 0 | G47: 0 | H47: 0 | I47: 0 | J47: 0.017920574 | K47: 0.093323542 | L47: 0.093323542 | M47: 0.093323542 | N47: 0.16215891 | O47: 0.26491513 | P47: 0.24553702 | Q47: 0.16932755 | R47: 0.12632465 | S47: 0.10560699 | T47: 0.057846462 | U47: 0.061698845 | V47: 0.084176144 | W47: 0.10079655 | X47: 0.026253816 | Y47: 0.018985049 | Z47: 0.049648533 | AA47: 0.17897838 | AB47: 0.058292812 | AC47: 0.095639907 | AD47: 0.07172993
A48: 97.1 BABEL | B48: 0 | C48: 0 | D48: 0 | E48: 0.020132115 | F48: 0.082157655 | G48: 0.082157655 | H48: 0.22610199 | I48: 0.27791374 | J48: 0.32013569 | K48: 0.35296259 | L48: 0.25649015 | M48: 0.29965194 | N48: 0.26024925 | O48: 0.30692628 | P48: 0.27190465 | Q48: 0.24212668 | R48: 0.22036945 | S48: 0.30539767 | T48: 0.30686995 | U48: 0.3789462 | V48: 0.27928573 | W48: 0.20842242 | X48: 0.12470495 | Y48: 0.06879283 | Z48: 0.28887602 | AA48: 0.267829 | AB48: 0.22783701 | AC48: 0.26151401 | AD48: 0.20382082
A49: 97.9 M24 | B49: 0.023153155 | C49: 0 | D49: 0 | E49: 0 | F49: 0.015098298 | G49: 0.27806527 | H49: 0.24653013 | I49: 0.25287629 | J49: 0.3339013 | K49: 0.29820799 | L49: 0.27992998 | M49: 0.26392431 | N49: 0.14263417 | O49: 0.093404042 | P49: 0.12519829 | Q49: 0.23845938 | R49: 0.23539024 | S49: 0.14392123 | T49: 0.12396359 | U49: 0.14626394 | V49: 0.075495604 | W49: 0.1891222 | X49: 0.119767 | Y49: 0.119767 | Z49: 0.27922833 | AA49: 0.16316789 | AB49: 0.12906322 | AC49: 0.19048648 | AD49: 0.15604473
... A65: RATING GENERAL | B65: 0 | C65: 1.8860725 | D65: 1.5766997 | E65: 1.5523756 | F65: 1.7484492 | G65: 4.4356658 | H65: 11.062256 | I65: 22.320962 | J65: 31.091004 | K65: 34.978714 | L65: 34.374748 | M65: 34.957603 | N65: 29.727443 | O65: 27.648962 | P65: 28.141108 | Q65: 26.23746 | R65: 25.965716 | S65: 23.858558 | T65: 19.827898 | U65: 14.49594 | V65: 10.682261 | W65: 9.2047268 | X65: 6.8556175 | Y65: 4.6592794 | Z65: 28.130881 | AA65: 26.929874 | AB65: 10.954287 | AC65: 22.005014 | AD65: 16.970397

Sheet RatC2C3D1SD
A1: CUADRO 60: RESUMEN DE RATING POR HORA - SEGMENTO C2C3D1 | AM | SABADO A DOMINGO
A3: RADIOS | B3: HORAS | Z3: PROMEDIO
B4: 00:00 - 00:59 | C4: 01:00 - 01:59 | D4: 02:00 - 02:59 | E4: 03:00 - 03:59 | F4: 04:00 - 04:59 | G4: 05:00 - 05:59 | H4: 06:00 - 06:59 | I4: 07:00 - 07:59 | J4: 08:00 - 08:59 | K4: 09:00 - 09:59 | L4: 10:00 - 10:59 | M4: 11:00 - 11:59 | N4: 12:00 - 12:59 | O4: 13:00 - 13:59 | P4: 14:00 - 14:59 | Q4: 15:00 - 15:59 | R4: 16:00 - 16:59 | S4: 17:00 - 17:59 | T4: 18:00 - 18:59 | U4: 19:00 - 19:59 | V4: 20:00 - 20:59 | W4: 21:00 - 21:59 | X4: 22:00 - 22:59 | Y4: 23:00 - 23:59 | Z4: 06:00 - 11:59 | AA4: 12:00 - 17:59 | AB4: 18:00 - 23:59 | AC4: 06:00 - 23:59 | AD4: 00:00 - 24:00
A5: CX4 RURAL | B5: 0.16530053 | C5: 0.16530053 | D5: 0.064995819 | E5: 0 | F5: 0 | G5: 0 | H5: 0.099097408 | I5: 0.14520167 | J5: 0.099097408 | K5: 0.088815801 | L5: 0.14607239 | M5: 0.14607239 | N5: 0 | O5: 0.045760943 | P5: 0.18019187 | Q5: 0.045194407 | R5: 0.13443093 | S5: 0.045194407 | T5: 0 | U5: 0.042790041 | V5: 0.042790041 | W5: 0.095467823 | X5: 0.042790041 | Y5: 0.16046364 | Z5: 0.12072618 | AA5: 0.07512876 | AB5: 0.064050265 | AC5: 0.086635067 | AD5: 0.081459503
A6: CX6 CLÁSICA | B6: 0 | C6: 0 | D6: 0 | E6: 0 | F6: 0 | G6: 0 | H6: 0 | I6: 0 | J6: 0.099761624 | K6: 0.14788041 | L6: 0.048118787 | M6: 0 | N6: 0 | O6: 0.099761624 | P6: 0.099761624 | Q6: 0 | R6: 0.048118787 | S6: 0 | T6: 0 | U6: 0.05333109 | V6: 0 | W6: 0 | X6: 0 | Y6: 0.05333109 | Z6: 0.04929347 | AA6: 0.041273672 | AB6: 0.01777703 | AC6: 0.036114724 | AD6: 0.027086043
A7: CX8 SARANDI | B7: 0.11193911 | C7: 0.10658907 | D7: 0.060828126 | E7: 0.060828126 | F7: 0.10658907 | G7: 0.14005211 | H7: 0.42582186 | I7: 0.83582077 | J7: 1.20009 | K7: 1.2360165 | L7: 0.83941586 | M7: 0.78576198 | N7: 0.41927232 | O7: 0.40543822 | P7: 0.19442495 | Q7: 0.14796872 | R7: 0.14796872 | S7: 0.15735734 | T7: 0.062674786 | U7: 0.040487556 | V7: 0.038736426 | W7: 0.051818187 | X7: 0 | Y7: 0 | Z7: 0.8871545 | AA7: 0.24540505 | AB7: 0.032286159 | AC7: 0.3882819 | AD7: 0.31566249
A8: CX10 CONTINENTE | B8: 0 | C8: 0 | D8: 0 | E8: 0 | F8: 0.066730263 | G8: 0.066730263 | H8: 0.046104258 | I8: 0.046104258 | J8: 0.086960727 | K8: 0.11110008 | L8: 0.046104258 | M8: 0.04085647 | N8: 0 | O8: 0 | P8: 0.077099197 | Q8: 0 | R8: 0.077099197 | S8: 0 | T8: 0.04085647 | U8: 0.046104258 | V8: 0.17864513 | W8: 0.18011241 | X8: 0.18011241 | Y8: 0.13778866 | Z8: 0.062871675 | AA8: 0.025699732 | AB8: 0.12726989 | AC8: 0.071947098 | AD8: 0.059521179
A9: CX12 ORIENTAL | B9: 0.065918337 | C9: 0 | D9: 0 | E9: 0 | F9: 0 | G9: 0.042642187 | H9: 0 | I9: 0.11465556 | J9: 0.21882375 | K9: 0.11465556 | L9: 0.16647374 | M9: 0.16700557 | N9: 0 | O9: 0.11963111 | P9: 0.27464577 | Q9: 0.20521577 | R9: 0.20521577 | S9: 0.24905972 | T9: 0.11732122 | U9: 0.18192913 | V9: 0.050649454 | W9: 0.13549872 | X9: 0 | Y9: 0.065918337 | Z9: 0.13026903 | AA9: 0.17562802 | AB9: 0.091886144 | AC9: 0.1325944 | AD9: 0.10396915
A10: CX14 EL ESPECTADOR | B10: 0.19933497 | C10: 0.10373219 | D10: 0.05333109 | E10: 0 | F10: 0 | G10: 0.051607814 | H10: 0.05323534 | I10: 0.17199602 | J10: 0.22052281 | K10: 0.25200436 | L10: 0.048526798 | M10: 0.14895291 | N10: 0.05323534 | O10: 0.28910006 | P10: 0.14014715 | Q10: 0.25806383 | R10: 0.11762974 | S10: 0.075305997 | T10: 0.075305997 | U10: 0.29597043 | V10: 0.24329264 | W10: 0.24329264 | X10: 0.22539805 | Y10: 0.1107425 | Z10: 0.14920637 | AA10: 0.15558035 | AB10: 0.19900038 | AC10: 0.16792903 | AD10: 0.14294703
A11: CX16 CARVE | B11: 0.054585036 | C11: 0.10048093 | D11: 0.15229912 | E11: 0.15229912 | F11: 0.10640322 | G11: 0.054585036 | H11: 0.054585036 | I11: 0.09693232 | J11: 0.33808759 | K11: 0.27015841 | L11: 0.15893136 | M11: 0.10782038 | N11: 0.054585036 | O11: 0 | P11: 0.1370931 | Q11: 0.14146008 | R11: 0.23378492 | S11: 0.089942919 | T11: 0 | U11: 0 | V11: 0 | W11: 0 | X11: 0 | Y11: 0 | Z11: 0.17108585 | AA11: 0.10947768 | AB11: 0 | AC11: 0.093521174 | AD11: 0.096001401
A12: CX18 SPORT 890 | B12: 0 | C12: 0 | D12: 0 | E12: 0.090432396 | F12: 0.042323747 | G12: 0.2712042 | H12: 0.17472683 | I12: 0.3679855 | J12: 0.40553298 | K12: 0.36390831 | L12: 0.31224426 | M12: 0.4290905 | N12: 0.43285738 | O12: 0.43747243 | P12: 0.4771277 | Q12: 0.55040591 | R12: 0.61721853 | S12: 0.62860166 | T12: 0.67164145 | U12: 0.44613498 | V12: 0.18971938 | W12: 0.10487011 | X12: 0.046030325 | Y12: 0 | Z12: 0.34224806 | AA12: 0.52394727 | AB12: 0.24306604 | AC12: 0.36975379 | AD12: 0.29414702
A13: CX20 MONTECARLO | B13: 0.13273702 | C13: 0.12025761 | D13: 0.077933864 | E13: 0.20102326 | F13: 0.077933864 | G13: 0.52349347 | H13: 1.6122049 | I13: 2.3381875 | J13: 2.6322055 | K13: 3.542968 | L13: 2.8877292 | M13: 3.2345342 | N13: 2.1003271 | O13: 1.3532649 | P13: 1.2342737 | Q13: 1.1455289 | R13: 1.1232461 | S13: 0.99643049 | T13: 0.53173854 | U13: 0.51501003 | V13: 0.17769549 | W13: 0.19785203 | X13: 0.23761463 | Y13: 0.14547287 | Z13: 2.7079715 | AA13: 1.3255119 | AB13: 0.30089727 | AC13: 1.4447936 | AD13: 1.1308193
A14: CX22 UNIVERSAL | B14: 0 | C14: 0 | D14: 0 | E14: 0 | F14: 0 | G14: 0 | H14: 0 | I14: 0.15149294 | J14: 0.15051417 | K14: 0.23548691 | L14: 0.18689234 | M14: 0.23777967 | N14: 0.26672234 | O14: 0.22621239 | P14: 0.11908088 | Q14: 0.23615335 | R14: 0.30195407 | S14: 0.20756355 | T14: 0.23958632 | U14: 0.10738045 | V14: 0.093122348 | W14: 0.20064683 | X14: 0.15223015 | Y14: 0.10318473 | Z14: 0.160361 | AA14: 0.2262811 | AB14: 0.14935847 | AC14: 0.17866686 | AD14: 0.13400014
A15: CX24 RADIO 1010 AM | B15: 0 | C15: 0 | D15: 0 | E15: 0 | F15: 0 | G15: 0 | H15: 0.05111098 | I15: 0 | J15: 0 | K15: 0 | L15: 0 | M15: 0.091185179 | N15: 0 | O15: 0 | P15: 0.091185179 | Q15: 0 | R15: 0.08932311 | S15: 0.08932311 | T15: 0 | U15: 0.05111098 | V15: 0.05111098 | W15: 0.05111098 | X15: 0.05111098 | Y15: 0 | Z15: 0.023716027 | AA15: 0.0449719 | AB15: 0.034073987 | AC15: 0.034253971 | AD15: 0.025690478
A16: CX26 RADIO URUGUAY | B16: 0.10434632 | C16: 0.10434632 | D16: 0.10434632 | E16: 0.15540185 | F16: 0.10429087 | G16: 0 | H16: 0 | I16: 0 | J16: 0.10600887 | K16: 0.26718581 | L16: 0.2631198 | M16: 0.31493798 | N16: 0.174117 | O16: 0.1721534 | P16: 0.12033521 | Q16: 0.051055529 | R16: 0.11697158 | S16: 0.051055529 | T16: 0.098613136 | U16: 0.16452919 | V16: 0.098613136 | W16: 0.047557607 | X16: 0.047557607 | Y16: 0.047557607 | Z16: 0.15854208 | AA16: 0.11428137 | AB16: 0.084071381 | AC16: 0.11896494 | AD16: 0.11308753
... A32: RATING GENERAL | B32: 0 | C32: 1.9561681 | D32: 1.8302899 | E32: 1.6105536 | F32: 1.8920187 | G32: 3.26255 | H32: 7.8731204 | I32: 16.033474 | J32: 22.141284 | K32: 27.513411 | L32: 27.187974 | M32: 27.034864 | N32: 22.520508 | O32: 20.482446 | P32: 20.164773 | Q32: 18.798846 | R32: 18.637588 | S32: 16.469778 | T32: 13.571463 | U32: 10.998541 | V32: 7.7855106 | W32: 7.1711093 | X32: 6.023187 | Y32: 4.1345475 | Z32: 21.297354 | AA32: 19.512323 | AB32: 8.2807265 | AC32: 16.363468 | AD32: 12.71225
A34: CUADRO 61: RESUMEN DE RATING POR HORA - SEGMENTO C2C3D1 | FM | SABADO A DOMINGO
A36: RADIOS | B36: HORAS | Z36: PROMEDIO
B37: 00:00 - 00:59 | C37: 01:00 - 01:59 | D37: 02:00 - 02:59 | E37: 03:00 - 03:59 | F37: 04:00 - 04:59 | G37: 05:00 - 05:59 | H37: 06:00 - 06:59 | I37: 07:00 - 07:59 | J37: 08:00 - 08:59 | K37: 09:00 - 09:59 | L37: 10:00 - 10:59 | M37: 11:00 - 11:59 | N37: 12:00 - 12:59 | O37: 13:00 - 13:59 | P37: 14:00 - 14:59 | Q37: 15:00 - 15:59 | R37: 16:00 - 16:59 | S37: 17:00 - 17:59 | T37: 18:00 - 18:59 | U37: 19:00 - 19:59 | V37: 20:00 - 20:59 | W37: 21:00 - 21:59 | X37: 22:00 - 22:59 | Y37: 23:00 - 23:59 | Z37: 06:00 - 11:59 | AA37: 12:00 - 17:59 | AB37: 18:00 - 23:59 | AC37: 06:00 - 23:59 | AD37: 00:00 - 24:00
A38: 88.3 LACOSTA | B38: 0.041959049 | C38: 0 | D38: 0 | E38: 0 | F38: 0 | G38: 0 | H38: 0.10590788 | I38: 0.12767172 | J38: 0.19065504 | K38: 0.10568194 | L38: 0.063722888 | M38: 0.063722888 | N38: 0.081892689 | O38: 0.085577581 | P38: 0.13170299 | Q38: 0.20582394 | R38: 0.20165758 | S38: 0.22268185 | T38: 0.045643942 | U38: 0.091769349 | V38: 0 | W38: 0.046125408 | X38: 0 | Y38: 0 | Z38: 0.10956039 | AA38: 0.15488944 | AB38: 0.030589783 | AC38: 0.098346538 | AD38: 0.075508197
A39: 90.3 OLDIES | B39: 0.1725652 | C39: 0.1725652 | D39: 0.12491299 | E39: 0.12491299 | F39: 0 | G39: 0 | H39: 0.04085647 | I39: 0.091057585 | J39: 0.41964239 | K39: 0.50909643 | L39: 0.45452067 | M39: 0.39986702 | N39: 0.44114192 | O39: 0.44514902 | P39: 0.48776751 | Q39: 0.45301624 | R39: 0.40124336 | S39: 0.31692407 | T39: 0.3596213 | U39: 0.18323053 | V39: 0.17934408 | W39: 0.21434661 | X39: 0.26020879 | Y39: 0.29602546 | Z39: 0.31917343 | AA39: 0.42420702 | AB39: 0.24879613 | AC39: 0.33072553 | AD39: 0.27283399
A40: 91.1 RADIOFUTURA | B40: 0.072262636 | C40: 0.072262636 | D40: 0 | E40: 0.04670214 | F40: 0.04670214 | G40: 0.094321312 | H40: 0 | I40: 0.053987749 | J40: 0.29659986 | K40: 0.66649926 | L40: 0.87575679 | M40: 0.79587056 | N40: 0.57582855 | O40: 0.61219607 | P40: 0.69137324 | Q40: 0.77457989 | R40: 0.78439119 | S40: 0.55731896 | T40: 0.57246485 | U40: 0.49725731 | V40: 0.44442865 | W40: 0.34526355 | X40: 0.37782481 | Y40: 0.12011097 | Z40: 0.44811904 | AA40: 0.66594798 | AB40: 0.39289169 | AC40: 0.50231957 | AD40: 0.39058346
A41: 91.9 DISNEY | B41: 0.1354957 | C41: 0 | D41: 0 | E41: 0 | F41: 0.070126693 | G41: 0.293676 | H41: 0.44404907 | I41: 0.87174883 | J41: 1.5784305 | K41: 2.1800658 | L41: 2.3002702 | M41: 2.2635804 | N41: 1.8740495 | O41: 1.6989554 | P41: 1.2917935 | Q41: 1.2575446 | R41: 0.99906679 | S41: 0.91641584 | T41: 0.39473473 | U41: 0.40344555 | V41: 0.45666668 | W41: 0.38117858 | X41: 0.27795138 | Y41: 0.23094867 | Z41: 1.6063575 | AA41: 1.3396376 | AB41: 0.3574876 | AC41: 1.1011609 | AD41: 0.84667477
A42: 92.5 CONCIERTO URBANA | B42: 0 | C42: 0 | D42: 0.050120202 | E42: 0 | F42: 0 | G42: 0 | H42: 0 | I42: 0.071595937 | J42: 0.071595937 | K42: 0.052333499 | L42: 0.052333499 | M42: 0.052333499 | N42: 0.052333499 | O42: 0.052333499 | P42: 0.052333499 | Q42: 0.17565004 | R42: 0.22577024 | S42: 0.17565004 | T42: 0.17711928 | U42: 0.12392944 | V42: 0 | W42: 0 | X42: 0 | Y42: 0 | Z42: 0.050032062 | AA42: 0.12234514 | AB42: 0.050174787 | AC42: 0.074183995 | AD42: 0.057726338
A43: 93.1 INOLVIDABLE | B43: 0 | C43: 0 | D43: 0 | E43: 0 | F43: 0 | G43: 0 | H43: 0.29862942 | I43: 0.39839104 | J43: 0.58481312 | K43: 1.0617 | L43: 1.10652 | M43: 1.1262495 | N43: 1.2700622 | O43: 1.1875323 | P43: 1.0130763 | Q43: 0.81528836 | R43: 1.0237313 | S43: 0.83092827 | T43: 0.78513107 | U43: 1.1068547 | V43: 0.97478864 | W43: 0.7602723 | X43: 0.50901959 | Y43: 0.11928258 | Z43: 0.76271718 | AA43: 1.0234365 | AB43: 0.70922482 | AC43: 0.83179282 | AD43: 0.62384461
A44: 93.9 OCEANO | B44: 0 | C44: 0 | D44: 0.049009479 | E44: 0 | F44: 0 | G44: 0 | H44: 0.10364282 | I44: 0.54613653 | J44: 0.35449677 | K44: 0.6650297 | L44: 0.76729985 | M44: 0.78781722 | N44: 0.82400326 | O44: 0.72351883 | P44: 0.58774455 | Q44: 0.65512029 | R44: 0.57973282 | S44: 0.52247075 | T44: 0.42207512 | U44: 0.18736309 | V44: 0.065916055 | W44: 0 | X44: 0 | Y44: 0 | Z44: 0.53740381 | AA44: 0.64876508 | AB44: 0.11255904 | AC44: 0.43290931 | AD44: 0.32672405
A45: 94.7 E. DEL SUR | B45: 0.05883979 | C45: 0.05883979 | D45: 0.10895999 | E45: 0 | F45: 0 | G45: 0 | H45: 0 | I45: 0 | J45: 0.10734823 | K45: 0.15676149 | L45: 0.23383093 | M45: 0.15676149 | N45: 0.16036241 | O45: 0.16036241 | P45: 0.0916844 | Q45: 0.16875384 | R45: 0.21397874 | S45: 0.16385854 | T45: 0.072174138 | U45: 0.12662058 | V45: 0.12662058 | W45: 0.15941164 | X45: 0.11328623 | Y45: 0.11328623 | Z45: 0.10911702 | AA45: 0.15983339 | AB45: 0.11856656 | AC45: 0.12917233 | AD45: 0.10632256
A46: 95.5 DEL PLATA | B46: 0.12491299 | C46: 0.12491299 | D46: 0.17392247 | E46: 0.12491299 | F46: 0 | G46: 0 | H46: 0.10546264 | I46: 0.26105946 | J46: 0.35817236 | K46: 0.58300164 | L46: 0.68846742 | M46: 0.82794434 | N46: 0.83251349 | O46: 0.97774913 | P46: 0.63687513 | Q46: 0.51696289 | R46: 0.46633781 | S46: 0.46574672 | T46: 0.44435723 | U46: 0.2364268 | V46: 0.17748991 | W46: 0.044804973 | X46: 0.085928075 | Y46: 0.20988663 | Z46: 0.47068464 | AA46: 0.6493642 | AB46: 0.1998156 | AC46: 0.43995481 | AD46: 0.352827
A47: 96.3 ALFA | B47: 0 | C47: 0 | D47: 0 | E47: 0 | F47: 0 | G47: 0 | H47: 0 | I47: 0 | J47: 0 | K47: 0 | L47: 0.048145546 | M47: 0.048145546 | N47: 0.17080547 | O47: 0.17080547 | P47: 0.10074142 | Q47: 0.14861743 | R47: 0.14861743 | S47: 0.14861743 | T47: 0.14861743 | U47: 0.04787601 | V47: 0.04787601 | W47: 0.04787601 | X47: 0.048145546 | Y47: 0.048145546 | Z47: 0.016048515 | AA47: 0.14803411 | AB47: 0.064756092 | AC47: 0.076279572 | AD47: 0.057209679
A48: 97.1 BABEL | B48: 0 | C48: 0 | D48: 0 | E48: 0 | F48: 0.11562928 | G48: 0.11562928 | H48: 0.11562928 | I48: 0.10718847 | J48: 0.12626734 | K48: 0.2304562 | L48: 0.49901263 | M48: 0.49401302 | N48: 0.26502432 | O48: 0.20127194 | P48: 0.20127194 | Q48: 0.32101931 | R48: 0.33214943 | S48: 0.48537778 | T48: 0.54295591 | U48: 0.65014438 | V48: 0.27216541 | W48: 0.17275661 | X48: 0.1098083 | Y48: 0.046055922 | Z48: 0.26209449 | AA48: 0.30101912 | AB48: 0.29898109 | AC48: 0.2873649 | AD48: 0.22515945
A49: 97.9 M24 | B49: 0 | C49: 0 | D49: 0 | E49: 0 | F49: 0.04114245 | G49: 0.086903393 | H49: 0.25053919 | I49: 0.43516884 | J49: 0.49122633 | K49: 0.52912111 | L49: 0.36532779 | M49: 0.38103722 | N49: 0.24706829 | O49: 0.20548668 | P49: 0.14750786 | Q49: 0.14750786 | R49: 0.25397014 | S49: 0.14863438 | T49: 0.22089702 | U49: 0.22089702 | V49: 0.072262636 | W49: 0.044705667 | X49: 0 | Y49: 0 | Z49: 0.40873675 | AA49: 0.19169587 | AB49: 0.093127057 | AC49: 0.23118656 | AD49: 0.17872516
... A65: RATING GENERAL | B65: 0 | C65: 1.9561681 | D65: 1.8302899 | E65: 1.6105536 | F65: 1.8920187 | G65: 3.26255 | H65: 7.8731204 | I65: 16.033474 | J65: 22.141284 | K65: 27.513411 | L65: 27.187974 | M65: 27.034864 | N65: 22.520508 | O65: 20.482446 | P65: 20.164773 | Q65: 18.798846 | R65: 18.637588 | S65: 16.469778 | T65: 13.571463 | U65: 10.998541 | V65: 7.7855106 | W65: 7.1711093 | X65: 6.023187 | Y65: 4.1345475 | Z65: 21.297354 | AA65: 19.512323 | AB65: 8.2807265 | AC65: 16.363468 | AD65: 12.71225

Sheet RatD2ELV
A1: CUADRO 62: RESUMEN DE RATING POR HORA - SEGMENTO D2E | AM | LUNES A VIERNES
A3: RADIOS | B3: HORAS | Z3: PROMEDIO
B4: 00:00 - 00:59 | C4: 01:00 - 01:59 | D4: 02:00 - 02:59 | E4: 03:00 - 03:59 | F4: 04:00 - 04:59 | G4: 05:00 - 05:59 | H4: 06:00 - 06:59 | I4: 07:00 - 07:59 | J4: 08:00 - 08:59 | K4: 09:00 - 09:59 | L4: 10:00 - 10:59 | M4: 11:00 - 11:59 | N4: 12:00 - 12:59 | O4: 13:00 - 13:59 | P4: 14:00 - 14:59 | Q4: 15:00 - 15:59 | R4: 16:00 - 16:59 | S4: 17:00 - 17:59 | T4: 18:00 - 18:59 | U4: 19:00 - 19:59 | V4: 20:00 - 20:59 | W4: 21:00 - 21:59 | X4: 22:00 - 22:59 | Y4: 23:00 - 23:59 | Z4: 06:00 - 11:59 | AA4: 12:00 - 17:59 | AB4: 18:00 - 23:59 | AC4: 06:00 - 23:59 | AD4: 00:00 - 24:00
A5: CX4 RURAL | B5: 0.066426534 | C5: 0 | D5: 0 | E5: 0 | F5: 0 | G5: 0 | H5: 0 | I5: 0.23261523 | J5: 0.23261523 | K5: 0 | L5: 0 | M5: 0 | N5: 0.042377524 | O5: 0.0767383 | P5: 0.2043978 | Q5: 0.31410321 | R5: 0.30608647 | S5: 0.12290982 | T5: 0.12290982 | U5: 0 | V5: 0 | W5: 0.03719245 | X5: 0.03719245 | Y5: 0.073865782 | Z5: 0.07753841 | AA5: 0.17776885 | AB5: 0.045193416 | AC5: 0.10016689 | AD5: 0.077892942
A6: CX6 CLÁSICA | B6: 0 | C6: 0 | D6: 0 | E6: 0 | F6: 0 | G6: 0 | H6: 0 | I6: 0 | J6: 0 | K6: 0 | L6: 0 | M6: 0 | N6: 0 | O6: 0 | P6: 0 | Q6: 0 | R6: 0 | S6: 0 | T6: 0 | U6: 0 | V6: 0 | W6: 0 | X6: 0 | Y6: 0 | Z6: 0 | AA6: 0 | AB6: 0 | AC6: 0 | AD6: 0
A7: CX8 SARANDI | B7: 0.047474872 | C7: 0 | D7: 0 | E7: 0 | F7: 0 | G7: 0.12057435 | H7: 0.18901101 | I7: 0.3419952 | J7: 0.13463449 | K7: 0.17948424 | L7: 0.26156176 | M7: 0.30005859 | N7: 0.046729797 | O7: 0.051754557 | P7: 0.051754557 | Q7: 0.051754557 | R7: 0.051754557 | S7: 0.051754557 | T7: 0.051754557 | U7: 0.051754557 | V7: 0.051754557 | W7: 0.099229429 | X7: 0 | Y7: 0 | Z7: 0.23445755 | AA7: 0.050917097 | AB7: 0.042415517 | AC7: 0.10926339 | AD7: 0.088949591
