Workbook

Sheet IndiceC
A1: INDICE DE CUADROS
A3: =+EstMuestra!A1 -> CUADRO 1: CARACTERIZACION DE LA POBLACION Y LA MUESTRA
A4: =+Error!A1 -> CUADRO 2: NIVELES DE ERROR DE LAS ESTIMACIONES
A5: =+RatxHoraxLD!A1 -> CUADRO 3: RESUMEN DE RATING POR HORA | AM | LUNES A DOMINGO
A6: =+RatxHoraxLD!A35 -> CUADRO 4: RESUMEN DE RATING POR HORA | FM | LUNES A DOMINGO
A7: =+RatxHoraxLV!A1 -> CUADRO 5: RESUMEN DE RATING POR HORA | AM | LUNES A VIERNES
A8: =+RatxHoraxLV!A35 -> CUADRO 6: RESUMEN DE RATING POR HORA | FM | LUNES A VIERNES
A9: =+RatxHoraxSD!A1 -> CUADRO 7: RESUMEN DE RATING POR HORA | AM | SABADO A DOMINGO
A10: =+RatxHoraxSD!A34 -> CUADRO 8: RESUMEN DE RATING POR HORA | FM | SABADO A DOMINGO
A11: =+RatxLDxABC1!A1 -> CUADRO 9: RESUMEN DE RATING POR HORA - SEGMENTO ABC1 | AM | LUNES A DOMINGO
A12: =+RatxLDxABC1!A34 -> CUADRO 10: RESUMEN DE RATING POR HORA - SEGMENTO ABC1 | FM | LUNES A DOMINGO
A13: =+RatxLVxABC1!A1 -> CUADRO 11: RESUMEN DE RATING POR HORA - SEGMENTO ABC1 | AM | LUNES A VIERNES
A14: =+RatxLVxABC1!A33 -> CUADRO 12: RESUMEN DE RATING POR HORA - SEGMENTO ABC1 | FM | LUNES A VIERNES
A15: =+RatxSDxABC1!A1 -> CUADRO 13: RESUMEN DE RATING POR HORA - SEGMENTO ABC1 | AM | SABADO A DOMINGO
A16: =+RatxSDxABC1!A33 -> CUADRO 14: RESUMEN DE RATING POR HORA - SEGMENTO ABC1 | FM | SABADO A DOMINGO
A17: =+RatxLDxC2C3D1!A1 -> CUADRO 15: RESUMEN DE RATING POR HORA - SEGMENTO C2C3D1 | AM | LUNES A DOMINGO
A18: =+RatxLDxC2C3D1!A33 -> CUADRO 16: RESUMEN DE RATING POR HORA - SEGMENTO C2C3D1 | FM | LUNES A DOMINGO
A19: =+RatxLVxC2C3D1!A1 -> CUADRO 17: RESUMEN DE RATING POR HORA - SEGMENTO C2C3D1 | AM | LUNES A VIERNES
A20: =+RatxLVxC2C3D1!A33 -> CUADRO 18: RESUMEN DE RATING POR HORA - SEGMENTO C2C3D1 | FM | LUNES A VIERNES
A21: =+RatxSDxC2C3D1!A1 -> CUADRO 19: RESUMEN DE RATING POR HORA - SEGMENTO C2C3D1 | AM | SABADO A DOMINGO
A22: =+RatxSDxC2C3D1!A33 -> CUADRO 20: RESUMEN DE RATING POR HORA - SEGMENTO C2C3D1 | FM | SABADO A DOMINGO
A23: =+RatxLDxD2E!A1 -> CUADRO 21: RESUMEN DE RATING POR HORA - SEGMENTO D2E | AM | LUNES A DOMINGO
A24: =+RatxLDxD2E!A33 -> CUADRO 22: RESUMEN DE RATING POR HORA - SEGMENTO D2E | FM | LUNES A DOMINGO
A25: =+RatxLVxD2E!A1 -> CUADRO 23: RESUMEN DE RATING POR HORA - SEGMENTO D2E | AM | LUNES A VIERNES
A26: =+RatxLVxD2E!A33 -> CUADRO 24: RESUMEN DE RATING POR HORA - SEGMENTO D2E | FM | LUNES A VIERNES
A27: =+RatxSDxD2E!A1 -> CUADRO 25: RESUMEN DE RATING POR HORA - SEGMENTO D2E | AM | SABADO A DOMINGO
A28: =+RatxSDxD2E!A33 -> CUADRO 26: RESUMEN DE RATING POR HORA - SEGMENTO D2E | FM | SABADO A DOMINGO
A29: =+RatxNSE!A1 -> CUADROS 27 - 32: RESUMEN DE RATING POR NIVEL SOCIOECONÓMICO | AM - FM
A30: =+RatxEdad!A1 -> CUADROS 33 - 38: RESUMEN DE RATING POR EDAD | AM - FM
A31: =+RatxSexo!A1 -> CUADROS 39 - 40: RESUMEN DE RATING POR SEXO | AM - FM
A32: =+RatxLugar!A1 -> CUADRO 41: RESUMEN DE RATING POR LUGAR DE ESCUCHA
A33: =+Cobertura!A1 -> CUADRO 42: COBERTURA SEMANAL POR NIVEL SOCIOECONÓMICO, EDAD Y SEXO | AM | LUNES A DOMINGO
A34: =+Cobertura!A33 -> CUADRO 43: COBERTURA SEMANAL POR NIVEL SOCIOECONÓMICO, EDAD Y SEXO | FM | LUNES A DOMINGO
A35: =+ShaxHoraxLD!A1 -> CUADRO 44: RESUMEN DE SHARE POR HORA | AM | LUNES A DOMINGO
A36: =+ShaxHoraxLD!A33 -> CUADRO 45: RESUMEN DE SHARE POR HORA | FM | LUNES A DOMINGO
A37: =+SharexHoraxLV!A1 -> CUADRO 46: RESUMEN DE SHARE POR HORA | AM | LUNES A VIERNES
A38: =+SharexHoraxLV!A32 -> CUADRO 47: RESUMEN DE SHARE POR HORA | FM | LUNES A VIERNES
A39: =+SharexHoraxSD!A1 -> CUADRO 48: RESUMEN DE SHARE POR HORA | AM | SABADO A DOMINGO
A40: =+SharexHoraxSD!A32 -> CUADRO 49: RESUMEN DE SHARE POR HORA | FM | SABADO A DOMINGO
A41: =+AudienciaxLD!A1 -> CUADRO 50: RESUMEN DE AUDIENCIA POR HORA | AM | LUNES A DOMINGO
...

Sheet InidiceG
A1: INDICE DE GRAFICOS
A3: =+GraxRAM!A1 -> PANEL 1: RESUMEN DE RATING Y COBERTURA | AM
A4: =+GraxRAMxNSE!A1 -> PANEL 2: RESUMEN DE RATING POR NSE | AM | LUNES A DOMINGO | 00:00 - 24:00
A5: =+GraxRFM!A1 -> PANEL 3: RESUMEN DE RATING Y COBERTURA | FM
A6: =+GraxRFMxNSE!A1 -> PANEL 4: RESUMEN DE RATING POR NSE | FM | LUNES A DOMINGO | 00:00 - 24:00
A7: =+EncxLug!A1 -> PANEL 5: RESUMEN DE ENCENDIDO POR LUGAR DE ESCUCHA
A8: =+CrvEncAMxLD!A1 -> PANEL 6: CURVAS DE ENCENDIDO | AM | LUNES A DOMINGO
A9: =+CrvEncAMxLV!A1 -> PANEL 7:CURVAS DE ENCENDIDO | AM | LUNES A VIERNES
A10: =+CrvEncAMxSD!A1 -> PANEL 8: CURVAS DE ENCENDIDO | AM | SABADO A DOMINGO
A11: =+CrvEncFMxLD!A1 -> PANEL 9: CURVAS DE ENCENDIDO | FM | LUNES A DOMINGO
A12: =+CrvEncFMxLV!A1 -> PANEL 10: CURVAS DE ENCENDIDO | FM | LUNES A VIERNES
A13: =+CrvEncFMxSD!A1 -> PANEL 11: CURVAS DE ENCENDIDO | FM | SABADO A DOMINGO

Sheet EstMuestra
A1: CUADRO 1: CARACTERIZACION DE LA POBLACION Y LA MUESTRA
A2: DIMENSION | B2: POBLACION | D2: MUESTRA
B3: TOTAL | C3: % | D3: TOTAL | E3: % | F3: PANEL | G3: % | H3: ROTATIVA | I3: %
A4: ZONA | B4: 1311422 | C4: 100.04377 | D4: 2000 | E4: 100 | F4: 1127 | G4: 100 | H4: 873 | I4: 77.462289
A5: Montevideo | B5: 1099709 | C5: 83.9 | D5: 1670 | E5: 83.5 | F5: 908 | G5: 80.567879 | H5: 762 | I5: 67.613132
A6: Estrato 1 | B6: 189149.95 | C6: 17.2 | D6: 336 | E6: 16.8 | F6: 214 | G6: 18.988465 | H6: 122 | I6: 10.8252
A7: Estrato 2 | B7: 199047.33 | C7: 18.1 | D7: 358 | E7: 17.9 | F7: 204 | G7: 18.101154 | H7: 154 | I7: 13.664596
A8: Estrato 3 | B8: 236437.43 | C8: 21.5 | D8: 418 | E8: 20.9 | F8: 200 | G8: 17.746229 | H8: 218 | I8: 19.34339
A9: Estrato 4 | B9: 197947.62 | C9: 18 | D9: 380 | E9: 19 | F9: 197 | G9: 17.480035 | H9: 183 | I9: 16.237799
A10: Estrato 5 | B10: 100073.52 | C10: 9.1 | D10: 178 | E10: 8.9 | F10: 93 | G10: 8.2519965 | H10: 85 | I10: 7.5421473
A11: A. Metropolitana | B11: 211713 | C11: 16.143774 | D11: 330 | E11: 16.5 | F11: 219 | G11: 19.432121 | H11: 111 | I11: 9.8491571
A12: SEXO | B12: 1311422 | C12: 100 | D12: 2000 | E12: 100 | F12: 1127 | G12: 100 | H12: 873 | I12: 100
A13: Masculino | B13: 602164 | C13: 45.916875 | D13: 969 | E13: 48.45 | F13: 531 | G13: 47.116238 | H13: 438 | I13: 50.171821
A14: Femenino | B14: 709258 | C14: 54.083125 | D14: 1031 | E14: 51.55 | F14: 596 | G14: 52.883762 | H14: 435 | I14: 49.828179
A15: EDAD | B15: 1311422 | C15: 100 | D15: 2000 | E15: 100 | F15: 1127 | G15: 100 | H15: 873 | I15: 100
... A29: B- | B29: 70126.98 | C29: 5.3474 | D29: 133 | E29: 6.65 | F29: 91 | G29: 8.0745342 | H29: 42 | I29: 4.8109966

Sheet Error
A1: CUADRO 2: NIVELES DE ERROR DE LAS ESTIMACIONES
A2: 95 % DE CONFIANZA
A3: DISEÑO | B3: MUESTRA | F3: RATING DIARIO
B4: TOTAL | C4: DIARIA | D4: ROTATIVA | E4: PANEL
F5: 0.005 | G5: 0.01 | H5: 0.02 | I5: 0.03 | J5: 0.05 | K5: 0.1 | L5: 0.15 | M5: 0.2
A6: MEDICION 2017 | B6: 2503 | C6: 1419.5714 | D6: 180.57143 | E6: 1239 | F6: 0.0035019806 | G6: 0.0049400892 | H6: 0.006950967 | I6: 0.0084696153 | J6: 0.010820915 | K6: 0.014894929 | L6: 0.017728512 | M6: 0.019859906
A7: MEDICION 2018 | B7: 2000 | C7: 1251.7143 | D7: 124.71429 | E7: 1127 | F7: 0.0037649807 | G7: 0.0053110917 | H7: 0.0074729873 | I7: 0.0091056866 | J7: 0.01163357 | K7: 0.016013544 | L7: 0.01905993 | M7: 0.021351392
A8: Notas: Muestra Total = Total de entrevistas realizadas. Muestra diaria = suma de los casos de panel + la muestra rotativa dividida en 7 dias. Muestra rotativa = muestra que no es de panel (hay una observacion de consumo por dia para cada persona). Panel = casos con observaciones en 7 dias.

Sheet RatxHoraxLD
A1: CUADRO 3: RESUMEN DE RATING POR HORA | AM | LUNES A DOMINGO
A2: RADIOS | B2: HORAS | Z2: PROMEDIO
B3: 00:00 - 00:59 | C3: 01:00 - 01:59 | D3: 02:00 - 02:59 | E3: 03:00 - 03:59 | F3: 04:00 - 04:59 | G3: 05:00 - 05:59 | H3: 06:00 - 06:59 | I3: 07:00 - 07:59 | J3: 08:00 - 08:59 | K3: 09:00 - 09:59 | L3: 10:00 - 10:59 | M3: 11:00 - 11:59 | N3: 12:00 - 12:59 | O3: 13:00 - 13:59 | P3: 14:00 - 14:59 | Q3: 15:00 - 15:59 | R3: 16:00 - 16:59 | S3: 17:00 - 17:59 | T3: 18:00 - 18:59 | U3: 19:00 - 19:59 | V3: 20:00 - 20:59 | W3: 21:00 - 21:59 | X3: 22:00 - 22:59 | Y3: 23:00 - 23:59 | Z3: 06:00 - 11:59 | AA3: 12:00 - 17:59 | AB3: 18:00 - 23:59 | AC3: 06:00 - 23:59 | AD3: 00:00 - 24:00
A4: CX4 RURAL | B4: 0.052129368 | C4: 0.043268311 | D4: 0.043268311 | E4: 0.025444247 | F4: 0 | G4: 0.024482125 | H4: 0.098622759 | I4: 0.089916305 | J4: 0.1435776 | K4: 0.17790465 | L4: 0.13379877 | M4: 0.13646189 | N4: 0.10360812 | O4: 0.059021866 | P4: 0.18692415 | Q4: 0.13495226 | R4: 0.11467711 | S4: 0.023433679 | T4: 0 | U4: 0.039315299 | V4: 0.057991965 | W4: 0.050205727 | X4: 0.0053705973 | Y4: 0.016063848 | Z4: 0.130047 | AA4: 0.10376953 | AB4: 0.028157906 | AC4: 0.087324811 | AD4: 0.073351623
A5: CX6 CLÁSICA | B5: 0 | C5: 0 | D5: 0 | E5: 0 | F5: 0 | G5: 0.014630941 | H5: 0.027649399 | I5: 0.042231396 | J5: 0.052930898 | K5: 0.049758102 | L5: 0.05254308 | M5: 0.039902331 | N5: 0.014630941 | O5: 0.014630941 | P5: 0.014630941 | Q5: 0.014630941 | R5: 0.023449619 | S5: 0.023449619 | T5: 0.023449619 | U5: 0.014630941 | V5: 0.014630941 | W5: 0.014630941 | X5: 0.020923494 | Y5: 0.014630941 | Z5: 0.044169201 | AA5: 0.0175705 | AB5: 0.017149479 | AC5: 0.026296393 | AD5: 0.020331918
A6: CX8 SARANDI | B6: 0.077005575 | C6: 0.069738464 | D6: 0.069738464 | E6: 0.058109613 | F6: 0.07761311 | G6: 0.22177404 | H6: 0.97972616 | I6: 1.6688756 | J6: 2.2689897 | K6: 2.1840303 | L6: 2.0516524 | M6: 1.475337 | N6: 0.82906481 | O6: 0.63442548 | P6: 0.60200097 | Q6: 0.73973589 | R6: 0.68915792 | S6: 0.62374027 | T6: 0.61056808 | U6: 0.18460174 | V6: 0.1464979 | W6: 0.14256251 | X6: 0.091162698 | Y6: 0.043719494 | Z6: 1.7714352 | AA6: 0.68635423 | AB6: 0.2031854 | AC6: 0.88699161 | AD6: 0.68915951
A7: CX10 CONTINENTE | B7: 0.027373888 | C7: 0.01614838 | D7: 0.0068006589 | E7: 0.0068006589 | F7: 0.0068006589 | G7: 0.0068006589 | H7: 0.035726243 | I7: 0.056451623 | J7: 0.066090648 | K7: 0.079644287 | L7: 0.12272823 | M7: 0.08864478 | N7: 0.033639596 | O7: 0.037234908 | P7: 0.024564171 | Q7: 0.03526584 | R7: 0.03526584 | S7: 0.026441958 | T7: 0.015216449 | U7: 0.0068006589 | V7: 0.0068006589 | W7: 0.0068006589 | X7: 0.019410269 | Y7: 0.018026167 | Z7: 0.074880969 | AA7: 0.032068718 | AB7: 0.01217581 | AC7: 0.039708499 | AD7: 0.032728245
A8: CX12 ORIENTAL | B8: 0.089102729 | C8: 0.087229846 | D8: 0.053081475 | E8: 0.019838936 | F8: 0.01042706 | G8: 0.090925551 | H8: 0.036487954 | I8: 0.1650154 | J8: 0.24630632 | K8: 0.24698023 | L8: 0.17137266 | M8: 0.21016131 | N8: 0.16216115 | O8: 0.071862971 | P8: 0.11673509 | Q8: 0.075372776 | R8: 0.084656241 | S8: 0.075421994 | T8: 0.0090396078 | U8: 0 | V8: 0.024092025 | W8: 0.082467994 | X8: 0.063862804 | Y8: 0.13374087 | Z8: 0.17938731 | AA8: 0.097701705 | AB8: 0.052200549 | AC8: 0.10976319 | AD8: 0.096930958
A9: CX14 EL ESPECTADOR | B9: 0 | C9: 0.0094876834 | D9: 0.0094876834 | E9: 0.0072671114 | F9: 0.0072671114 | G9: 0.022248106 | H9: 0.076737098 | I9: 0.12286231 | J9: 0.28009985 | K9: 0.25927731 | L9: 0.45198935 | M9: 0.4690916 | N9: 0.24963108 | O9: 0.17652799 | P9: 0.041726876 | Q9: 0.14692311 | R9: 0.23464385 | S9: 0.27439071 | T9: 0.078653225 | U9: 0.039342592 | V9: 0.028636566 | W9: 0.010292363 | X9: 0 | Y9: 0 | Z9: 0.27667625 | AA9: 0.18730727 | AB9: 0.026154124 | AC9: 0.16337922 | AD9: 0.12485765
A10: CX16 CARVE | B10: 0.084801394 | C10: 0.073634779 | D10: 0 | E10: 0.011268239 | F10: 0 | G10: 0.064485959 | H10: 0.20675901 | I10: 0.22821693 | J10: 0.2006183 | K10: 0.25887016 | L10: 0.22936588 | M10: 0.1571408 | N10: 0.22052713 | O10: 0.17398395 | P10: 0.12882885 | Q10: 0.12784881 | R10: 0.081583962 | S10: 0.044994091 | T10: 0.012878348 | U10: 0.012878348 | V10: 0.053256921 | W10: 0.13069266 | X10: 0.23262329 | Y10: 0.19751969 | Z10: 0.21349518 | AA10: 0.1296278 | AB10: 0.10664154 | AC10: 0.14992151 | AD10: 0.12219906
A11: CX18 SPORT 890 | B11: 0 | C11: 0 | D11: 0.0099076704 | E11: 0.0099076704 | F11: 0 | G11: 0.062912983 | H11: 0.33975224 | I11: 0.49572961 | J11: 0.76315577 | K11: 0.82943705 | L11: 0.98821104 | M11: 0.90028092 | N11: 0.88937124 | O11: 0.713653 | P11: 0.87379044 | Q11: 0.63233958 | R11: 0.45544495 | S11: 0.3451207 | T11: 0.19587668 | U11: 0.1474685 | V11: 0.060268058 | W11: 0.031382534 | X11: 0.039547925 | Y11: 0.059147862 | Z11: 0.71942777 | AA11: 0.65161998 | AB11: 0.088948592 | AC11: 0.48666545 | AD11: 0.3684461
A12: CX20 MONTECARLO | B12: 0.27722724 | C12: 0.044904229 | D12: 0.035196731 | E12: 0.018919646 | F12: 0.13413545 | G12: 0.49131302 | H12: 1.4129202 | I12: 2.4633354 | J12: 3.310048 | K12: 3.5984421 | L12: 3.6522394 | M12: 3.6260049 | N12: 2.6742012 | O12: 2.4057272 | P12: 2.1350699 | Q12: 1.6655244 | R12: 1.4885567 | S12: 1.2973073 | T12: 1.020451 | U12: 0.73272392 | V12: 0.59522539 | W12: 0.48860037 | X12: 0.51570991 | Y12: 0.44328492 | Z12: 3.0104983 | AA12: 1.9443978 | AB12: 0.63266592 | AC12: 1.8625207 | AD12: 1.4386279
A13: CX22 UNIVERSAL | B13: 0.1366626 | C13: 0.1366626 | D13: 0.034729918 | E13: 0.020270796 | F13: 0.0080550653 | G13: 0.022723337 | H13: 0.14723917 | I13: 0.059209543 | J13: 0.10405252 | K13: 0.10323707 | L13: 0.087215134 | M13: 0.11970726 | N13: 0.23393929 | O13: 0.26077241 | P13: 0.04085305 | Q13: 0.16450458 | R13: 0.16922487 | S13: 0.14902662 | T13: 0.1246723 | U13: 0.11020863 | V13: 0.049633249 | W13: 0.095865868 | X13: 0.069282617 | Y13: 0.070630562 | Z13: 0.10344345 | AA13: 0.16972014 | AB13: 0.086715538 | AC13: 0.11995971 | AD13: 0.10493246
A14: CX24 RADIO 1010 AM | B14: 0 | C14: 0 | D14: 0 | E14: 0 | F14: 0 | G14: 0 | H14: 0 | I14: 0.052554346 | J14: 0.075732632 | K14: 0.094549133 | L14: 0.10147175 | M14: 0.10147175 | N14: 0.052025837 | O14: 0.054563753 | P14: 0.066598529 | Q14: 0.16060139 | R14: 0.25816023 | S14: 0.094596716 | T14: 0.11259336 | U14: 0.10086569 | V14: 0.071710584 | W14: 0.045005601 | X14: 0 | Y14: 0 | Z14: 0.070963269 | AA14: 0.11442441 | AB14: 0.055029206 | AC14: 0.080138961 | AD14: 0.060104221
A15: CX26 RADIO URUGUAY | B15: 0.11156116 | C15: 0.08079023 | D15: 0.036745266 | E15: 0.036745266 | F15: 0 | G15: 0 | H15: 0.12603177 | I15: 0.12158542 | J15: 0.12520985 | K15: 0.14198205 | L15: 0.17301501 | M15: 0.10220222 | N15: 0.095223193 | O15: 0.12945062 | P15: 0.17249686 | Q15: 0.20151894 | R15: 0.20151894 | S15: 0.18763672 | T15: 0.1040427 | U15: 0.099278053 | V15: 0.09413503 | W15: 0.085140649 | X15: 0.15377596 | Y15: 0.19699583 | Z15: 0.13167105 | AA15: 0.16464088 | AB15: 0.12222804 | AC15: 0.13951332 | AD15: 0.11571174
... A31: RATING GENERAL | B31: 2.2693989 | C31: 1.4046613 | D31: 1.0030652 | E31: 0.7512738 | F31: 0.75661912 | G31: 2.4370274 | H31: 8.0910013 | I31: 14.124633 | J31: 23.733838 | K31: 31.064876 | L31: 34.347006 | M31: 33.579784 | N31: 29.196864 | O31: 26.95558 | P31: 26.837381 | Q31: 29.03866 | R31: 27.897252 | S31: 25.051574 | T31: 21.439031 | U31: 14.296286 | V31: 11.204793 | W31: 9.4791161 | X31: 6.0052686 | Y31: 4.5080844 | Z31: 24.156857 | AA31: 27.496219 | AB31: 11.15543 | AC31: 20.936168 | AD31: 16.061378
A35: CUADRO 4: RESUMEN DE RATING POR HORA | FM | LUNES A DOMINGO
A36: RADIOS | B36: HORAS | Z36: PROMEDIO
B37: 00:00 - 00:59 | C37: 01:00 - 01:59 | D37: 02:00 - 02:59 | E37: 03:00 - 03:59 | F37: 04:00 - 04:59 | G37: 05:00 - 05:59 | H37: 06:00 - 06:59 | I37: 07:00 - 07:59 | J37: 08:00 - 08:59 | K37: 09:00 - 09:59 | L37: 10:00 - 10:59 | M37: 11:00 - 11:59 | N37: 12:00 - 12:59 | O37: 13:00 - 13:59 | P37: 14:00 - 14:59 | Q37: 15:00 - 15:59 | R37: 16:00 - 16:59 | S37: 17:00 - 17:59 | T37: 18:00 - 18:59 | U37: 19:00 - 19:59 | V37: 20:00 - 20:59 | W37: 21:00 - 21:59 | X37: 22:00 - 22:59 | Y37: 23:00 - 23:59 | Z37: 06:00 - 11:59 | AA37: 12:00 - 17:59 | AB37: 18:00 - 23:59 | AC37: 06:00 - 23:59 | AD37: 00:00 - 24:00
A38: 88.3 LACOSTA | B38: 0.01178701 | C38: 0 | D38: 0 | E38: 0 | F38: 0.011616674 | G38: 0 | H38: 0.020472792 | I38: 0.010347905 | J38: 0.19920289 | K38: 0.44514284 | L38: 0.64891889 | M38: 0.61196657 | N38: 0.47903661 | O38: 0.4266856 | P38: 0.42695847 | Q38: 0.33879662 | R38: 0.33906837 | S38: 0.37334423 | T38: 0.36615617 | U38: 0.21592905 | V38: 0.15253054 | W38: 0.099432632 | X38: 0.15653401 | Y38: 0 | Z38: 0.32267532 | AA38: 0.39731498 | AB38: 0.16509707 | AC38: 0.29502912 | AD38: 0.22224699
A39: 90.3 OLDIES | B39: 0.0091973461 | C39: 0.023590799 | D39: 0 | E39: 0.0091973461 | F39: 0.0047040332 | G39: 0.064521813 | H39: 0.36062291 | I39: 0.41439917 | J39: 0.61329921 | K39: 1.0084324 | L39: 1.0170892 | M39: 0.95861672 | N39: 0.93870375 | O39: 0.90414311 | P39: 0.83649613 | Q39: 0.72501694 | R39: 0.71431994 | S39: 0.54411384 | T39: 0.64465776 | U39: 0.39505304 | V39: 0.35197514 | W39: 0.17033713 | X39: 0.090264819 | Y39: 0.059219739 | Z39: 0.72874327 | AA39: 0.77713228 | AB39: 0.28525127 | AC39: 0.59704228 | AD39: 0.45241551
A40: 91.1 RADIOFUTURA | B40: 0.015117198 | C40: 0.015117198 | D40: 0 | E40: 0 | F40: 0 | G40: 0.009483541 | H40: 0.04015747 | I40: 0.13298587 | J40: 0.86617612 | K40: 1.2428251 | L40: 1.1989587 | M40: 1.1403129 | N40: 0.95215885 | O40: 1.0070253 | P40: 1.2489091 | Q40: 1.2719415 | R40: 1.2744071 | S40: 1.1999518 | T40: 1.1281065 | U40: 0.62701646 | V40: 0.47236774 | W40: 0.32740939 | X40: 0.17767626 | Y40: 0.10833847 | Z40: 0.77023603 | AA40: 1.1590656 | AB40: 0.47348581 | AC40: 0.80092915 | AD40: 0.60235178
A41: 91.9 DISNEY | B41: 0.0080122355 | C41: 0.0080122355 | D41: 0.0080122355 | E41: 0.0080122355 | F41: 0.0287256 | G41: 0.096237207 | H41: 0.49940301 | I41: 0.691461 | J41: 0.9937757 | K41: 1.6922721 | L41: 2.1388844 | M41: 2.0977001 | N41: 1.8034155 | O41: 1.6329375 | P41: 1.788554 | Q41: 1.4803402 | R41: 1.4474885 | S41: 1.2554059 | T41: 1.0804487 | U41: 0.73898655 | V41: 0.63364372 | W41: 0.47320986 | X41: 0.11764465 | Y41: 0.016437356 | Z41: 1.3522494 | AA41: 1.5680236 | AB41: 0.51006181 | AC41: 1.1434449 | AD41: 0.86412585
A42: 92.5 CONCIERTO URBANA | B42: 0.0088557873 | C42: 0.0088557873 | D42: 0 | E42: 0 | F42: 0 | G42: 0 | H42: 0.0063019004 | I42: 0.038029506 | J42: 0.055415638 | K42: 0.078946678 | L42: 0.073566279 | M42: 0.055794661 | N42: 0.18256472 | O42: 0.14103974 | P42: 0.14021879 | Q42: 0.11742313 | R42: 0.093904184 | S42: 0.10054196 | T42: 0.15591034 | U42: 0.023097536 | V42: 0.10467622 | W42: 0.10288631 | X42: 0.026127956 | Y42: 0 | Z42: 0.051342444 | AA42: 0.12928209 | AB42: 0.068783059 | AC42: 0.083135864 | AD42: 0.06308988
A43: 93.1 INOLVIDABLE | B43: 0.0075771225 | C43: 0.0075771225 | D43: 0 | E43: 0 | F43: 0 | G43: 0.060989271 | H43: 0.14557865 | I43: 0.37086566 | J43: 1.135311 | K43: 1.235066 | L43: 1.3926115 | M43: 1.6150256 | N43: 1.7605148 | O43: 1.8277385 | P43: 1.6783901 | Q43: 1.6499071 | R43: 1.6703797 | S43: 1.325449 | T43: 1.2181658 | U43: 1.1396199 | V43: 1.1018329 | W43: 0.94063885 | X43: 0.38445452 | Y43: 0.17944616 | Z43: 0.98240975 | AA43: 1.6520632 | AB43: 0.82735969 | AC43: 1.1539442 | AD43: 0.86863081
A44: 93.9 OCEANO | B44: 0.059223358 | C44: 0.036242129 | D44: 0 | E44: 0 | F44: 0 | G44: 0 | H44: 0.045240222 | I44: 0.1743121 | J44: 0.67143221 | K44: 0.97839585 | L44: 1.0881267 | M44: 1.1530581 | N44: 1.1991432 | O44: 1.042932 | P44: 1.0580381 | Q44: 0.95653935 | R44: 0.93287545 | S44: 0.65681816 | T44: 0.54565514 | U44: 0.21518966 | V44: 0.097190717 | W44: 0.081133514 | X44: 0.041879564 | Y44: 0.033987832 | Z44: 0.68509419 | AA44: 0.97439105 | AB44: 0.16917274 | AC44: 0.60955266 | AD44: 0.46114222
A45: 94.7 E. DEL SUR | B45: 0 | C45: 0 | D45: 0 | E45: 0 | F45: 0 | G45: 0 | H45: 0.087002112 | I45: 0.090702431 | J45: 0.093827286 | K45: 0.113321 | L45: 0.13534322 | M45: 0.14125564 | N45: 0.050969066 | O45: 0.088648212 | P45: 0.12035998 | Q45: 0.14442808 | R45: 0.092051643 | S45: 0.048298835 | T45: 0.055370446 | U45: 0.13074844 | V45: 0.056295269 | W45: 0.020402477 | X45: 0.0087746718 | Y45: 0.0087746718 | Z45: 0.11024195 | AA45: 0.090792636 | AB45: 0.046727663 | AC45: 0.082587416 | AD45: 0.061940562
A46: 95.5 DEL PLATA | B46: 0.008671319 | C46: 0.057545241 | D46: 0.056135923 | E46: 0.048873922 | F46: 0.094269934 | G46: 0.045396011 | H46: 0.12691981 | I46: 0.38987392 | J46: 0.54522894 | K46: 0.78637683 | L46: 0.86090266 | M46: 1.0348085 | N46: 1.0979397 | O46: 1.1130519 | P46: 1.1938227 | Q46: 1.1408876 | R46: 1.0514014 | S46: 1.251268 | T46: 1.1042652 | U46: 0.85005861 | V46: 0.50787364 | W46: 0.34705706 | X46: 0.090656416 | Y46: 0.070635711 | Z46: 0.62401845 | AA46: 1.1413952 | AB46: 0.49509111 | AC46: 0.75350159 | AD46: 0.57808004
A47: 96.3 ALFA | B47: 0 | C47: 0 | D47: 0 | E47: 0 | F47: 0 | G47: 0 | H47: 0.020797484 | I47: 0.032958283 | J47: 0.10906787 | K47: 0.19074166 | L47: 0.23373129 | M47: 0.18320969 | N47: 0.15029979 | O47: 0.14730843 | P47: 0.11100447 | Q47: 0.09320389 | R47: 0.10251965 | S47: 0.09320389 | T47: 0.068089752 | U47: 0.052267499 | V47: 0.046622164 | W47: 0.025843418 | X47: 0.017888988 | Y47: 0 | Z47: 0.12841771 | AA47: 0.11625669 | AB47: 0.035118637 | AC47: 0.093264345 | AD47: 0.069948259
A48: 97.1 BABEL | B48: 0 | C48: 0.0077468601 | D48: 0 | E48: 0 | F48: 0 | G48: 0.0077468601 | H48: 0.031293356 | I48: 0.11232658 | J48: 0.17068549 | K48: 0.3909807 | L48: 0.504329 | M48: 0.45170729 | N48: 0.46488004 | O48: 0.3665072 | P48: 0.36664888 | Q48: 0.36232293 | R48: 0.37462672 | S48: 0.33172403 | T48: 0.22599391 | U48: 0.26704283 | V48: 0.18941015 | W48: 0.063637358 | X48: 0.037192776 | Y48: 0.0362201 | Z48: 0.27688707 | AA48: 0.37778497 | AB48: 0.13658285 | AC48: 0.26375163 | AD48: 0.19845929
A49: 97.9 M24 | B49: 0 | C49: 0 | D49: 0 | E49: 0 | F49: 0 | G49: 0 | H49: 0 | I49: 0.12157423 | J49: 0.22698645 | K49: 0.36559819 | L49: 0.45685722 | M49: 0.44737674 | N49: 0.33205096 | O49: 0.31268958 | P49: 0.33787259 | Q49: 0.30294595 | R49: 0.3354931 | S49: 0.26318046 | T49: 0.25116192 | U49: 0.17489255 | V49: 0.10588884 | W49: 0.11185843 | X49: 0.10613059 | Y49: 0.16228356 | Z49: 0.26973214 | AA49: 0.31403877 | AB49: 0.15203598 | AC49: 0.24526896 | AD49: 0.18395172
... A65: RATING GENERAL | B65: 2.2693989 | C65: 1.4046613 | D65: 1.0030652 | E65: 0.7512738 | F65: 0.75661912 | G65: 2.4370274 | H65: 8.0910013 | I65: 14.124633 | J65: 23.733838 | K65: 31.064876 | L65: 34.347006 | M65: 33.579784 | N65: 29.196864 | O65: 26.95558 | P65: 26.837381 | Q65: 29.03866 | R65: 27.897252 | S65: 25.051574 | T65: 21.439031 | U65: 14.296286 | V65: 11.204793 | W65: 9.4791161 | X65: 6.0052686 | Y65: 4.5080844 | Z65: 24.156857 | AA65: 27.496219 | AB65: 11.15543 | AC65: 20.936168 | AD65: 16.061378

Sheet RatxHoraxLV
A1: CUADRO 5: RESUMEN DE RATING POR HORA | AM | LUNES A VIERNES
A2: RADIOS | B2: HORAS | Z2: PROMEDIO
B3: 00:00 - 00:59 | C3: 01:00 - 01:59 | D3: 02:00 - 02:59 | E3: 03:00 - 03:59 | F3: 04:00 - 04:59 | G3: 05:00 - 05:59 | H3: 06:00 - 06:59 | I3: 07:00 - 07:59 | J3: 08:00 - 08:59 | K3: 09:00 - 09:59 | L3: 10:00 - 10:59 | M3: 11:00 - 11:59 | N3: 12:00 - 12:59 | O3: 13:00 - 13:59 | P3: 14:00 - 14:59 | Q3: 15:00 - 15:59 | R3: 16:00 - 16:59 | S3: 17:00 - 17:59 | T3: 18:00 - 18:59 | U3: 19:00 - 19:59 | V3: 20:00 - 20:59 | W3: 21:00 - 21:59 | X3: 22:00 - 22:59 | Y3: 23:00 - 23:59 | Z3: 06:00 - 11:59 | AA3: 12:00 - 17:59 | AB3: 18:00 - 23:59 | AC3: 06:00 - 23:59 | AD3: 00:00 - 24:00
A4: CX4 RURAL | B4: 0.060575635 | C4: 0.060575635 | D4: 0.060575635 | E4: 0.035621945 | F4: 0 | G4: 0.034274975 | H4: 0.10033044 | I4: 0.10482421 | J4: 0.11320335 | K4: 0.17955489 | L4: 0.12906162 | M4: 0.11509294 | N4: 0.077765279 | O4: 0.042680221 | P4: 0.21469518 | Q4: 0.15752737 | R4: 0.14482308 | S4: 0.017630971 | T4: 0 | U4: 0.026482385 | V4: 0.05261432 | W4: 0.044011647 | X4: 0.0075188363 | Y4: 0.0075188363 | Z4: 0.12367791 | AA4: 0.10918702 | AB4: 0.023024338 | AC4: 0.085296421 | AD4: 0.074456642
A5: CX6 CLÁSICA | B5: 0 | C5: 0 | D5: 0 | E5: 0 | F5: 0 | G5: 0.020483317 | H5: 0.038709158 | I5: 0.059123954 | J5: 0.038709158 | K5: 0.034267244 | L5: 0.020483317 | M5: 0.020483317 | N5: 0.020483317 | O5: 0.020483317 | P5: 0.020483317 | Q5: 0.020483317 | R5: 0.032829466 | S5: 0.032829466 | T5: 0.032829466 | U5: 0.020483317 | V5: 0.020483317 | W5: 0.020483317 | X5: 0.029292892 | Y5: 0.020483317 | Z5: 0.035296025 | AA5: 0.0245987 | AB5: 0.024009271 | AC5: 0.027967999 | AD5: 0.02182947
A6: CX8 SARANDI | B6: 0.095973645 | C6: 0.085799689 | D6: 0.085799689 | E6: 0.069519299 | F6: 0.082695925 | G6: 0.23803302 | H6: 1.1274339 | I6: 1.8185275 | J6: 2.4442541 | K6: 2.3162739 | L6: 2.2339669 | M6: 1.6072889 | N6: 0.88019185 | O6: 0.68930341 | P6: 0.64876632 | Q6: 0.73654978 | R6: 0.66422056 | S6: 0.61973897 | T6: 0.64135864 | U6: 0.15426259 | V6: 0.17739821 | W6: 0.17188865 | X6: 0.070339052 | Y6: 0.049039877 | Z6: 1.9246242 | AA6: 0.70646182 | AB6: 0.2107145 | AC6: 0.94726684 | AD6: 0.73785935
A7: CX10 CONTINENTE | B7: 0.038323444 | C7: 0.022607732 | D7: 0.0095209225 | E7: 0.0095209225 | F7: 0.0095209225 | G7: 0.0095209225 | H7: 0.05001674 | I7: 0.067894168 | J7: 0.081388802 | K7: 0.076855461 | L7: 0.1254085 | M7: 0.089456151 | N7: 0.022719636 | O7: 0.040346764 | P7: 0.022607732 | Q7: 0.022607732 | R7: 0.022607732 | S7: 0.025236634 | T7: 0.0095209225 | U7: 0.0095209225 | V7: 0.0095209225 | W7: 0.0095209225 | X7: 0.027174376 | Y7: 0.025236634 | Z7: 0.081836637 | AA7: 0.026021038 | AB7: 0.01508245 | AC7: 0.040980042 | AD7: 0.034860651
A8: CX12 ORIENTAL | B8: 0.044308385 | C8: 0.057485011 | D8: 0.036191256 | E8: 0.013176626 | F8: 0 | G8: 0.082745001 | H8: 0.036485252 | I8: 0.18644773 | J8: 0.29907736 | K8: 0.28739854 | L8: 0.19653876 | M8: 0.23032747 | N8: 0.16853545 | O8: 0.040968489 | P8: 0.12418707 | Q8: 0.09259394 | R8: 0.10559079 | S8: 0.10559079 | T8: 0.012655451 | U8: 0 | V8: 0.033728835 | W8: 0.083215932 | X8: 0.052235238 | Y8: 0.099947293 | Z8: 0.20604585 | AA8: 0.10624442 | AB8: 0.046963791 | AC8: 0.11975136 | AD8: 0.099559611
A9: CX14 EL ESPECTADOR | B9: 0 | C9: 0.013282757 | D9: 0.013282757 | E9: 0.010173956 | F9: 0.010173956 | G9: 0.031147348 | H9: 0.10743194 | I9: 0.16078939 | J9: 0.34360595 | K9: 0.32204438 | L9: 0.53058414 | M9: 0.55452728 | N9: 0.30051703 | O9: 0.2158556 | P9: 0.058417627 | Q9: 0.18022496 | R9: 0.26713645 | S9: 0.31049142 | T9: 0.084334699 | U9: 0.041590434 | V9: 0.040091192 | W9: 0.014409308 | X9: 0 | Y9: 0 | Z9: 0.33649718 | AA9: 0.22210718 | AB9: 0.030070939 | AC9: 0.1962251 | AD9: 0.15042136
A10: CX16 CARVE | B10: 0.10236792 | C10: 0.086734661 | D10: 0 | E10: 0 | F10: 0 | G10: 0.064237116 | H10: 0.22163235 | I10: 0.26593454 | J10: 0.23127815 | K10: 0.28748295 | L10: 0.22849406 | M10: 0.13921311 | N10: 0.24462999 | O10: 0.2197879 | P10: 0.14250252 | Q10: 0.12253818 | R10: 0.069417178 | S10: 0.032259587 | T10: 0.0058898406 | U10: 0.0058898406 | V10: 0.062419843 | W10: 0.14505334 | X10: 0.25106616 | Y10: 0.234397 | Z10: 0.22900586 | AA10: 0.13852256 | AB10: 0.11745267 | AC10: 0.16166036 | AD10: 0.13180109
A11: CX18 SPORT 890 | B11: 0 | C11: 0 | D11: 0 | E11: 0 | F11: 0 | G11: 0.077335917 | H11: 0.39332809 | I11: 0.56082173 | J11: 0.87626005 | K11: 0.96894699 | L11: 1.1114309 | M11: 1.0442378 | N11: 1.0795522 | O11: 0.8510719 | P11: 1.0282562 | Q11: 0.66741693 | R11: 0.48996514 | S11: 0.37018858 | T11: 0.22669676 | U11: 0.171519 | V11: 0.062209471 | W11: 0.043935548 | X11: 0.055367095 | Y11: 0.070610104 | Z11: 0.82583759 | AA11: 0.74774181 | AB11: 0.10505633 | AC11: 0.55954524 | AD11: 0.42288126
A12: CX20 MONTECARLO | B12: 0.2917301 | C12: 0.038979696 | D12: 0.025389199 | E12: 0.01381841 | F12: 0.16973346 | G12: 0.54334594 | H12: 1.5268004 | I12: 2.6472397 | J12: 3.5324582 | K12: 3.8906271 | L12: 4.0023183 | M12: 3.9408111 | N12: 2.929399 | O12: 2.657255 | P12: 2.312411 | Q12: 1.7891731 | R12: 1.6347459 | S12: 1.4402538 | T12: 1.1218416 | U12: 0.76425335 | V12: 0.61277503 | W12: 0.52454512 | X12: 0.56698845 | Y12: 0.48406934 | Z12: 3.2567091 | AA12: 2.1272063 | AB12: 0.67907881 | AC12: 2.0209981 | AD12: 1.5608734
A13: CX22 UNIVERSAL | B13: 0.15616746 | C13: 0.15616746 | D13: 0.038226192 | E13: 0.028379114 | F13: 0 | G13: 0.02053558 | H13: 0.16830959 | I13: 0.071616268 | J13: 0.11212149 | K13: 0.11097987 | L13: 0.082941436 | M13: 0.10384741 | N13: 0.25807197 | O13: 0.3027989 | P13: 0.0062757871 | Q13: 0.068887551 | R13: 0.086336998 | S13: 0.056805517 | T13: 0.037401295 | U13: 0.054020527 | V13: 0.03175855 | W13: 0.098227348 | X13: 0.075321857 | Y13: 0.088486071 | Z13: 0.10830268 | AA13: 0.12986279 | AB13: 0.064202608 | AC13: 0.10078936 | AD13: 0.092236844
A14: CX24 RADIO 1010 AM | B14: 0 | C14: 0 | D14: 0 | E14: 0 | F14: 0 | G14: 0 | H14: 0 | I14: 0.073576084 | J14: 0.10602569 | K14: 0.10968371 | L14: 0.11937538 | M14: 0.11937538 | N14: 0.072836172 | O14: 0.076389254 | P14: 0.093237941 | Q14: 0.18963958 | R14: 0.31334384 | S14: 0.084354924 | T14: 0.10963556 | U14: 0.10386158 | V14: 0.083190894 | W14: 0.063007842 | X14: 0 | Y14: 0 | Z14: 0.088006041 | AA14: 0.13830028 | AB14: 0.059949312 | AC14: 0.095418546 | AD14: 0.07156391
A15: CX26 RADIO URUGUAY | B15: 0.12019054 | C15: 0.09141362 | D15: 0.039609212 | E15: 0.039609212 | F15: 0 | G15: 0 | H15: 0.13797483 | I15: 0.15576317 | J15: 0.16083736 | K15: 0.18431844 | L15: 0.2148043 | M15: 0.1156664 | N15: 0.10589576 | O15: 0.16677444 | P15: 0.22703917 | Q15: 0.25379935 | R15: 0.25379935 | S15: 0.23436424 | T15: 0.11733261 | U15: 0.12453285 | V15: 0.11733261 | W15: 0.10474048 | X15: 0.20082992 | Y15: 0.24904711 | Z15: 0.16156075 | AA15: 0.20694538 | AB15: 0.1523026 | AC15: 0.17360291 | AD15: 0.14231979
... A31: RATING GENERAL | B31: 2.3922638 | C31: 1.5363196 | D31: 1.1487164 | E31: 0.87921107 | F31: 0.83292647 | G31: 2.7101834 | H31: 9.1108631 | I31: 15.396727 | J31: 25.700418 | K31: 33.696157 | L31: 37.013387 | M31: 35.895765 | N31: 31.43613 | O31: 29.077921 | P31: 29.127755 | Q31: 31.538139 | R31: 30.625821 | S31: 27.475452 | T31: 23.277273 | U31: 15.256897 | V31: 11.957481 | W31: 10.108187 | X31: 6.3382418 | Y31: 4.8325902 | Z31: 26.135553 | AA31: 29.880203 | AB31: 11.961778 | AC31: 22.659178 | AD31: 17.390201
A35: CUADRO 6: RESUMEN DE RATING POR HORA | FM | LUNES A VIERNES
A36: RADIOS | B36: HORAS | Z36: PROMEDIO
B37: 00:00 - 00:59 | C37: 01:00 - 01:59 | D37: 02:00 - 02:59 | E37: 03:00 - 03:59 | F37: 04:00 - 04:59 | G37: 05:00 - 05:59 | H37: 06:00 - 06:59 | I37: 07:00 - 07:59 | J37: 08:00 - 08:59 | K37: 09:00 - 09:59 | L37: 10:00 - 10:59 | M37: 11:00 - 11:59 | N37: 12:00 - 12:59 | O37: 13:00 - 13:59 | P37: 14:00 - 14:59 | Q37: 15:00 - 15:59 | R37: 16:00 - 16:59 | S37: 17:00 - 17:59 | T37: 18:00 - 18:59 | U37: 19:00 - 19:59 | V37: 20:00 - 20:59 | W37: 21:00 - 21:59 | X37: 22:00 - 22:59 | Y37: 23:00 - 23:59 | Z37: 06:00 - 11:59 | AA37: 12:00 - 17:59 | AB37: 18:00 - 23:59 | AC37: 06:00 - 23:59 | AD37: 00:00 - 24:00
A38: 88.3 LACOSTA | B38: 0.016501815 | C38: 0 | D38: 0 | E38: 0 | F38: 0 | G38: 0 | H38: 0 | I38: 0.014487067 | J38: 0.23837002 | K38: 0.48629842 | L38: 0.67975564 | M38: 0.65848956 | N38: 0.55922861 | O38: 0.46400515 | P38: 0.49915396 | Q38: 0.39914232 | R38: 0.38292311 | S38: 0.38823803 | T38: 0.41158165 | U38: 0.24603282 | V38: 0.16106814 | W38: 0.11251903 | X38: 0.15802546 | Y38: 0 | Z38: 0.34623345 | AA38: 0.44878186 | AB38: 0.18153785 | AC38: 0.32551772 | AD38: 0.24482587
A39: 90.3 OLDIES | B39: 0.012876285 | C39: 0.033027119 | D39: 0 | E39: 0.012876285 | F39: 0.0065856465 | G39: 0.076980174 | H39: 0.46582769 | I39: 0.36900478 | J39: 0.53046839 | K39: 1.0399055 | L39: 1.021094 | M39: 0.90882714 | N39: 0.94933386 | O39: 0.88474521 | P39: 0.83167468 | Q39: 0.75335498 | R39: 0.71976774 | S39: 0.54776222 | T39: 0.62319374 | U39: 0.37259718 | V39: 0.36014111 | W39: 0.19515096 | X39: 0.095510655 | Y39: 0.065210585 | Z39: 0.72252124 | AA39: 0.78110645 | AB39: 0.2853007 | AC39: 0.59630947 | AD39: 0.45316316
A40: 91.1 RADIOFUTURA | B40: 0 | C40: 0 | D40: 0 | E40: 0 | F40: 0 | G40: 0 | H40: 0.041630457 | I40: 0.18618022 | J40: 0.94920171 | K40: 1.3263829 | L40: 1.3257216 | M40: 1.2688772 | N40: 1.0056201 | O40: 1.0994708 | P40: 1.3800617 | Q40: 1.33661 | R40: 1.4212625 | S40: 1.3497443 | T40: 1.329742 | U40: 0.75828201 | V40: 0.5365665 | W40: 0.32071527 | X40: 0.12237909 | Y40: 0.079899049 | Z40: 0.84966568 | AA40: 1.2654616 | AB40: 0.52459732 | AC40: 0.87990819 | AD40: 0.65993114
A41: 91.9 DISNEY | B41: 0 | C41: 0 | D41: 0 | E41: 0 | F41: 0.015512605 | G41: 0.086172343 | H41: 0.55229305 | I41: 0.67618159 | J41: 1.0533289 | K41: 1.7805664 | L41: 2.2275918 | M41: 2.1880387 | N41: 1.9594036 | O41: 1.8035052 | P41: 1.9345678 | Q41: 1.6048624 | R41: 1.5973163 | S41: 1.2809137 | T41: 1.0905576 | U41: 0.78197056 | V41: 0.66621896 | W41: 0.57296844 | X41: 0.075582885 | Y41: 0.010359418 | Z41: 1.4130001 | AA41: 1.6967615 | AB41: 0.53294297 | AC41: 1.2142348 | AD41: 0.91491301
A42: 92.5 CONCIERTO URBANA | B42: 0 | C42: 0 | D42: 0 | E42: 0 | F42: 0 | G42: 0 | H42: 0.0088226605 | I42: 0.041070508 | J42: 0.066599582 | K42: 0.080373263 | L42: 0.080373263 | M42: 0.055492996 | N42: 0.21221394 | O42: 0.15407896 | P42: 0.13673182 | Q42: 0.10736614 | R42: 0.056742571 | S42: 0.086352933 | T42: 0.18040101 | U42: 0.032336551 | V42: 0.13079436 | W42: 0.12828849 | X42: 0.036579138 | Y42: 0 | Z42: 0.055455379 | AA42: 0.12558106 | AB42: 0.084733259 | AC42: 0.088589899 | AD42: 0.066442424
A43: 93.1 INOLVIDABLE | B43: 0.010607971 | C43: 0.010607971 | D43: 0 | E43: 0 | F43: 0 | G43: 0.073819072 | H43: 0.11205803 | I43: 0.38091619 | J43: 1.1869749 | K43: 1.1952287 | L43: 1.353254 | M43: 1.5495093 | N43: 1.7544069 | O43: 1.7248998 | P43: 1.5715902 | Q43: 1.5974687 | R43: 1.6272262 | S43: 1.3201676 | T43: 1.1995563 | U43: 1.2050503 | V43: 1.1879545 | W43: 0.96436481 | X43: 0.36771576 | Y43: 0.15125535 | Z43: 0.9629902 | AA43: 1.5992932 | AB43: 0.84598284 | AC43: 1.1360888 | AD43: 0.85602636
A44: 93.9 OCEANO | B44: 0.064559705 | C44: 0.039521851 | D44: 0 | E44: 0 | F44: 0 | G44: 0 | H44: 0.028620328 | I44: 0.15069704 | J44: 0.68470249 | K44: 1.0644401 | L44: 1.1683763 | M44: 1.1894193 | N44: 1.2022176 | O44: 1.0946019 | P44: 1.149907 | Q44: 1.088528 | R44: 1.050733 | S44: 0.71536612 | T44: 0.59629476 | U44: 0.23853504 | V44: 0.070838558 | W44: 0.065917465 | X44: 0.046067961 | Y44: 0.035019535 | Z44: 0.71437593 | AA44: 1.0502256 | AB44: 0.17544555 | AC44: 0.64668236 | AD44: 0.4893485
A45: 94.7 E. DEL SUR | B45: 0 | C45: 0 | D45: 0 | E45: 0 | F45: 0 | G45: 0 | H45: 0.12180296 | I45: 0.11506913 | J45: 0.11944393 | K45: 0.14602712 | L45: 0.14602712 | M45: 0.14275797 | N45: 0.040187844 | O45: 0.092938648 | P45: 0.12102916 | Q45: 0.15472449 | R45: 0.10457731 | S45: 0.054996081 | T45: 0.064896336 | U45: 0.11493853 | V45: 0.033932381 | W45: 0.016278927 | X45: 0 | Y45: 0 | Z45: 0.1318547 | AA45: 0.094742255 | AB45: 0.038341028 | AC45: 0.088312663 | AD45: 0.066234497
A46: 95.5 DEL PLATA | B46: 0 | C46: 0.068423491 | D46: 0.078590292 | E46: 0.068423491 | F46: 0.12015658 | G46: 0.051733091 | H46: 0.16586641 | I46: 0.47791463 | J46: 0.56771747 | K46: 0.81676534 | L46: 0.87703903 | M46: 1.0348947 | N46: 1.1167954 | O46: 1.2291971 | P46: 1.3336851 | Q46: 1.2549653 | R46: 1.1674178 | S46: 1.4052344 | T46: 1.2611822 | U46: 0.95092455 | V46: 0.59659382 | W46: 0.41628655 | X46: 0.10348708 | Y46: 0.087240205 | Z46: 0.6566996 | AA46: 1.2512159 | AB46: 0.56928573 | AC46: 0.82573373 | AD46: 0.63543892
A47: 96.3 ALFA | B47: 0 | C47: 0 | D47: 0 | E47: 0 | F47: 0 | G47: 0 | H47: 0.014937857 | I47: 0.031962975 | J47: 0.12639309 | K47: 0.21785028 | L47: 0.27002147 | M47: 0.21346984 | N47: 0.17541028 | O47: 0.18249295 | P47: 0.1316674 | Q47: 0.11836213 | R47: 0.13140419 | S47: 0.11836213 | T47: 0.083041113 | U47: 0.060889958 | V47: 0.065271029 | W47: 0.036180786 | X47: 0.025044583 | Y47: 0 | Z47: 0.14577258 | AA47: 0.14294985 | AB47: 0.045071245 | AC47: 0.11126456 | AD47: 0.083448419
A48: 97.1 BABEL | B48: 0 | C48: 0 | D48: 0 | E48: 0 | F48: 0 | G48: 0 | H48: 0.043810698 | I48: 0.13213507 | J48: 0.21383754 | K48: 0.39965775 | L48: 0.46094581 | M48: 0.40562457 | N48: 0.43543241 | O48: 0.34335211 | P48: 0.34746288 | Q48: 0.38715113 | R48: 0.41798648 | S48: 0.37520791 | T48: 0.21463389 | U48: 0.28083164 | V48: 0.20031133 | W48: 0.068566782 | X48: 0.052069886 | Y48: 0.039862535 | Z48: 0.2760019 | AA48: 0.38443215 | AB48: 0.14271268 | AC48: 0.26771558 | AD48: 0.20078668
A49: 97.9 M24 | B49: 0 | C49: 0 | D49: 0 | E49: 0 | F49: 0 | G49: 0 | H49: 0 | I49: 0.13594792 | J49: 0.24734959 | K49: 0.37486152 | L49: 0.50262416 | M49: 0.46583127 | N49: 0.3482163 | O49: 0.31847461 | P49: 0.32857521 | Q49: 0.29606229 | R49: 0.35071091 | S49: 0.26554621 | T49: 0.22671765 | U49: 0.15697701 | V49: 0.096940369 | W49: 0.096940369 | X49: 0.088921389 | Y49: 0.14460189 | Z49: 0.28776908 | AA49: 0.31793092 | AB49: 0.13518311 | AC49: 0.24696104 | AD49: 0.18522078
... A65: RATING GENERAL | B65: 2.3922638 | C65: 1.5363196 | D65: 1.1487164 | E65: 0.87921107 | F65: 0.83292647 | G65: 2.7101834 | H65: 9.1108631 | I65: 15.396727 | J65: 25.700418 | K65: 33.696157 | L65: 37.013387 | M65: 35.895765 | N65: 31.43613 | O65: 29.077921 | P65: 29.127755 | Q65: 31.538139 | R65: 30.625821 | S65: 27.475452 | T65: 23.277273 | U65: 15.256897 | V65: 11.957481 | W65: 10.108187 | X65: 6.3382418 | Y65: 4.8325902 | Z65: 26.135553 | AA65: 29.880203 | AB65: 11.961778 | AC65: 22.659178 | AD65: 17.390201

Sheet RatxHoraxSD
A1: CUADRO 7: RESUMEN DE RATING POR HORA | AM | SABADO A DOMINGO
A2: RADIOS | B2: HORAS | Z2: PROMEDIO
B3: 00:00 - 00:59 | C3: 01:00 - 01:59 | D3: 02:00 - 02:59 | E3: 03:00 - 03:59 | F3: 04:00 - 04:59 | G3: 05:00 - 05:59 | H3: 06:00 - 06:59 | I3: 07:00 - 07:59 | J3: 08:00 - 08:59 | K3: 09:00 - 09:59 | L3: 10:00 - 10:59 | M3: 11:00 - 11:59 | N3: 12:00 - 12:59 | O3: 13:00 - 13:59 | P3: 14:00 - 14:59 | Q3: 15:00 - 15:59 | R3: 16:00 - 16:59 | S3: 17:00 - 17:59 | T3: 18:00 - 18:59 | U3: 19:00 - 19:59 | V3: 20:00 - 20:59 | W3: 21:00 - 21:59 | X3: 22:00 - 22:59 | Y3: 23:00 - 23:59 | Z3: 06:00 - 11:59 | AA3: 12:00 - 17:59 | AB3: 18:00 - 23:59 | AC3: 06:00 - 23:59 | AD3: 00:00 - 24:00
A4: CX4 RURAL | B4: 0.031013701 | C4: 0 | D4: 0 | E4: 0 | F4: 0 | G4: 0 | H4: 0.094353562 | I4: 0.052646538 | J4: 0.2195132 | K4: 0.17377904 | L4: 0.14564166 | M4: 0.18988428 | N4: 0.16821522 | O4: 0.099875977 | P4: 0.11749658 | Q4: 0.078514476 | R4: 0.03931219 | S4: 0.037940447 | T4: 0 | U4: 0.071397583 | V4: 0.071436077 | W4: 0.065690927 | X4: 0 | Y4: 0.037426376 | Z4: 0.14596971 | AA4: 0.090225814 | AB4: 0.040991827 | AC4: 0.092395785 | AD4: 0.070589076
A5: CX6 CLÁSICA | B5: 0 | C5: 0 | D5: 0 | E5: 0 | F5: 0 | G5: 0 | H5: 0 | I5: 0 | J5: 0.088485247 | K5: 0.088485247 | L5: 0.13269249 | M5: 0.088449866 | N5: 0 | O5: 0 | P5: 0 | Q5: 0 | R5: 0 | S5: 0 | T5: 0 | U5: 0 | V5: 0 | W5: 0 | X5: 0 | Y5: 0 | Z5: 0.066352142 | AA5: 0 | AB5: 0 | AC5: 0.022117381 | AD5: 0.016588035
A6: CX8 SARANDI | B6: 0.0295854 | C6: 0.0295854 | D6: 0.0295854 | E6: 0.0295854 | F6: 0.064906071 | G6: 0.18112661 | H6: 0.61045683 | I6: 1.2947458 | J6: 1.8308288 | K6: 1.8534211 | L6: 1.5958662 | M6: 1.1454573 | N6: 0.70124721 | O6: 0.49723068 | P6: 0.48508761 | Q6: 0.74770118 | R6: 0.75150131 | S6: 0.63374355 | T6: 0.53359168 | U6: 0.26044961 | V6: 0.069247146 | W6: 0.069247146 | X6: 0.14322181 | Y6: 0.030418536 | Z6: 1.3884627 | AA6: 0.63608525 | AB6: 0.18436265 | AC6: 0.73630353 | AD6: 0.56740991
A7: CX10 CONTINENTE | B7: 0 | C7: 0 | D7: 0 | E7: 0 | F7: 0 | G7: 0 | H7: 0 | I7: 0.027845262 | J7: 0.027845262 | K7: 0.086616352 | L7: 0.11602756 | M7: 0.086616352 | N7: 0.060939493 | O7: 0.029455267 | P7: 0.029455267 | Q7: 0.066911108 | R7: 0.066911108 | S7: 0.029455267 | T7: 0.029455267 | U7: 0 | V7: 0 | W7: 0 | X7: 0 | Y7: 0 | Z7: 0.057491798 | AA7: 0.047187918 | AB7: 0.0049092112 | AC7: 0.036529642 | AD7: 0.027397232
A8: CX12 ORIENTAL | B8: 0.20108859 | C8: 0.16159193 | D8: 0.095307021 | E8: 0.036494709 | F8: 0.036494709 | G8: 0.11137693 | H8: 0.036494709 | I8: 0.11143459 | J8: 0.11437872 | K8: 0.14593444 | L8: 0.1084574 | M8: 0.15974589 | N8: 0.14622542 | O8: 0.14909918 | P8: 0.098105152 | Q8: 0.032319867 | R8: 0.032319867 | S8: 0 | T8: 0 | U8: 0 | V8: 0 | W8: 0.080598148 | X8: 0.092931718 | Y8: 0.2182248 | Z8: 0.11274096 | AA8: 0.076344913 | AB8: 0.065292444 | AC8: 0.084792772 | AD8: 0.090359324
A9: CX14 EL ESPECTADOR | B9: 0 | C9: 0 | D9: 0 | E9: 0 | F9: 0 | G9: 0 | H9: 0 | I9: 0.028044606 | J9: 0.1213346 | K9: 0.10235965 | L9: 0.25550239 | M9: 0.25550239 | N9: 0.12241619 | O9: 0.078208946 | P9: 0 | Q9: 0.063668504 | R9: 0.15341236 | S9: 0.18413891 | T9: 0.06444954 | U9: 0.033722988 | V9: 0 | W9: 0 | X9: 0 | Y9: 0 | Z9: 0.12712394 | AA9: 0.10030749 | AB9: 0.016362088 | AC9: 0.081264505 | AD9: 0.060948379
A10: CX16 CARVE | B10: 0.040885073 | C10: 0.040885073 | D10: 0 | E10: 0.039438837 | F10: 0 | G10: 0.065108068 | H10: 0.16957568 | I10: 0.13392288 | J10: 0.12396868 | K10: 0.18733818 | L10: 0.23154542 | M10: 0.20196002 | N10: 0.16026997 | O10: 0.059474094 | P10: 0.094644666 | Q10: 0.1411254 | R10: 0.11200092 | S10: 0.076830351 | T10: 0.030349617 | U10: 0.030349617 | V10: 0.030349617 | W10: 0.094790955 | X10: 0.18651612 | Y10: 0.10532641 | Z10: 0.17471848 | AA10: 0.1073909 | AB10: 0.079613722 | AC10: 0.12057437 | AD10: 0.098193986
A11: CX18 SPORT 890 | B11: 0 | C11: 0 | D11: 0.034676846 | E11: 0.034676846 | F11: 0 | G11: 0.026855648 | H11: 0.20581262 | I11: 0.33299932 | J11: 0.48039506 | K11: 0.48066219 | L11: 0.68016149 | M11: 0.54038873 | N11: 0.41391888 | O11: 0.37010573 | P11: 0.48762616 | Q11: 0.54464623 | R11: 0.36914446 | S11: 0.28245101 | T11: 0.11882648 | U11: 0.087342252 | V11: 0.055414524 | W11: 0 | X11: 0 | Y11: 0.030492258 | Z11: 0.45340323 | AA11: 0.41131541 | AB11: 0.048679252 | AC11: 0.30446597 | AD11: 0.2323582
A12: CX20 MONTECARLO | B12: 0.24097009 | C12: 0.059715561 | D12: 0.059715561 | E12: 0.031672737 | F12: 0.045140399 | G12: 0.36123073 | H12: 1.1282199 | I12: 2.0035747 | J12: 2.7540223 | K12: 2.8679797 | L12: 2.7770423 | M12: 2.8389893 | N12: 2.0362067 | O12: 1.7769077 | P12: 1.691717 | Q12: 1.3564026 | R12: 1.1230834 | S12: 0.93994112 | T12: 0.76697471 | U12: 0.65390034 | V12: 0.55135129 | W12: 0.39873849 | X12: 0.38751357 | Y12: 0.34132387 | Z12: 2.3949714 | AA12: 1.4873764 | AB12: 0.51663371 | AC12: 1.4663272 | AD12: 1.1330139
A13: CX22 UNIVERSAL | B13: 0.087900461 | C13: 0.087900461 | D13: 0.025989234 | E13: 0 | F13: 0.028192728 | G13: 0.028192728 | H13: 0.094563106 | I13: 0.028192728 | J13: 0.083880082 | K13: 0.083880082 | L13: 0.097899378 | M13: 0.15935689 | N13: 0.17360758 | O13: 0.15570619 | P13: 0.12729621 | Q13: 0.40354715 | R13: 0.37644455 | S13: 0.37957937 | T13: 0.3428498 | U13: 0.25067891 | V13: 0.094319996 | W13: 0.089962167 | X13: 0.054184516 | Y13: 0.025991788 | Z13: 0.091295378 | AA13: 0.26936351 | AB13: 0.14299786 | AC13: 0.16788558 | AD13: 0.1366715
A14: CX24 RADIO 1010 AM | B14: 0 | C14: 0 | D14: 0 | E14: 0 | F14: 0 | G14: 0 | H14: 0 | I14: 0 | J14: 0 | K14: 0.056712679 | L14: 0.056712679 | M14: 0.056712679 | N14: 0 | O14: 0 | P14: 0 | Q14: 0.088005902 | R14: 0.1202012 | S14: 0.1202012 | T14: 0.11998785 | U14: 0.093375984 | V14: 0.04300981 | W14: 0 | X14: 0 | Y14: 0 | Z14: 0.028356339 | AA14: 0.054734717 | AB14: 0.04272894 | AC14: 0.041939999 | AD14: 0.031454999
A15: CX26 RADIO URUGUAY | B15: 0.0899877 | C15: 0.054231754 | D15: 0.0295854 | E15: 0.0295854 | F15: 0 | G15: 0 | H15: 0.096174111 | I15: 0.036141067 | J15: 0.036141067 | K15: 0.036141067 | L15: 0.068541784 | M15: 0.068541784 | N15: 0.068541784 | O15: 0.036141067 | P15: 0.036141067 | Q15: 0.070817913 | R15: 0.070817913 | S15: 0.070817913 | T15: 0.070817913 | U15: 0.036141067 | V15: 0.036141067 | W15: 0.036141067 | X15: 0.036141067 | Y15: 0.066867619 | Z15: 0.056946813 | AA15: 0.05887961 | AB15: 0.047041633 | AC15: 0.054289352 | AD15: 0.049191608
... A31: RATING GENERAL | B31: 1.9622368 | C31: 1.0755154 | D31: 0.63893727 | E31: 0.4314306 | F31: 0.56585073 | G31: 1.7541372 | H31: 5.5413469 | I31: 10.944398 | J31: 18.817387 | K31: 24.486676 | L31: 27.681054 | M31: 27.789833 | N31: 23.598699 | O31: 21.649729 | P31: 21.111449 | Q31: 22.78996 | R31: 21.07583 | S31: 18.991878 | T31: 16.843426 | U31: 11.894757 | V31: 9.3230744 | W31: 7.906439 | X31: 5.1728354 | Y31: 3.6968199 | Z31: 19.210116 | AA31: 21.536258 | AB31: 9.1395586 | AC31: 16.628644 | AD31: 12.739321
A34: CUADRO 8: RESUMEN DE RATING POR HORA | FM | SABADO A DOMINGO
A35: RADIOS | B35: HORAS | Z35: PROMEDIO
B36: 00:00 - 00:59 | C36: 01:00 - 01:59 | D36: 02:00 - 02:59 | E36: 03:00 - 03:59 | F36: 04:00 - 04:59 | G36: 05:00 - 05:59 | H36: 06:00 - 06:59 | I36: 07:00 - 07:59 | J36: 08:00 - 08:59 | K36: 09:00 - 09:59 | L36: 10:00 - 10:59 | M36: 11:00 - 11:59 | N36: 12:00 - 12:59 | O36: 13:00 - 13:59 | P36: 14:00 - 14:59 | Q36: 15:00 - 15:59 | R36: 16:00 - 16:59 | S36: 17:00 - 17:59 | T36: 18:00 - 18:59 | U36: 19:00 - 19:59 | V36: 20:00 - 20:59 | W36: 21:00 - 21:59 | X36: 22:00 - 22:59 | Y36: 23:00 - 23:59 | Z36: 06:00 - 11:59 | AA36: 12:00 - 17:59 | AB36: 18:00 - 23:59 | AC36: 06:00 - 23:59 | AD36: 00:00 - 24:00
A37: 88.3 LACOSTA | B37: 0 | C37: 0 | D37: 0 | E37: 0 | F37: 0.040658358 | G37: 0 | H37: 0.07165477 | I37: 0 | J37: 0.10128508 | K37: 0.34225387 | L37: 0.57182703 | M37: 0.49565911 | N37: 0.27855659 | O37: 0.33338674 | P37: 0.24646974 | Q37: 0.18793238 | R37: 0.22943152 | S37: 0.33610972 | T37: 0.25259247 | U37: 0.14066964 | V37: 0.13118655 | W37: 0.066716627 | X37: 0.15280538 | Y37: 0 | Z37: 0.26377998 | AA37: 0.26864778 | AB37: 0.12399511 | AC37: 0.21880762 | AD37: 0.16579982
A38: 90.3 OLDIES | B38: 0 | C38: 0 | D38: 0 | E38: 0 | F38: 0 | G38: 0.03337591 | H38: 0.097610937 | I38: 0.52788515 | J38: 0.82037626 | K38: 0.92974983 | L38: 1.0070772 | M38: 1.0830907 | N38: 0.91212846 | O38: 0.95263784 | P38: 0.84854975 | Q38: 0.65417186 | R38: 0.70070044 | S38: 0.53499286 | T38: 0.69831781 | U38: 0.45119271 | V38: 0.33156022 | W38: 0.10830257 | X38: 0.077150231 | Y38: 0.044242624 | Z38: 0.74429835 | AA38: 0.76719687 | AB38: 0.28512769 | AC38: 0.5988743 | AD38: 0.45054639
A39: 91.1 RADIOFUTURA | B39: 0.052910194 | C39: 0.052910194 | D39: 0 | E39: 0 | F39: 0 | G39: 0.033192394 | H39: 0.036475002 | I39: 0 | J39: 0.65861217 | K39: 1.0339304 | L39: 0.88205158 | M39: 0.81890224 | N39: 0.81850568 | O39: 0.77591153 | P39: 0.92102767 | Q39: 1.1102705 | R39: 0.90726862 | S39: 0.82547053 | T39: 0.62401787 | U39: 0.29885257 | V39: 0.31187085 | W39: 0.34414467 | X39: 0.31591919 | Y39: 0.17943701 | Z39: 0.57166189 | AA39: 0.89307575 | AB39: 0.34570703 | AC39: 0.60348156 | AD39: 0.45840337
A40: 91.9 DISNEY | B40: 0.028042824 | C40: 0.028042824 | D40: 0.028042824 | E40: 0.028042824 | F40: 0.061758087 | G40: 0.12139937 | H40: 0.36717792 | I40: 0.72965952 | J40: 0.84489284 | K40: 1.4715363 | L40: 1.9171158 | M40: 1.8718536 | N40: 1.4134451 | O40: 1.2065183 | P40: 1.4235194 | Q40: 1.1690347 | R40: 1.0729188 | S40: 1.1916364 | T40: 1.0551767 | U40: 0.63152652 | V40: 0.55220561 | W40: 0.22381338 | X40: 0.22279906 | Y40: 0.0316322 | Z40: 1.2003727 | AA40: 1.2461788 | AB40: 0.45285891 | AC40: 0.96647013 | AD40: 0.73715796
A41: 92.5 CONCIERTO URBANA | B41: 0.030995255 | C41: 0.030995255 | D41: 0 | E41: 0 | F41: 0 | G41: 0 | H41: 0 | I41: 0.030427002 | J41: 0.027455777 | K41: 0.075380218 | L41: 0.056548821 | M41: 0.056548821 | N41: 0.10844169 | O41: 0.10844169 | P41: 0.14893622 | Q41: 0.1425656 | R41: 0.18680822 | S41: 0.13601453 | T41: 0.094683642 | U41: 0 | V41: 0.039380856 | W41: 0.039380856 | X41: 0 | Y41: 0 | Z41: 0.041060107 | AA41: 0.13853466 | AB41: 0.028907559 | AC41: 0.069500775 | AD41: 0.054708519
A42: 93.1 INOLVIDABLE | B42: 0 | C42: 0 | D42: 0 | E42: 0 | F42: 0 | G42: 0.028914766 | H42: 0.22938022 | I42: 0.34573933 | J42: 1.0061512 | K42: 1.3346594 | L42: 1.4910053 | M42: 1.7788163 | N42: 1.7757846 | O42: 2.0848352 | P42: 1.94539 | Q42: 1.7810032 | R42: 1.7782634 | S42: 1.3386523 | T42: 1.2646895 | U42: 0.97604416 | V42: 0.88652878 | W42: 0.88132395 | X42: 0.42630142 | Y42: 0.2499232 | Z42: 1.0309586 | AA42: 1.7839881 | AB42: 0.78080183 | AC42: 1.1985829 | AD42: 0.90014193
A43: 93.9 OCEANO | B43: 0.045882491 | C43: 0.028042824 | D43: 0 | E43: 0 | F43: 0 | G43: 0 | H43: 0.086789956 | I43: 0.23334973 | J43: 0.63825652 | K43: 0.76328517 | L43: 0.88750258 | M43: 1.0621552 | N43: 1.1914573 | O43: 0.91375707 | P43: 0.82836596 | Q43: 0.6265677 | R43: 0.63823154 | S43: 0.51044824 | T43: 0.41905611 | U43: 0.15682621 | V43: 0.16307112 | W43: 0.11917364 | X43: 0.031408574 | Y43: 0.031408574 | Z43: 0.61188985 | AA43: 0.78480464 | AB43: 0.1534907 | AC43: 0.5167284 | AD43: 0.39062652
A44: 94.7 E. DEL SUR | B44: 0 | C44: 0 | D44: 0 | E44: 0 | F44: 0 | G44: 0 | H44: 0 | I44: 0.029785674 | J44: 0.029785674 | K44: 0.031555722 | L44: 0.10863347 | M44: 0.13749983 | N44: 0.07792212 | O44: 0.07792212 | P44: 0.11868703 | Q44: 0.11868703 | R44: 0.060737485 | S44: 0.031555722 | T44: 0.031555722 | U44: 0.17027323 | V44: 0.11220249 | W44: 0.030711351 | X44: 0.030711351 | Y44: 0.030711351 | Z44: 0.056210062 | AA44: 0.080918586 | AB44: 0.06769425 | AC44: 0.068274299 | AD44: 0.051205724
A45: 95.5 DEL PLATA | B45: 0.030349617 | C45: 0.030349617 | D45: 0 | E45: 0 | F45: 0.029553311 | G45: 0.029553311 | H45: 0.029553311 | I45: 0.16977215 | J45: 0.48900762 | K45: 0.71040555 | L45: 0.82056173 | M45: 1.0345931 | N45: 1.0508005 | O45: 0.82268862 | P45: 0.84416684 | Q45: 0.85569324 | R45: 0.76136033 | S45: 0.86635224 | T45: 0.71197277 | U45: 0.59789377 | V45: 0.28607318 | W45: 0.17398335 | X45: 0.058579744 | Y45: 0.029124477 | Z45: 0.54231558 | AA45: 0.86684363 | AB45: 0.30960455 | AC45: 0.57292125 | AD45: 0.43468285
A46: 96.3 ALFA | B46: 0 | C46: 0 | D46: 0 | E46: 0 | F46: 0 | G46: 0 | H46: 0.035446551 | I46: 0.035446551 | J46: 0.065754838 | K46: 0.12297012 | L46: 0.14300585 | M46: 0.1075593 | N46: 0.087523565 | O46: 0.05934715 | P46: 0.05934715 | Q46: 0.030308288 | R46: 0.030308288 | S46: 0.030308288 | T46: 0.030711351 | U46: 0.030711351 | V46: 0 | W46: 0 | X46: 0 | Y46: 0 | Z46: 0.085030536 | AA46: 0.049523788 | AB46: 0.010237117 | AC46: 0.048263814 | AD46: 0.03619786
A47: 97.1 BABEL | B47: 0 | C47: 0.027114011 | D47: 0 | E47: 0 | F47: 0 | G47: 0.027114011 | H47: 0 | I47: 0.062805365 | J47: 0.062805365 | K47: 0.36928809 | L47: 0.61278697 | M47: 0.56691409 | N47: 0.53849911 | O47: 0.42439493 | P47: 0.41461389 | Q47: 0.30025244 | R47: 0.26622733 | S47: 0.22301435 | T47: 0.25439396 | U47: 0.23257082 | V47: 0.16215717 | W47: 0.051313799 | X47: 0 | Y47: 0.027114011 | Z47: 0.27909998 | AA47: 0.36116701 | AB47: 0.12125829 | AC47: 0.25384176 | AD47: 0.19264082
A48: 97.9 M24 | B48: 0 | C48: 0 | D48: 0 | E48: 0 | F48: 0 | G48: 0 | H48: 0 | I48: 0.085640009 | J48: 0.17607861 | K48: 0.34243987 | L48: 0.34243987 | M48: 0.40124042 | N48: 0.2916376 | O48: 0.29822701 | P48: 0.36111603 | Q48: 0.32015509 | R48: 0.29744859 | S48: 0.25726607 | T48: 0.31227258 | U48: 0.2196814 | V48: 0.12826002 | W48: 0.1491536 | X48: 0.1491536 | Y48: 0.20648772 | Z48: 0.2246398 | AA48: 0.3043084 | AB48: 0.19416815 | AC48: 0.24103878 | AD48: 0.18077909
... A64: RATING GENERAL | B64: 1.9622368 | C64: 1.0755154 | D64: 0.63893727 | E64: 0.4314306 | F64: 0.56585073 | G64: 1.7541372 | H64: 5.5413469 | I64: 10.944398 | J64: 18.817387 | K64: 24.486676 | L64: 27.681054 | M64: 27.789833 | N64: 23.598699 | O64: 21.649729 | P64: 21.111449 | Q64: 22.78996 | R64: 21.07583 | S64: 18.991878 | T64: 16.843426 | U64: 11.894757 | V64: 9.3230744 | W64: 7.906439 | X64: 5.1728354 | Y64: 3.6968199 | Z64: 19.210116 | AA64: 21.536258 | AB64: 9.1395586 | AC64: 16.628644 | AD64: 12.739321

Sheet RatxLDxABC1
A1: CUADRO 9: RESUMEN DE RATING POR HORA - SEGMENTO ABC1 | AM | LUNES A DOMINGO
A2: RADIOS | B2: HORAS | Z2: PROMEDIO
B3: 00:00 - 00:59 | C3: 01:00 - 01:59 | D3: 02:00 - 02:59 | E3: 03:00 - 03:59 | F3: 04:00 - 04:59 | G3: 05:00 - 05:59 | H3: 06:00 - 06:59 | I3: 07:00 - 07:59 | J3: 08:00 - 08:59 | K3: 09:00 - 09:59 | L3: 10:00 - 10:59 | M3: 11:00 - 11:59 | N3: 12:00 - 12:59 | O3: 13:00 - 13:59 | P3: 14:00 - 14:59 | Q3: 15:00 - 15:59 | R3: 16:00 - 16:59 | S3: 17:00 - 17:59 | T3: 18:00 - 18:59 | U3: 19:00 - 19:59 | V3: 20:00 - 20:59 | W3: 21:00 - 21:59 | X3: 22:00 - 22:59 | Y3: 23:00 - 23:59 | Z3: 06:00 - 11:59 | AA3: 12:00 - 17:59 | AB3: 18:00 - 23:59 | AC3: 06:00 - 23:59 | AD3: 00:00 - 24:00
A4: CX4 RURAL | B4: 0 | C4: 0 | D4: 0 | E4: 0 | F4: 0 | G4: 0.10286607 | H4: 0.2202273 | I4: 0.041922816 | J4: 0.11426514 | K4: 0.11426514 | L4: 0.11426514 | M4: 0.12545472 | N4: 0.12545472 | O4: 0 | P4: 0.077111147 | Q4: 0.085036018 | R4: 0 | S4: 0 | T4: 0 | U4: 0 | V4: 0 | W4: 0 | X4: 0 | Y4: 0 | Z4: 0.12173338 | AA4: 0.047933647 | AB4: 0 | AC4: 0.056555674 | AD4: 0.046702842
A5: CX6 CLÁSICA | B5: 0 | C5: 0 | D5: 0 | E5: 0 | F5: 0 | G5: 0 | H5: 0 | I5: 0.061268895 | J5: 0.10622479 | K5: 0.14759312 | L5: 0.15929471 | M5: 0.10618231 | N5: 0 | O5: 0 | P5: 0 | Q5: 0 | R5: 0 | S5: 0 | T5: 0 | U5: 0 | V5: 0 | W5: 0 | X5: 0 | Y5: 0 | Z5: 0.096760636 | AA5: 0 | AB5: 0 | AC5: 0.032253545 | AD5: 0.024190159
A6: CX8 SARANDI | B6: 0.19322505 | C6: 0.19322505 | D6: 0.19322505 | E6: 0.19322505 | F6: 0.19322505 | G6: 0.45273028 | H6: 1.9254234 | I6: 2.9156934 | J6: 4.352831 | K6: 4.2821684 | L6: 3.8425091 | M6: 2.7815099 | N6: 1.5177621 | O6: 1.2935807 | P6: 1.4562233 | Q6: 1.7394561 | R6: 1.7394561 | S6: 1.2719643 | T6: 1.4336934 | U6: 0.13173087 | V6: 0.055541427 | W6: 0 | X6: 0 | Y6: 0 | Z6: 3.3500225 | AA6: 1.5030738 | AB6: 0.27016096 | AC6: 1.7077524 | AD6: 1.3399333
A7: CX10 CONTINENTE | B7: 0.047166001 | C7: 0 | D7: 0 | E7: 0 | F7: 0 | G7: 0 | H7: 0 | I7: 0 | J7: 0 | K7: 0.10398122 | L7: 0.18878626 | M7: 0.23595226 | N7: 0.11276864 | O7: 0.088598855 | P7: 0.035360465 | Q7: 0.035360465 | R7: 0.035360465 | S7: 0.082526466 | T7: 0.035360465 | U7: 0 | V7: 0 | W7: 0 | X7: 0.052981554 | Y7: 0.047166001 | Z7: 0.088119956 | AA7: 0.064995893 | AB7: 0.02258467 | AC7: 0.058566839 | AD7: 0.04589038
A8: CX12 ORIENTAL | B8: 0.080784877 | C8: 0.080784877 | D8: 0 | E8: 0 | F8: 0 | G8: 0.042686901 | H8: 0.10949956 | I8: 0.31485217 | J8: 0.36901638 | K8: 0.37184793 | L8: 0.35735007 | M8: 0.40327011 | N8: 0.15577795 | O8: 0.15577795 | P8: 0.079316107 | Q8: 0.23991143 | R8: 0.23991143 | S8: 0.23991143 | T8: 0 | U8: 0 | V8: 0 | W8: 0.13132242 | X8: 0.10385991 | Y8: 0.23984575 | Z8: 0.3209727 | AA8: 0.18510105 | AB8: 0.079171347 | AC8: 0.1950817 | AD8: 0.15482197
A9: CX14 EL ESPECTADOR | B9: 0 | C9: 0 | D9: 0 | E9: 0 | F9: 0 | G9: 0 | H9: 0.080743135 | I9: 0.1866825 | J9: 0.613928 | K9: 0.56895736 | L9: 1.5151194 | M9: 1.5869775 | N9: 0.92618804 | O9: 0.48406104 | P9: 0.093747002 | Q9: 0.28923834 | R9: 0.45990163 | S9: 0.58159329 | T9: 0.036886617 | U9: 0 | V9: 0.077076484 | W9: 0 | X9: 0 | Y9: 0 | Z9: 0.75873465 | AA9: 0.47245489 | AB9: 0.01899385 | AC9: 0.4167278 | AD9: 0.31254585
A10: CX16 CARVE | B10: 0 | C10: 0.047166001 | D10: 0 | E10: 0 | F10: 0 | G10: 0.032341184 | H10: 0.22556624 | I10: 0.51490916 | J10: 0.56207517 | K10: 0.78335782 | L10: 0.70653134 | M10: 0.51330629 | N10: 0.5630648 | O10: 0.36652933 | P10: 0.042742036 | Q10: 0.098541236 | R10: 0.14570724 | S10: 0.055799201 | T10: 0 | U10: 0 | V10: 0.1330997 | W10: 0.0859337 | X10: 0.0859337 | Y10: 0 | Z10: 0.55095767 | AA10: 0.21206397 | AB10: 0.05082785 | AC10: 0.27128316 | AD10: 0.20677517
A11: CX18 SPORT 890 | B11: 0 | C11: 0 | D11: 0.041628867 | E11: 0.041628867 | F11: 0 | G11: 0 | H11: 0.29769449 | I11: 0.29769449 | J11: 0.31077888 | K11: 0.24889195 | L11: 0.5023959 | M11: 0.71427538 | N11: 1.1742418 | O11: 0.83791292 | P11: 0.92707677 | Q11: 0.64709464 | R11: 0.51780743 | S11: 0.50275019 | T11: 0.32074182 | U11: 0.093172313 | V11: 0.054843708 | W11: 0 | X11: 0 | Y11: 0 | Z11: 0.39528852 | AA11: 0.76781396 | AB11: 0.078126307 | AC11: 0.41374293 | AD11: 0.31377627
A12: CX20 MONTECARLO | B12: 0 | C12: 0 | D12: 0 | E12: 0 | F12: 0.22202808 | G12: 0.38284189 | H12: 1.1199197 | I12: 2.0013814 | J12: 1.211719 | K12: 1.3751361 | L12: 1.5995742 | M12: 1.7574807 | N12: 1.6114078 | O12: 1.3535492 | P12: 1.0404373 | Q12: 0.98849414 | R12: 0.53885488 | S12: 0.36218518 | T12: 0.38516634 | U12: 0.32087039 | V12: 0.35961147 | W12: 0.085573351 | X12: 0.12609993 | Y12: 0.27263017 | Z12: 1.5108685 | AA12: 0.98248809 | AB12: 0.25832528 | AC12: 0.91722729 | AD12: 0.71312339
A13: CX22 UNIVERSAL | B13: 0.388864 | C13: 0.388864 | D13: 0 | E13: 0 | F13: 0 | G13: 0 | H13: 0 | I13: 0 | J13: 0.055192686 | K13: 0 | L13: 0 | M13: 0.059344671 | N13: 0.059344671 | O13: 0.060746403 | P13: 0.056588372 | Q13: 0.056588372 | R13: 0 | S13: 0.034925623 | T13: 0.034925623 | U13: 0.066812654 | V13: 0 | W13: 0 | X13: 0 | Y13: 0.039508446 | Z13: 0.019089559 | AA13: 0.044698907 | AB13: 0.02354112 | AC13: 0.029109862 | AD13: 0.05423773
A14: CX24 RADIO 1010 AM | B14: 0 | C14: 0 | D14: 0 | E14: 0 | F14: 0 | G14: 0 | H14: 0 | I14: 0 | J14: 0 | K14: 0 | L14: 0 | M14: 0 | N14: 0 | O14: 0 | P14: 0.056655547 | Q14: 0.28960823 | R14: 0.28960823 | S14: 0 | T14: 0 | U14: 0.060573387 | V14: 0.060573387 | W14: 0 | X14: 0 | Y14: 0 | Z14: 0 | AA14: 0.10597867 | AB14: 0.020191129 | AC14: 0.042056599 | AD14: 0.031542449
A15: CX26 RADIO URUGUAY | B15: 0.15439187 | C15: 0.15439187 | D15: 0.15439187 | E15: 0.15439187 | F15: 0 | G15: 0 | H15: 0 | I15: 0.096602747 | J15: 0.096602747 | K15: 0.29753271 | L15: 0.37699031 | M15: 0.079457595 | N15: 0.079457595 | O15: 0.19394665 | P15: 0.37481321 | Q15: 0.41644208 | R15: 0.41644208 | S15: 0.37972276 | T15: 0.041628867 | U15: 0 | V15: 0 | W15: 0 | X15: 0.29753271 | Y15: 0.38809997 | Z15: 0.15786435 | AA15: 0.3101374 | AB15: 0.12121026 | AC15: 0.196404 | AD15: 0.17303498
... A31: RATING GENERAL | B31: 1.3009242 | C31: 1.3825349 | D31: 0.70926897 | E31: 0.86098977 | F31: 0.91311436 | G31: 1.9988827 | H31: 7.8996562 | I31: 15.558743 | J31: 26.436106 | K31: 36.153754 | L31: 40.139033 | M31: 38.706663 | N31: 31.821054 | O31: 28.526937 | P31: 27.393035 | Q31: 29.107344 | R31: 28.521533 | S31: 24.740896 | T31: 20.573514 | U31: 11.966725 | V31: 7.0042992 | W31: 4.1113212 | X31: 2.7611735 | Y31: 1.8404868 | Z31: 27.482326 | AA31: 28.3518 | AB31: 8.04292 | AC31: 21.292349 | AD31: 16.267833
A34: CUADRO 10: RESUMEN DE RATING POR HORA - SEGMENTO ABC1 | FM | LUNES A DOMINGO
A35: RADIOS | B35: HORAS | Z35: PROMEDIO
B36: 00:00 - 00:59 | C36: 01:00 - 01:59 | D36: 02:00 - 02:59 | E36: 03:00 - 03:59 | F36: 04:00 - 04:59 | G36: 05:00 - 05:59 | H36: 06:00 - 06:59 | I36: 07:00 - 07:59 | J36: 08:00 - 08:59 | K36: 09:00 - 09:59 | L36: 10:00 - 10:59 | M36: 11:00 - 11:59 | N36: 12:00 - 12:59 | O36: 13:00 - 13:59 | P36: 14:00 - 14:59 | Q36: 15:00 - 15:59 | R36: 16:00 - 16:59 | S36: 17:00 - 17:59 | T36: 18:00 - 18:59 | U36: 19:00 - 19:59 | V36: 20:00 - 20:59 | W36: 21:00 - 21:59 | X36: 22:00 - 22:59 | Y36: 23:00 - 23:59 | Z36: 06:00 - 11:59 | AA36: 12:00 - 17:59 | AB36: 18:00 - 23:59 | AC36: 06:00 - 23:59 | AD36: 00:00 - 24:00
A37: 88.3 LACOSTA | B37: 0 | C37: 0 | D37: 0 | E37: 0 | F37: 0 | G37: 0 | H37: 0 | I37: 0 | J37: 0.51980712 | K37: 0.89307713 | L37: 1.4976254 | M37: 1.2784391 | N37: 1.0056908 | O37: 0.85275158 | P37: 0.60817545 | Q37: 0.62264005 | R37: 0.62309257 | S37: 0.65240354 | T37: 0.52363863 | U37: 0.15565824 | V37: 0 | W37: 0.1230738 | X37: 0.39809289 | Y37: 0 | Z37: 0.69815811 | AA37: 0.727459 | AB37: 0.20007726 | AC37: 0.54189812 | AD37: 0.40642359
A38: 90.3 OLDIES | B38: 0 | C38: 0 | D38: 0 | E38: 0 | F38: 0 | G38: 0 | H38: 0 | I38: 0.26096849 | J38: 0.81064529 | K38: 1.5658811 | L38: 1.6713719 | M38: 1.5392278 | N38: 1.7630474 | O38: 1.7626178 | P38: 1.2998629 | Q38: 1.2902726 | R38: 1.3127655 | S38: 1.245162 | T38: 1.7598674 | U38: 1.3173311 | V38: 0.96320751 | W38: 0.35941742 | X38: 0.053112393 | Y38: 0.053112393 | Z38: 0.97468243 | AA38: 1.4456214 | AB38: 0.75100803 | AC38: 1.0571039 | AD38: 0.79282796
A39: 91.1 RADIOFUTURA | B39: 0.06351764 | C39: 0.06351764 | D39: 0 | E39: 0 | F39: 0 | G39: 0 | H39: 0.075745955 | I39: 0.23901137 | J39: 1.1147609 | K39: 1.4880515 | L39: 1.2230814 | M39: 0.99497388 | N39: 0.76973704 | O39: 0.77611895 | P39: 0.84073593 | Q39: 0.99032529 | R39: 1.1990898 | S39: 0.97741788 | T39: 0.78509347 | U39: 0.69965144 | V39: 0.56174561 | W39: 0.38665175 | X39: 0.42197119 | Y39: 0.13063593 | Z39: 0.8559375 | AA39: 0.92557082 | AB39: 0.4976249 | AC39: 0.75971107 | AD39: 0.57507644
