Workbook
Name _ftn1: Intro2!#REF!
Name _ftn2: Intro2!#REF!
Name _ftn3: Intro2!#REF!

Sheet Tapa
A49: MEDICION GENERAL DE AUDIENCIA DE RADIO
A50: JULIO - SETIEMBRE 2021

Sheet Intro1
F15: No. 39
F16: MEDICION GENERAL DE AUDIENCIA DE RADIO
F17: JULIO - SETIEMBRE 2021
F47: MEDICION AUDITADA POR

Sheet Intro2
F1: CARACTERISTICAS GENERALES DEL RELEVAMIENTO
A3: OBJETIVO GENERAL
A4: Estimar la escucha de radio y caracterizar desde un punto de vista socio-demográfico a los radioescuchas.
A6: OBJETIVOS ESPECIFICOS
A7: Se estimaron las siguientes medidas de audiencia: (i) Cobertura semanal (ii) Share (iii) Rating del Medio y de cada Radio y la información se presenta discriminada según los siguientes dominios: (i) Banda (AM – FM) (ii) Emisora (iii) Día (Lunes a Domingo) (iv) Hora (en tramos de una hora) (v) Lugar de Escucha (vi) Sexo (vii) Edad (12 años y más) (viii) Nivel Socioeconómico
A9: POBLACION
A10: La medición se realizó sobre la población de 12 años y más residente en hogares particulares en Montevideo y Zona Metropolitana (ZM). La ZM se compone por las siguientes sub-zonas: Ciudad de la Costa, Ciudad del Plata, La Paz, Las Piedras y Pando. De acuerdo con los datos publicados por el INE correspondientes al Censo de Población, Hogares y Viviendas realizado en 2011 (CPHV 2011) y considerando, que se excluyen del universo las personas que residen en viviendas colectivas (hoteles, pensiones, asilos, internado de estudiantes, cuarteles, cárceles, conventos, etc.) la población del universo objetivo se compone de 1:311.422 personas. En este sentido, cada punto de rating corresponde a 13.114 personas.
A12: TRABAJO DE CAMPO
A13: PERIODO: el trabajo de campo se realizó desde el 13/07 hasta el 01/09.
A14: TIPO DE RELEVAMIENTO: cara a cara en la entrevista inicial y autoempadronamiento en las siguientes instancias.
A15: SOPORTE PARA RELEVAMEINTO: formulario en papel y web.
A16: ENTREVISTA: en la entrevista inicial se relevó la escucha coincidental y la declarada en el día anterior. En las 6 instancias posteriores que completan la semana de escucha, el participante completó el formulario cada día con la escucha del día anterior.
A18: DISEÑO MUESTRAL
... A26: COBERTURA SEMANAL: se define como la cantidad de personas distintas que escucharon por lo menos una emisora de radio en la semana.

Sheet IndiceC
A1: INDICE DE CUADROS
A3: =+EstMuestra!A1 -> CUADRO 1: CARACTERIZACION DE LA POBLACION Y LA MUESTRA
A4: =+Error!A1 -> CUADRO 2: NIVELES DE ERROR DE LAS ESTIMACIONES
A5: =+RatxHoraxLD!A1 -> CUADRO 3: RESUMEN DE RATING POR HORA | AM | LUNES A DOMINGO
A6: =+RatxHoraxLD!A32 -> CUADRO 4: RESUMEN DE RATING POR HORA | FM | LUNES A DOMINGO
A7: =+RatxHoraxLV!A1 -> CUADRO 5: RESUMEN DE RATING POR HORA | AM | LUNES A VIERNES
A8: =+RatxHoraxLV!A32 -> CUADRO 6: RESUMEN DE RATING POR HORA | FM | LUNES A VIERNES
A9: =+RatxHoraxSD!A1 -> CUADRO 7: RESUMEN DE RATING POR HORA | AM | SABADO A DOMINGO
A10: =+RatxHoraxSD!A32 -> CUADRO 8: RESUMEN DE RATING POR HORA | FM | SABADO A DOMINGO
A11: =+RatxLDxABC1!A1 -> CUADRO 9: RESUMEN DE RATING POR HORA - SEGMENTO ABC1 | AM | LUNES A DOMINGO
A12: =+RatxLDxABC1!A32 -> CUADRO 10: RESUMEN DE RATING POR HORA - SEGMENTO ABC1 | FM | LUNES A DOMINGO
A13: =+RatxLVxABC1!A1 -> CUADRO 11: RESUMEN DE RATING POR HORA - SEGMENTO ABC1 | AM | LUNES A VIERNES
A14: =+RatxLVxABC1!A32 -> CUADRO 12: RESUMEN DE RATING POR HORA - SEGMENTO ABC1 | FM | LUNES A VIERNES
A15: =+RatxSDxABC1!A1 -> CUADRO 13: RESUMEN DE RATING POR HORA - SEGMENTO ABC1 | AM | SABADO A DOMINGO
A16: =+RatxSDxABC1!A32 -> CUADRO 14: RESUMEN DE RATING POR HORA - SEGMENTO ABC1 | FM | SABADO A DOMINGO
A17: =+RatxLDxC2C3D1!A1 -> CUADRO 15: RESUMEN DE RATING POR HORA - SEGMENTO C2C3D1 | AM | LUNES A DOMINGO
A18: =+RatxLDxC2C3D1!A32 -> CUADRO 16: RESUMEN DE RATING POR HORA - SEGMENTO C2C3D1 | FM | LUNES A DOMINGO
A19: =+RatxLVxC2C3D1!A1 -> CUADRO 17: RESUMEN DE RATING POR HORA - SEGMENTO C2C3D1 | AM | LUNES A VIERNES
A20: =+RatxLVxC2C3D1!A32 -> CUADRO 18: RESUMEN DE RATING POR HORA - SEGMENTO C2C3D1 | FM | LUNES A VIERNES
A21: =+RatxSDxC2C3D1!A1 -> CUADRO 19: RESUMEN DE RATING POR HORA - SEGMENTO C2C3D1 | AM | SABADO A DOMINGO
A22: =+RatxSDxC2C3D1!A32 -> CUADRO 20: RESUMEN DE RATING POR HORA - SEGMENTO C2C3D1 | FM | SABADO A DOMINGO
A23: =+RatxLDxD2E!A1 -> CUADRO 21: RESUMEN DE RATING POR HORA - SEGMENTO D2E | AM | LUNES A DOMINGO
A24: =+RatxLDxD2E!A32 -> CUADRO 22: RESUMEN DE RATING POR HORA - SEGMENTO D2E | FM | LUNES A DOMINGO
A25: =+RatxLVxD2E!A1 -> CUADRO 23: RESUMEN DE RATING POR HORA - SEGMENTO D2E | AM | LUNES A VIERNES
A26: =+RatxLVxD2E!A32 -> CUADRO 24: RESUMEN DE RATING POR HORA - SEGMENTO D2E | FM | LUNES A VIERNES
A27: =+RatxSDxD2E!A1 -> CUADRO 25: RESUMEN DE RATING POR HORA - SEGMENTO D2E | AM | SABADO A DOMINGO
A28: =+RatxSDxD2E!A32 -> CUADRO 26: RESUMEN DE RATING POR HORA - SEGMENTO D2E | FM | SABADO A DOMINGO
A29: =+RatxNSE!A1 -> CUADROS 27 - 28: RESUMEN DE RATING PROMEDIO - HORA POR NIVEL SOCIOECONÓMICO | AM - FM
A30: =+RatxEdad!A1 -> CUADROS 29 - 30: RESUMEN DE RATING POR EDAD | AM - FM
A31: =+RatxSexo!A1 -> CUADROS 31 - 32: RESUMEN DE RATING PROMEDIO-HORA POR SEXO | AM - FM
A32: =+RatxLugar!A1 -> CUADRO 33: RESUMEN DE RATING POR LUGAR DE ESCUCHA
A33: =+Cobertura!A1 -> CUADRO 34: COBERTURA SEMANAL POR NIVEL SOCIOECONÓMICO, EDAD Y SEXO | AM | LUNES A DOMINGO
A34: =+Cobertura!A32 -> CUADRO 35: COBERTURA SEMANAL POR NIVEL SOCIOECONÓMICO, EDAD Y SEXO | FM | LUNES A DOMINGO
A35: =+ShaxHoraxLD!A1 -> CUADRO 36: RESUMEN DE SHARE POR HORA | AM | LUNES A DOMINGO
A36: =+ShaxHoraxLD!A32 -> CUADRO 37: RESUMEN DE SHARE POR HORA | FM | LUNES A DOMINGO
A37: =+SharexHoraxLV!A1 -> CUADRO 38: RESUMEN DE SHARE POR HORA | AM | LUNES A VIERNES
A38: =+SharexHoraxLV!A31 -> CUADRO 39: RESUMEN DE SHARE POR HORA | FM | LUNES A VIERNES
A39: =+SharexHoraxSD!A1 -> CUADRO 40: RESUMEN DE SHARE POR HORA | AM | SABADO A DOMINGO
A40: =+SharexHoraxSD!A31 -> CUADRO 41: RESUMEN DE SHARE POR HORA | FM | SABADO A DOMINGO
A41: =+AudienciaxLD!A1 -> CUADRO 42: RESUMEN DE AUDIENCIA POR HORA | AM | LUNES A DOMINGO
...

Sheet InidiceG
A1: INDICE DE GRAFICOS
A3: =+GraxRAM!A1 -> PANEL 1: RESUMEN DE RATING Y COBERTURA | AM
A4: =+GraxRAMxNSE!A1 -> PANEL 2: RESUMEN DE RATING POR NSE | AM | LUNES A DOMINGO | 00:00 - 24:00
A5: =+GraxRFM!A1 -> PANEL 3: RESUMEN DE RATING Y COBERTURA | FM
A6: =+GraxRFMxNSE!A1 -> PANEL 4: RESUMEN DE RATING POR NSE | FM | LUNES A DOMINGO | 00:00 - 24:00
A7: =+EncxLug!A1 -> PANEL 5: RESUMEN DE ENCENDIDO POR LUGAR DE ESCUCHA
A8: =+CrvEncAMxLD!A1 -> PANEL 6: CURVAS DE ENCENDIDO | AM | LUNES A DOMINGO
A9: =+CrvEncAMxLV!A1 -> PANEL 7:CURVAS DE ENCENDIDO | AM | LUNES A VIERNES
A10: =+CrvEncAMxSD!A1 -> PANEL 8: CURVAS DE ENCENDIDO | AM | SABADO A DOMINGO
A11: =+CrvEncFMxLD!A1 -> PANEL 9: CURVAS DE ENCENDIDO | FM | LUNES A DOMINGO
A12: =+CrvEncFMxLV!A1 -> PANEL 10: CURVAS DE ENCENDIDO | FM | LUNES A VIERNES
A13: =+CrvEncFMxSD!A1 -> PANEL 11: CURVAS DE ENCENDIDO | FM | SABADO A DOMINGO

Sheet EstMuestra
A1: CUADRO 1: CARACTERIZACION DE LA POBLACION Y LA MUESTRA
A2: DIMENSION | B2: POBLACION | D2: MUESTRA
B3: TOTAL | C3: % | D3: TOTAL | E3: %
A4: ZONA | B4: 1311422 | C4: 100.04377 | D4: 2557 | E4: 100
A5: Montevideo | B5: 1099709 | C5: 83.9 | D5: 2225 | E5: 87.016034
A6: Estrato 1 | B6: 189149.95 | C6: 17.2 | D6: 440 | E6: 17.207665
A7: Estrato 2 | B7: 199047.33 | C7: 18.1 | D7: 502 | E7: 19.632382
A8: Estrato 3 | B8: 236437.43 | C8: 21.5 | D8: 531 | E8: 20.766523
A9: Estrato 4 | B9: 197947.62 | C9: 18 | D9: 452 | E9: 17.676965
A10: Estrato 5 | B10: 100073.52 | C10: 9.1 | D10: 300 | E10: 11.732499
A11: A. Metropolitana | B11: 211713 | C11: 16.143774 | D11: 332 | E11: 12.983966
A12: SEXO | B12: 1311422 | C12: 100 | D12: 2557 | E12: 100
A13: Masculino | B13: 602164 | C13: 45.916875 | D13: 1176 | E13: 45.991396
A14: Femenino | B14: 709258 | C14: 54.083125 | D14: 1381 | E14: 54.008604
A15: EDAD | B15: 1311422 | C15: 100 | D15: 2557 | E15: 100
... A29: B- | B29: 70126.98 | C29: 5.3474 | D29: 350 | E29: 13.687916

Sheet Error
A1: CUADRO 2: NIVELES DE ERROR DE LAS ESTIMACIONES
A2: 95 % DE CONFIANZA
A3: DISEÑO | B3: MUESTRA | F3: RATING DIARIO
B4: TOTAL | C4: DIARIA | D4: ROTATIVA | E4: PANEL
F5: 0.005 | G5: 0.01 | H5: 0.02 | I5: 0.03 | J5: 0.05 | K5: 0.1 | L5: 0.15 | M5: 0.2
A6: MEDICION 2021 | B6: 2557 | C6: 1475.2857 | D6: 180.28571 | E6: 1295 | F6: 0.0034410503 | G6: 0.0048541375 | H6: 0.0068300284 | I6: 0.008322254 | J6: 0.010632644 | K6: 0.014635775 | L6: 0.017420057 | M6: 0.019514367
A7: MEDICION 2019 | B7: 2000 | C7: 1190 | D7: 135 | E7: 1055 | F7: 0.0038428924 | G7: 0.0054209983 | H7: 0.0076276317 | I7: 0.0092941178 | J7: 0.011874313 | K7: 0.016344925 | L7: 0.019454352 | M7: 0.021793233
A8: MEDICION 2018 | B8: 2000 | C8: 1251.7143 | D8: 124.71429 | E8: 1127 | F8: 0.0037649807 | G8: 0.0053110917 | H8: 0.0074729873 | I8: 0.0091056866 | J8: 0.01163357 | K8: 0.016013544 | L8: 0.01905993 | M8: 0.021351392
A9: Notas: Muestra Total = Total de entrevistas realizadas. Muestra diaria = suma de los casos de panel + la muestra rotativa dividida en 7 dias. Muestra rotativa = muestra que no es de panel (hay menos de 7 observaciones de consumo por dia para cada persona). Panel = casos con observaciones en 7 dias.

Sheet RatxHoraxLD
A1: CUADRO 3: RESUMEN DE RATING POR HORA | AM | LUNES A DOMINGO
A2: RADIOS | B2: HORAS | Z2: PROMEDIO
B3: 00:00 - 00:59 | C3: 01:00 - 01:59 | D3: 02:00 - 02:59 | E3: 03:00 - 03:59 | F3: 04:00 - 04:59 | G3: 05:00 - 05:59 | H3: 06:00 - 06:59 | I3: 07:00 - 07:59 | J3: 08:00 - 08:59 | K3: 09:00 - 09:59 | L3: 10:00 - 10:59 | M3: 11:00 - 11:59 | N3: 12:00 - 12:59 | O3: 13:00 - 13:59 | P3: 14:00 - 14:59 | Q3: 15:00 - 15:59 | R3: 16:00 - 16:59 | S3: 17:00 - 17:59 | T3: 18:00 - 18:59 | U3: 19:00 - 19:59 | V3: 20:00 - 20:59 | W3: 21:00 - 21:59 | X3: 22:00 - 22:59 | Y3: 23:00 - 23:59 | Z3: 06:00 - 11:59 | AA3: 12:00 - 17:59 | AB3: 18:00 - 23:59 | AC3: 06:00 - 23:59 | AD3: 00:00 - 24:00
A4: 610 - CX4 RURAL | B4: 0.20842363 | C4: 0.26194653 | D4: 0.21755039 | E4: 0 | F4: 0.025330871 | G4: 0.073186629 | H4: 0.21095787 | I4: 0.44740424 | J4: 0.56999386 | K4: 0.52069744 | L4: 0.3940646 | M4: 0.32184314 | N4: 0.22721756 | O4: 0.47212013 | P4: 0.32434411 | Q4: 0.32434411 | R4: 0.21261771 | S4: 0.21261771 | T4: 0.22721756 | U4: 0.23951044 | V4: 0.26004234 | W4: 0.44080323 | X4: 0.30275236 | Y4: 0.1898492 | Z4: 0.41082686 | AA4: 0.29554356 | AB4: 0.27669585 | AC4: 0.32768876 | AD4: 0.27853482
A5: 650 - CX6 CLÁSICA | B5: 0.022927857 | C5: 0.035078771 | D5: 0.054892114 | E5: 0.015764029 | F5: 0 | G5: 0 | H5: 0.038126271 | I5: 0.048793543 | J5: 0.024955129 | K5: 0.024953814 | L5: 0.024953814 | M5: 0.024953814 | N5: 0 | O5: 0 | P5: 0 | Q5: 0 | R5: 0.0054067 | S5: 0.024955129 | T5: 0 | U5: 0 | V5: 0 | W5: 0.0058029857 | X5: 0.0199914 | Y5: 0.0199914 | Z5: 0.031122731 | AA5: 0.0050603048 | AB5: 0.0076309643 | AC5: 0.014604667 | AD5: 0.016314449
A6: 690 - CX8 SARANDI | B6: 0.078120429 | C6: 0.034402843 | D6: 0.0162792 | E6: 0 | F6: 0.053094843 | G6: 0.68062014 | H6: 2.5354106 | I6: 4.0942142 | J6: 3.6686256 | K6: 3.7078617 | L6: 2.5849394 | M6: 2.1145786 | N6: 1.138619 | O6: 0.55550364 | P6: 0.7366538 | Q6: 0.52147941 | R6: 0.3566734 | S6: 0.38337747 | T6: 0.45822777 | U6: 0.3849164 | V6: 0.10438501 | W6: 0.19632487 | X6: 0.28423043 | Y6: 0.19703104 | Z6: 3.117605 | AA6: 0.61538446 | AB6: 0.27085259 | AC6: 1.334614 | AD6: 1.0368987
A7: 730 - CX10 CONTINENTE | B7: 0.097129357 | C7: 0.091722657 | D7: 0.097129357 | E7: 0.059394914 | F7: 0 | G7: 0 | H7: 0.047800114 | I7: 0.096255357 | J7: 0.142671 | K7: 0.058637843 | L7: 0.049115386 | M7: 0.033526086 | N7: 0.033526086 | O7: 0.044339486 | P7: 0 | Q7: 0 | R7: 0.094215757 | S7: 0.099622457 | T7: 0.053206814 | U7: 0.22083329 | V7: 0.0690432 | W7: 0.053206814 | X7: 0 | Y7: 0.0054067 | Z7: 0.071334298 | AA7: 0.045283964 | AB7: 0.066949469 | AC7: 0.061189244 | AD7: 0.060282611
A8: 770 - CX12 ORIENTAL | B8: 0.057036686 | C8: 0.011688214 | D8: 0.011688214 | E8: 0.0042579714 | F8: 0.0042579714 | G8: 0.092935443 | H8: 0.065759943 | I8: 0.37806097 | J8: 0.4008801 | K8: 0.14169067 | L8: 0.41549999 | M8: 0.2404039 | N8: 0.24779466 | O8: 0.16679854 | P8: 0.15377729 | Q8: 0.36086946 | R8: 0.23327823 | S8: 0.22085356 | T8: 0.045663271 | U8: 0.039723529 | V8: 0.024148829 | W8: 0.23488507 | X8: 0.20502667 | Y8: 0.072697886 | Z8: 0.27371593 | AA8: 0.23056195 | AB8: 0.10369088 | AC8: 0.20265625 | AD8: 0.15956988
A9: 810 - CX14 EL ESPECTADOR | B9: 0.28811796 | C9: 0.24913503 | D9: 0.032673143 | E9: 0.078084271 | F9: 0 | G9: 0.020942757 | H9: 0.061111671 | I9: 0.59287346 | J9: 0.82207436 | K9: 0.85038967 | L9: 0.79048861 | M9: 0.76352511 | N9: 0.64958211 | O9: 0.85649783 | P9: 1.1254442 | Q9: 1.1501957 | R9: 0.70215379 | S9: 0.43573727 | T9: 0.16843273 | U9: 0.13998233 | V9: 0.037500971 | W9: 0.14017376 | X9: 0.072195714 | Y9: 0.20507904 | Z9: 0.64674381 | AA9: 0.81993515 | AB9: 0.12722742 | AC9: 0.53130213 | AD9: 0.42634964
A10: 850 - CX16 CARVE | B10: 0.41653004 | C10: 0.40060147 | D10: 0.38227927 | E10: 0.22125246 | F10: 0.15252099 | G10: 0.37265767 | H10: 0.90471964 | I10: 1.7092339 | J10: 0.98648217 | K10: 0.60702677 | L10: 0.38617997 | M10: 0.37120713 | N10: 0.2340895 | O10: 0.33131903 | P10: 0.4276449 | Q10: 0.36313701 | R10: 0.30387159 | S10: 0.17084524 | T10: 0.083588771 | U10: 0.1490925 | V10: 0.18841476 | W10: 0.44660296 | X10: 0.47336931 | Y10: 0.43463923 | Z10: 0.82747493 | AA10: 0.30515121 | AB10: 0.29595125 | AC10: 0.47619247 | AD10: 0.4382211
A11: 890 - CX18 SPORT 890 | B11: 0.017477386 | C11: 0.0054067 | D11: 0.031771829 | E11: 0.040165957 | F11: 0.028211371 | G11: 0.1170275 | H11: 0.23304381 | I11: 1.2782525 | J11: 2.0582024 | K11: 1.79239 | L11: 1.7225517 | M11: 1.4627146 | N11: 0.97686563 | O11: 1.2302284 | P11: 1.2079762 | Q11: 1.0790511 | R11: 1.0224139 | S11: 0.89246783 | T11: 0.73428059 | U11: 0.7137409 | V11: 0.44923189 | W11: 0.46505481 | X11: 0.30688796 | Y11: 0.15473746 | Z11: 1.4245258 | AA11: 1.0681672 | AB11: 0.4706556 | AC11: 0.98778287 | AD11: 0.75083968
A12: 930 - CX20 MONTECARLO | B12: 0.41469239 | C12: 0.24496297 | D12: 0.11571253 | E12: 0.10604263 | F12: 0.13181251 | G12: 0.67396511 | H12: 1.6308231 | I12: 2.5782399 | J12: 3.7821652 | K12: 4.8897681 | L12: 4.6942538 | M12: 4.3552334 | N12: 3.5243649 | O12: 3.4514763 | P12: 2.2053835 | Q12: 1.6595553 | R12: 1.5248968 | S12: 1.5426587 | T12: 1.5795637 | U12: 1.3541144 | V12: 1.1763595 | W12: 0.92977093 | X12: 0.44972787 | Y12: 0.35060044 | Z12: 3.6550806 | AA12: 2.3180559 | AB12: 0.97335613 | AC12: 2.3154975 | AD12: 1.8069227
A13: 970 - CX22 UNIVERSAL | B13: 0.4406454 | C13: 0.060592514 | D13: 0.022952114 | E13: 0.051954429 | F13: 0.073781029 | G13: 0.0576363 | H13: 0.10470779 | I13: 0.33323464 | J13: 0.53488859 | K13: 0.52031399 | L13: 0.49543866 | M13: 0.29076111 | N13: 0.55384497 | O13: 0.67771769 | P13: 0.51206104 | Q13: 0.54149297 | R13: 0.67204641 | S13: 0.51957064 | T13: 0.50753463 | U13: 0.43011923 | V13: 0.41227883 | W13: 0.40869339 | X13: 0.014599843 | Y13: 0 | Z13: 0.3798908 | AA13: 0.57945562 | AB13: 0.29553765 | AC13: 0.41829469 | AD13: 0.34320276
A14: 1010 - CX24 LA 1010 AM | B14: 0.039610514 | C14: 0.034203814 | D14: 0.020942757 | E14: 0 | F14: 0.0054067 | G14: 0.1304468 | H14: 0.1693072 | I14: 0.2204376 | J14: 0.34289986 | K14: 0.27084091 | L14: 0.26450304 | M14: 0.2203558 | N14: 0.32940587 | O14: 0.33240379 | P14: 0.29453617 | Q14: 0.35514573 | R14: 0.26574329 | S14: 0.18245304 | T14: 0.54669749 | U14: 0.32930153 | V14: 0.20716204 | W14: 0.1201579 | X14: 0.094994843 | Y14: 0.051457943 | Z14: 0.2480574 | AA14: 0.29328131 | AB14: 0.22496196 | AC14: 0.25543356 | AD14: 0.20118394
A15: 1050 - CX26 RADIO URUGUAY | B15: 0.0054067 | C15: 0 | D15: 0.0054067 | E15: 0.0054067 | F15: 0 | G15: 0.0054067 | H15: 0.024831271 | I15: 0.13975037 | J15: 0.13083437 | K15: 0.33714001 | L15: 0.30862406 | M15: 0.27460501 | N15: 0.34367633 | O15: 0.33017317 | P15: 0.14562421 | Q15: 0.10905674 | R15: 0.26792329 | S15: 0.0686763 | T15: 0.21553237 | U15: 0.0648523 | V15: 0.0648523 | W15: 0.22031727 | X15: 0.0217384 | Y15: 0.0271451 | Z15: 0.20263085 | AA15: 0.21085501 | AB15: 0.10240629 | AC15: 0.17196405 | AD15: 0.12987415
... A30: RATING GENERAL | B30: 5.6535428 | C30: 3.3685129 | D30: 2.4218017 | E30: 1.9863806 | F30: 2.4155625 | G30: 5.3462021 | H30: 12.358245 | I30: 27.496069 | J30: 38.909144 | K30: 49.462982 | L30: 51.520483 | M30: 48.775993 | N30: 41.716553 | O30: 40.582706 | P30: 39.964631 | Q30: 41.300594 | R30: 38.981896 | S30: 35.365789 | T30: 29.692637 | U30: 21.983294 | V30: 15.362035 | W30: 12.537774 | X30: 6.955042 | Y30: 4.8422061 | Z30: 38.087153 | AA30: 39.652028 | AB30: 15.228831 | AC30: 30.989337 | AD30: 24.125003
A32: CUADRO 4: RESUMEN DE RATING POR HORA | FM | LUNES A DOMINGO
A33: RADIOS | B33: HORAS | Z33: PROMEDIO
B34: 00:00 - 00:59 | C34: 01:00 - 01:59 | D34: 02:00 - 02:59 | E34: 03:00 - 03:59 | F34: 04:00 - 04:59 | G34: 05:00 - 05:59 | H34: 06:00 - 06:59 | I34: 07:00 - 07:59 | J34: 08:00 - 08:59 | K34: 09:00 - 09:59 | L34: 10:00 - 10:59 | M34: 11:00 - 11:59 | N34: 12:00 - 12:59 | O34: 13:00 - 13:59 | P34: 14:00 - 14:59 | Q34: 15:00 - 15:59 | R34: 16:00 - 16:59 | S34: 17:00 - 17:59 | T34: 18:00 - 18:59 | U34: 19:00 - 19:59 | V34: 20:00 - 20:59 | W34: 21:00 - 21:59 | X34: 22:00 - 22:59 | Y34: 23:00 - 23:59 | Z34: 06:00 - 11:59 | AA34: 12:00 - 17:59 | AB34: 18:00 - 23:59 | AC34: 06:00 - 23:59 | AD34: 00:00 - 24:00
A35: 88.3 - LACOSTA | B35: 0.062241686 | C35: 0.062241686 | D35: 0.062241686 | E35: 0.062241686 | F35: 0.10289311 | G35: 0.062241686 | H35: 0.060108257 | I35: 0.1572832 | J35: 0.38439893 | K35: 0.34074339 | L35: 0.25535891 | M35: 0.25729466 | N35: 0.20669651 | O35: 0.16355496 | P35: 0.30531877 | Q35: 0.18572233 | R35: 0.3382728 | S35: 0.38320137 | T35: 0.5096922 | U35: 0.30273291 | V35: 0.18830556 | W35: 0.11838131 | X35: 0.18388656 | Y35: 0.012672457 | Z35: 0.24253122 | AA35: 0.26379446 | AB35: 0.2192785 | AC35: 0.24186806 | AD35: 0.19865528
A36: 90.3 - FM HIT (OLDIES) | B36: 0.145382 | C36: 0.045503771 | D36: 0.045503771 | E36: 0.045503771 | F36: 0.14412949 | G36: 0.23492443 | H36: 0.22627207 | I36: 0.52013184 | J36: 0.6392458 | K36: 0.9758654 | L36: 1.1407295 | M36: 0.91067847 | N36: 0.79790076 | O36: 0.85681786 | P36: 1.1381235 | Q36: 0.8893879 | R36: 0.70633579 | S36: 0.58087084 | T36: 0.41759524 | U36: 0.32647141 | V36: 0.26072953 | W36: 0.24168303 | X36: 0.20826967 | Y36: 0.082640229 | Z36: 0.73548718 | AA36: 0.82823945 | AB36: 0.25623152 | AC36: 0.60665271 | AD36: 0.482529
A37: 91.1 - RADIO FUTURA | B37: 0 | C37: 0.013537457 | D37: 0.013537457 | E37: 0.013537457 | F37: 0.013537457 | G37: 0.0806207 | H37: 0.27233607 | I37: 0.58749829 | J37: 0.6091594 | K37: 0.90591536 | L37: 1.4446072 | M37: 1.412574 | N37: 1.288192 | O37: 1.3006649 | P37: 1.3298006 | Q37: 1.2398659 | R37: 1.16351 | S37: 1.0501229 | T37: 0.96611661 | U37: 1.189499 | V37: 1.1254676 | W37: 0.63369899 | X37: 0.21033676 | Y37: 0.1724742 | Z37: 0.87201504 | AA37: 1.2286927 | AB37: 0.71626553 | AC37: 0.93899109 | AD37: 0.70985876
A38: 91.9 - FM LIKE | B38: 0.0152506 | C38: 0.0152506 | D38: 0.0152506 | E38: 0.0098439 | F38: 0 | G38: 0 | H38: 0.1061115 | I38: 0.1071117 | J38: 0.9008104 | K38: 1.4062046 | L38: 2.0001769 | M38: 2.0486927 | N38: 2.056811 | O38: 2.0345458 | P38: 1.6616564 | Q38: 1.5847768 | R38: 1.7312388 | S38: 1.8084459 | T38: 1.5413471 | U38: 0.69570931 | V38: 0.44796431 | W38: 0.42466261 | X38: 0.23137394 | Y38: 0.0054067 | Z38: 1.0948513 | AA38: 1.8129124 | AB38: 0.557744 | AC38: 1.1551692 | AD38: 0.86869342
A39: 92.5 - URBANA FM | B39: 0.019426271 | C39: 0 | D39: 0 | E39: 0 | F39: 0 | G39: 0 | H39: 0.021969929 | I39: 0.13217606 | J39: 0.61101991 | K39: 0.82727119 | L39: 0.93882423 | M39: 1.0508085 | N39: 1.0259614 | O39: 0.9080357 | P39: 0.64549543 | Q39: 0.44514756 | R39: 0.91615059 | S39: 0.8787572 | T39: 0.54344986 | U39: 0.34695897 | V39: 0.083857829 | W39: 0.037542814 | X39: 0.0663284 | Y39: 0.0054067 | Z39: 0.59701164 | AA39: 0.80325799 | AB39: 0.18059076 | AC39: 0.52695346 | AD39: 0.39602452
A40: 93.1 - INOLVIDABLE | B40: 0.2040325 | C40: 0.17663443 | D40: 0.048706429 | E40: 0.061692214 | F40: 0.28943517 | G40: 0.059660529 | H40: 0.26105954 | I40: 0.94215429 | J40: 1.6086779 | K40: 2.4291449 | L40: 2.9877663 | M40: 3.2252883 | N40: 2.9271313 | O40: 3.0943848 | P40: 3.4872696 | Q40: 3.4691202 | R40: 3.466334 | S40: 2.8782398 | T40: 2.2830739 | U40: 1.6466966 | V40: 1.3441264 | W40: 0.99881006 | X40: 0.36308851 | Y40: 0.22829521 | Z40: 1.9090152 | AA40: 3.2204133 | AB40: 1.1440151 | AC40: 2.0911479 | AD40: 1.6033676
A41: 93.9 - OCEANO | B41: 0.0449005 | C41: 0.011122014 | D41: 0 | E41: 0.0054067 | F41: 0.0909757 | G41: 0.0909757 | H41: 0.12182954 | I41: 0.29885621 | J41: 0.88327177 | K41: 0.96418926 | L41: 1.141835 | M41: 1.2766835 | N41: 0.98780953 | O41: 1.1859847 | P41: 1.2284057 | Q41: 1.2841883 | R41: 0.99837979 | S41: 0.77040834 | T41: 0.55359833 | U41: 0.4635818 | V41: 0.10876307 | W41: 0.083272343 | X41: 0.0058029857 | Y41: 0.037028143 | Z41: 0.78111088 | AA41: 1.0758627 | AB41: 0.20867445 | AC41: 0.68854935 | AD41: 0.52655287
A42: 94.7 - DEL SUR | B42: 0.059399271 | C42: 0 | D42: 0 | E42: 0 | F42: 0 | G42: 0.10889319 | H42: 0.1578995 | I42: 0.1456427 | J42: 0.16483663 | K42: 0.1303109 | L42: 0.074070857 | M42: 0.091781357 | N42: 0.15749666 | O42: 0.069149014 | P42: 0.12662971 | Q42: 0.19330564 | R42: 0.089345486 | S42: 0.10265536 | T42: 0.14224186 | U42: 0.083481286 | V42: 0.15015586 | W42: 0.095611029 | X42: 0.10090784 | Y42: 0.1784629 | Z42: 0.12742366 | AA42: 0.12309698 | AB42: 0.12514346 | AC42: 0.12522137 | AD42: 0.10092821
A43: 95.5 - DEL PLATA | B43: 0.24270929 | C43: 0.031483986 | D43: 0.031483986 | E43: 0.070926571 | F43: 0.070926571 | G43: 0.16819397 | H43: 0.30385707 | I43: 0.59970919 | J43: 1.2416624 | K43: 1.9340582 | L43: 2.5998131 | M43: 2.44156 | N43: 2.5115356 | O43: 2.4702414 | P43: 2.5735728 | Q43: 2.4657151 | R43: 1.8782398 | S43: 1.8562123 | T43: 1.7110374 | U43: 1.6401121 | V43: 1.1795881 | W43: 0.78968811 | X43: 0.36377427 | Y43: 0.1339005 | Z43: 1.52011 | AA43: 2.2925862 | AB43: 0.9696834 | AC43: 1.5941265 | AD43: 1.2212501
A44: 96.3 - ALFA | B44: 0.0054067 | C44: 0 | D44: 0 | E44: 0 | F44: 0 | G44: 0 | H44: 0 | I44: 0.0054067 | J44: 0.069972571 | K44: 0.13991123 | L44: 0.17871261 | M44: 0.2484214 | N44: 0.31386883 | O44: 0.19735631 | P44: 0.16499243 | Q44: 0.14450883 | R44: 0.133768 | S44: 0.17710593 | T44: 0.12776389 | U44: 0.0339308 | V44: 0.099721414 | W44: 0.019981086 | X44: 0.025387786 | Y44: 0 | Z44: 0.10707075 | AA44: 0.18860005 | AB44: 0.051130829 | AC44: 0.11560055 | AD44: 0.086925688
A45: 97.1 - BABEL | B45: 0.1168533 | C45: 0.074369629 | D45: 0.062429071 | E45: 0.051195014 | F45: 0.051195014 | G45: 0.093708886 | H45: 0.1622793 | I45: 0.45018229 | J45: 0.5235941 | K45: 0.85530269 | L45: 0.87111809 | M45: 0.74359074 | N45: 0.76338037 | O45: 0.79369981 | P45: 0.58307461 | Q45: 0.44174553 | R45: 0.38492361 | S45: 0.35876937 | T45: 0.34058044 | U45: 0.43087744 | V45: 0.40213059 | W45: 0.1996264 | X45: 0.11582261 | Y45: 0.1660014 | Z45: 0.6010112 | AA45: 0.55426555 | AB45: 0.27583981 | AC45: 0.47703886 | AD45: 0.37651876
A46: 97.9 - M24 | B46: 0.058924929 | C46: 0.0267243 | D46: 0.084674671 | E46: 0.0054067 | F46: 0.028302886 | G46: 0.0859161 | H46: 0.33609307 | I46: 1.0665773 | J46: 1.2551197 | K46: 1.3822677 | L46: 1.2904569 | M46: 1.1810641 | N46: 0.95487864 | O46: 0.67411966 | P46: 0.6087781 | Q46: 0.71689769 | R46: 0.62642009 | S46: 0.3801224 | T46: 0.27419429 | U46: 0.19019271 | V46: 0.048832029 | W46: 0.14057481 | X46: 0.14116729 | Y46: 0.11225401 | Z46: 1.0852631 | AA46: 0.66020276 | AB46: 0.15120252 | AC46: 0.63222281 | AD46: 0.48624834
... A62: RATING GENERAL | B62: 5.6535428 | C62: 3.3685129 | D62: 2.4218017 | E62: 1.9863806 | F62: 2.4155625 | G62: 5.3462021 | H62: 12.358245 | I62: 27.496069 | J62: 38.909144 | K62: 49.462982 | L62: 51.520483 | M62: 48.775993 | N62: 41.716553 | O62: 40.582706 | P62: 39.964631 | Q62: 41.300594 | R62: 38.981896 | S62: 35.365789 | T62: 29.692637 | U62: 21.983294 | V62: 15.362035 | W62: 12.537774 | X62: 6.955042 | Y62: 4.8422061 | Z62: 38.087153 | AA62: 39.652028 | AB62: 15.228831 | AC62: 30.989337 | AD62: 24.125003

Sheet RatxHoraxLV
A1: CUADRO 5: RESUMEN DE RATING POR HORA | AM | LUNES A VIERNES
A2: OTRAS AM | B2: HORAS | Z2: PROMEDIO
B3: 00:00 - 00:59 | C3: 01:00 - 01:59 | D3: 02:00 - 02:59 | E3: 03:00 - 03:59 | F3: 04:00 - 04:59 | G3: 05:00 - 05:59 | H3: 06:00 - 06:59 | I3: 07:00 - 07:59 | J3: 08:00 - 08:59 | K3: 09:00 - 09:59 | L3: 10:00 - 10:59 | M3: 11:00 - 11:59 | N3: 12:00 - 12:59 | O3: 13:00 - 13:59 | P3: 14:00 - 14:59 | Q3: 15:00 - 15:59 | R3: 16:00 - 16:59 | S3: 17:00 - 17:59 | T3: 18:00 - 18:59 | U3: 19:00 - 19:59 | V3: 20:00 - 20:59 | W3: 21:00 - 21:59 | X3: 22:00 - 22:59 | Y3: 23:00 - 23:59 | Z3: 06:00 - 11:59 | AA3: 12:00 - 17:59 | AB3: 18:00 - 23:59 | AC3: 06:00 - 23:59 | AD3: 00:00 - 24:00
A4: 610 - CX4 RURAL | B4: 0.26032138 | C4: 0.25934646 | D4: 0.25122228 | E4: 0 | F4: 0.03546322 | G4: 0.06158172 | H4: 0.16219232 | I4: 0.46016862 | J4: 0.59680682 | K4: 0.59095986 | L4: 0.42901554 | M4: 0.37549076 | N4: 0.24301494 | O4: 0.37337242 | P4: 0.35184664 | Q4: 0.35184664 | R4: 0.22257516 | S4: 0.22257516 | T4: 0.22257516 | U4: 0.26022498 | V4: 0.2438582 | W4: 0.39132046 | X4: 0.32680972 | Y4: 0.1687453 | Z4: 0.43577232 | AA4: 0.29420516 | AB4: 0.2689223 | AC4: 0.33296659 | AD4: 0.28588891
A5: 650 - CX6 CLÁSICA | B5: 0.032099 | C5: 0.02347688 | D5: 0.05121556 | E5: 0.02206964 | F5: 0 | G5: 0 | H5: 0.02980754 | I5: 0.03493718 | J5: 0.03493718 | K5: 0 | L5: 0 | M5: 0 | N5: 0 | O5: 0 | P5: 0 | Q5: 0 | R5: 0.00756938 | S5: 0.03493718 | T5: 0 | U5: 0 | V5: 0 | W5: 0 | X5: 0.02798796 | Y5: 0.02798796 | Z5: 0.01661365 | AA5: 0.0070844267 | AB5: 0.00932932 | AC5: 0.011009132 | AD5: 0.013626061
A6: 690 - CX8 SARANDI | B6: 0.04124218 | C6: 0 | D6: 0.00552532 | E6: 0 | F6: 0.07433278 | G6: 0.70290512 | H6: 2.8058768 | I6: 4.120024 | J6: 3.5917913 | K6: 3.664432 | L6: 2.6492353 | M6: 2.2599885 | N6: 1.065446 | O6: 0.56799684 | P6: 0.79641574 | Q6: 0.45703036 | R6: 0.22314982 | S6: 0.22768558 | T6: 0.44235276 | U6: 0.38317408 | V6: 0.06762834 | W6: 0.11560054 | X6: 0.24054844 | Y6: 0.15866112 | Z6: 3.1818913 | AA6: 0.55628739 | AB6: 0.23466088 | AC6: 1.3242799 | AD6: 1.0275435
A7: 730 - CX10 CONTINENTE | B7: 0.1359811 | C7: 0.12841172 | D7: 0.1359811 | E7: 0.08315288 | F7: 0 | G7: 0 | H7: 0.0557668 | I7: 0.0994528 | J7: 0.0994528 | K7: 0.03611662 | L7: 0.04693652 | M7: 0.04693652 | N7: 0.04693652 | O7: 0.06207528 | P7: 0 | Q7: 0 | R7: 0.0557668 | S7: 0.06333618 | T7: 0.06333618 | U7: 0.08550712 | V7: 0.08550712 | W7: 0.06333618 | X7: 0 | Y7: 0.00756938 | Z7: 0.064110343 | AA7: 0.03801913 | AB7: 0.050875997 | AC7: 0.051001823 | AD7: 0.058398318
A8: 770 - CX12 ORIENTAL | B8: 0.07985136 | C8: 0.0163635 | D8: 0.0163635 | E8: 0 | F8: 0 | G8: 0.1096489 | H8: 0.07270982 | I8: 0.45760838 | J8: 0.49103708 | K8: 0.1747977 | L8: 0.5258517 | M8: 0.30428642 | N8: 0.3349124 | O8: 0.22104662 | P8: 0.18502182 | Q8: 0.379239 | R8: 0.2426523 | S8: 0.2430528 | T8: 0.06392858 | U8: 0.0436737 | V8: 0.02186912 | W8: 0.2615786 | X8: 0.2314716 | Y8: 0.0710966 | Z8: 0.33771518 | AA8: 0.26765416 | AB8: 0.11560303 | AC8: 0.24032412 | AD8: 0.18950256
A9: 810 - CX14 EL ESPECTADOR | B9: 0.30470892 | C9: 0.28800648 | D9: 0.02078728 | E9: 0.0753662 | F9: 0 | G9: 0.02931986 | H9: 0.06372498 | I9: 0.73142836 | J9: 0.93395996 | K9: 0.9284327 | L9: 0.85954864 | M9: 0.78926342 | N9: 0.72906696 | O9: 0.98666982 | P9: 1.2836839 | Q9: 1.3391785 | R9: 0.80817652 | S9: 0.48207182 | T9: 0.23580582 | U9: 0.14752094 | V9: 0.00756938 | W9: 0.14729418 | X9: 0.08044456 | Y9: 0.17077826 | Z9: 0.71772634 | AA9: 0.93814125 | AB9: 0.13156886 | AC9: 0.59581215 | AD9: 0.47678364
A10: 850 - CX16 CARVE | B10: 0.41780022 | C10: 0.37891624 | D10: 0.35710854 | E10: 0.18420806 | F10: 0.13309544 | G10: 0.38742698 | H10: 1.0736764 | I10: 1.9883857 | J10: 1.0378568 | K10: 0.64615748 | L10: 0.40037506 | M10: 0.3858524 | N10: 0.21802822 | O10: 0.38233292 | P10: 0.41630158 | Q10: 0.33686224 | R10: 0.25389064 | S10: 0.16927208 | T10: 0.06601016 | U10: 0.1300825 | V10: 0.18513366 | W10: 0.46052432 | X10: 0.48380072 | Y10: 0.53022526 | Z10: 0.92205065 | AA10: 0.29611461 | AB10: 0.3092961 | AC10: 0.50915379 | AD10: 0.45930515
A11: 890 - CX18 SPORT 890 | B11: 0.02446834 | C11: 0 | D11: 0.04448056 | E11: 0.05623234 | F11: 0.03949592 | G11: 0.149642 | H11: 0.3055098 | I11: 1.3896703 | J11: 2.2452882 | K11: 1.9621891 | L11: 1.9010509 | M11: 1.5306359 | N11: 1.0856715 | O11: 1.3966618 | P11: 1.3251976 | Q11: 1.2517766 | R11: 1.1598708 | S11: 1.0294235 | T11: 0.82295438 | U11: 0.75272878 | V11: 0.48159654 | W11: 0.50138966 | X11: 0.38540758 | Y11: 0.18205268 | Z11: 1.555724 | AA11: 1.2081003 | AB11: 0.5210216 | AC11: 1.0949487 | AD11: 0.83430812
A12: 930 - CX20 MONTECARLO | B12: 0.45491818 | C12: 0.32213212 | D12: 0.1411815 | E12: 0.11155226 | F12: 0.1476301 | G12: 0.68339014 | H12: 1.6381368 | I12: 2.75892 | J12: 3.7741956 | K12: 5.0546986 | L12: 4.7002941 | M12: 4.4447875 | N12: 3.7112397 | O12: 3.6201714 | P12: 2.2113536 | Q12: 1.6693247 | R12: 1.601841 | S12: 1.6490712 | T12: 1.6944681 | U12: 1.4326354 | V12: 1.0957484 | W12: 0.87515826 | X12: 0.38557014 | Y12: 0.3237112 | Z12: 3.7285054 | AA12: 2.4105003 | AB12: 0.96788192 | AC12: 2.3689625 | AD12: 1.8542554
A13: 970 - CX22 UNIVERSAL | B13: 0.52529034 | C13: 0.05661432 | D13: 0 | E13: 0.034902 | F13: 0.0445578 | G13: 0.07153914 | H13: 0.1465909 | I13: 0.39143886 | J13: 0.50358948 | K13: 0.47799546 | L13: 0.46631586 | M13: 0.2661624 | N13: 0.4903612 | O13: 0.68085682 | P13: 0.41696838 | Q13: 0.5135799 | R13: 0.62158162 | S13: 0.44842982 | T13: 0.43754056 | U13: 0.38582482 | V13: 0.38582482 | W13: 0.4062646 | X13: 0.02043978 | Y13: 0 | Z13: 0.37534883 | AA13: 0.52862962 | AB13: 0.2726491 | AC13: 0.39220918 | AD13: 0.32469454
A14: 1010 - CX24 LA 1010 AM | B14: 0.05545472 | C14: 0.04788534 | D14: 0.02931986 | E14: 0 | F14: 0.00756938 | G14: 0.18262552 | H14: 0.23703008 | I14: 0.25235946 | J14: 0.3425624 | K14: 0.23101834 | L14: 0.22214532 | M14: 0.22214532 | N14: 0.30212726 | O14: 0.2686152 | P14: 0.30647696 | Q14: 0.23060532 | R14: 0.30937784 | S14: 0.20134168 | T14: 0.55658668 | U14: 0.34209534 | V14: 0.25288748 | W14: 0.16822106 | X14: 0.13299278 | Y14: 0.04479148 | Z14: 0.25121015 | AA14: 0.26975738 | AB14: 0.2495958 | AC14: 0.25685444 | AD14: 0.20609312
A15: 1050 - CX26 RADIO URUGUAY | B15: 0.00756938 | C15: 0 | D15: 0 | E15: 0.00756938 | F15: 0 | G15: 0.00756938 | H15: 0.03476378 | I15: 0.11897612 | J15: 0.09892434 | K15: 0.35156484 | L15: 0.30183796 | M15: 0.28683298 | N15: 0.4431863 | O15: 0.40669424 | P15: 0.13981272 | Q15: 0.10292544 | R15: 0.35666594 | S15: 0.08031796 | T15: 0.2809261 | U15: 0.09079322 | V15: 0.09079322 | W15: 0.3008748 | X15: 0.03043376 | Y15: 0.03800314 | Z15: 0.19881667 | AA15: 0.25493377 | AB15: 0.13863737 | AC15: 0.1974626 | AD15: 0.14904312
... A30: RATING GENERAL | B30: 6.5224872 | C30: 3.6984753 | D30: 2.6883593 | E30: 2.1243633 | F30: 2.6296125 | G30: 5.8757107 | H30: 13.38183 | I30: 29.637463 | J30: 41.004843 | K30: 52.788059 | L30: 54.729971 | M30: 51.173902 | N30: 43.480945 | O30: 42.387044 | P30: 42.032571 | Q30: 43.497355 | R30: 40.692364 | S30: 37.29531 | T30: 30.849587 | U30: 22.974351 | V30: 15.910853 | W30: 12.969102 | X30: 7.1410512 | Y30: 5.0519012 | Z30: 40.452678 | AA30: 41.564265 | AB30: 15.816141 | AC30: 32.611028 | AD30: 25.439063
A32: CUADRO 6: RESUMEN DE RATING POR HORA | FM | LUNES A VIERNES
A33: RADIOS | B33: HORAS | Z33: PROMEDIO
B34: 00:00 - 00:59 | C34: 01:00 - 01:59 | D34: 02:00 - 02:59 | E34: 03:00 - 03:59 | F34: 04:00 - 04:59 | G34: 05:00 - 05:59 | H34: 06:00 - 06:59 | I34: 07:00 - 07:59 | J34: 08:00 - 08:59 | K34: 09:00 - 09:59 | L34: 10:00 - 10:59 | M34: 11:00 - 11:59 | N34: 12:00 - 12:59 | O34: 13:00 - 13:59 | P34: 14:00 - 14:59 | Q34: 15:00 - 15:59 | R34: 16:00 - 16:59 | S34: 17:00 - 17:59 | T34: 18:00 - 18:59 | U34: 19:00 - 19:59 | V34: 20:00 - 20:59 | W34: 21:00 - 21:59 | X34: 22:00 - 22:59 | Y34: 23:00 - 23:59 | Z34: 06:00 - 11:59 | AA34: 12:00 - 17:59 | AB34: 18:00 - 23:59 | AC34: 06:00 - 23:59 | AD34: 00:00 - 24:00
A35: 88.3 - LACOSTA | B35: 0.08713836 | C35: 0.08713836 | D35: 0.08713836 | E35: 0.08713836 | F35: 0.13266796 | G35: 0.08713836 | H35: 0.05179018 | I35: 0.15816036 | J35: 0.2860109 | K35: 0.34172364 | L35: 0.2159532 | M35: 0.21538486 | N35: 0.2608917 | O35: 0.18294448 | P35: 0.15266202 | Q35: 0.21101534 | R35: 0.32242002 | S35: 0.3568366 | T35: 0.41589024 | U35: 0.32348096 | V35: 0.1910288 | W35: 0.06315348 | X35: 0.05227044 | Y35: 0.01774144 | Z35: 0.21150386 | AA35: 0.24779503 | AB35: 0.17726089 | AC35: 0.21218659 | AD35: 0.1828216
A36: 90.3 - FM HIT (OLDIES) | B36: 0.12789394 | C36: 0.06370528 | D36: 0.06370528 | E36: 0.06370528 | F36: 0.18770526 | G36: 0.26157352 | H36: 0.24946022 | I36: 0.54954472 | J36: 0.6935017 | K36: 1.0149384 | L36: 1.2435486 | M36: 0.94885766 | N36: 0.87458576 | O36: 0.8898348 | P36: 1.0920177 | Q36: 0.8068557 | R36: 0.64985074 | S36: 0.61220116 | T36: 0.48474756 | U36: 0.31021498 | V36: 0.29109638 | W36: 0.21444028 | X36: 0.19778464 | Y36: 0.10418416 | Z36: 0.78330855 | AA36: 0.82089098 | AB36: 0.267078 | AC36: 0.62375918 | AD36: 0.49983141
A37: 91.1 - RADIO FUTURA | B37: 0 | C37: 0.01895244 | D37: 0.01895244 | E37: 0.01895244 | F37: 0.01895244 | G37: 0.05388044 | H37: 0.19986926 | I37: 0.64890492 | J37: 0.73416426 | K37: 0.95460802 | L37: 1.5417129 | M37: 1.4145501 | N37: 1.2782958 | O37: 1.2741501 | P37: 1.3636849 | Q37: 1.2422691 | R37: 1.1453665 | S37: 0.86034638 | T37: 0.92038502 | U37: 1.3538634 | V37: 1.2494077 | W37: 0.66857974 | X37: 0.23422666 | Y37: 0.18121908 | Z37: 0.9156349 | AA37: 1.1940188 | AB37: 0.76794692 | AC37: 0.9592002 | AD37: 0.72480391
A38: 91.9 - FM LIKE | B38: 0.00756938 | C38: 0.00756938 | D38: 0.00756938 | E38: 0 | F38: 0 | G38: 0 | H38: 0.09844954 | I38: 0.09984982 | J38: 0.85027196 | K38: 1.5418017 | L38: 2.0958146 | M38: 2.1489772 | N38: 2.1644751 | O38: 2.1664076 | P38: 1.8554766 | Q38: 1.7851631 | R38: 1.7733644 | S38: 1.8885344 | T38: 1.5499022 | U38: 0.6705065 | V38: 0.46977116 | W38: 0.44984886 | X38: 0.28345152 | Y38: 0.00756938 | Z38: 1.1391941 | AA38: 1.9389035 | AB38: 0.5718416 | AC38: 1.2166464 | AD38: 0.91343099
A39: 92.5 - URBANA FM | B39: 0.02719678 | C39: 0 | D39: 0 | E39: 0 | F39: 0 | G39: 0 | H39: 0.0307579 | I39: 0.1640727 | J39: 0.66715526 | K39: 0.9083883 | L39: 1.0385376 | M39: 1.0469484 | N39: 1.0041476 | O39: 0.93602928 | P39: 0.6521008 | Q39: 0.4323602 | R39: 0.9401156 | S39: 0.936614 | T39: 0.63761002 | U39: 0.46219504 | V39: 0.11740096 | W39: 0.05255994 | X39: 0.05255994 | Y39: 0.00756938 | Z39: 0.64264337 | AA39: 0.81689458 | AB39: 0.22164921 | AC39: 0.56039572 | AD39: 0.42142999
A40: 93.1 - INOLVIDABLE | B40: 0.23211522 | C40: 0.18350588 | D40: 0.04019026 | E40: 0.04062366 | F40: 0.2479977 | G40: 0.03411524 | H40: 0.20751448 | I40: 0.94104566 | J40: 1.5926345 | K40: 2.4485 | L40: 3.0499471 | M40: 3.1136519 | N40: 2.902569 | O40: 3.19734 | P40: 3.6875706 | Q40: 3.3412045 | R40: 3.4094553 | S40: 2.907994 | T40: 2.0675949 | U40: 1.5475758 | V40: 1.4083899 | W40: 1.1368812 | X40: 0.31472004 | Y40: 0.22526088 | Z40: 1.8922156 | AA40: 3.2410222 | AB40: 1.1167371 | AC40: 2.083325 | AD40: 1.5949332
A41: 93.9 - OCEANO | B41: 0.0628607 | C41: 0.01557082 | D41: 0 | E41: 0 | F41: 0.10801188 | G41: 0.10801188 | H41: 0.10981462 | I41: 0.2871145 | J41: 0.94631938 | K41: 1.0224664 | L41: 1.0949465 | M41: 1.2493617 | N41: 0.8993039 | O41: 1.1909304 | P41: 1.3299757 | Q41: 1.4621321 | R41: 1.0426748 | S41: 0.78690084 | T41: 0.55687944 | U41: 0.40575544 | V41: 0.05509756 | W41: 0.1021726 | X41: 0 | Y41: 0.0518394 | Z41: 0.78500386 | AA41: 1.1186529 | AB41: 0.19529074 | AC41: 0.69964918 | AD41: 0.53700585
A42: 94.7 - DEL SUR | B42: 0.08315898 | C42: 0 | D42: 0 | E42: 0 | F42: 0 | G42: 0.10017534 | H42: 0.15458768 | I42: 0.13742816 | J42: 0.13745776 | K42: 0.17142058 | L42: 0.08637154 | M42: 0.08637154 | N42: 0.16189404 | O42: 0.074356 | P42: 0.11355536 | Q42: 0.2311731 | R42: 0.09810022 | S42: 0.07805334 | T42: 0.166827 | U42: 0.10440246 | V42: 0.19774686 | W42: 0.09811602 | X42: 0.10553156 | Y42: 0.16838696 | Z42: 0.12893954 | AA42: 0.12618868 | AB42: 0.14016848 | AC42: 0.13176557 | AD42: 0.1064631
A43: 95.5 - DEL PLATA | B43: 0.31671184 | C43: 0.04407758 | D43: 0.04407758 | E43: 0.04407758 | F43: 0.04407758 | G43: 0.21783266 | H43: 0.3092755 | I43: 0.68539084 | J43: 1.3996584 | K43: 2.1376061 | L43: 2.8025436 | M43: 2.5129453 | N43: 2.5950114 | O43: 2.5724029 | P43: 2.8391035 | Q43: 2.7506451 | R43: 1.9823814 | S43: 2.0135219 | T43: 1.826647 | U43: 1.9025709 | V43: 1.3940984 | W43: 0.91857436 | X43: 0.41230144 | Y43: 0.13248758 | Z43: 1.6412366 | AA43: 2.4588444 | AB43: 1.0977799 | AC43: 1.7326203 | AD43: 1.3290842
A44: 96.3 - ALFA | B44: 0 | C44: 0 | D44: 0 | E44: 0 | F44: 0 | G44: 0 | H44: 0 | I44: 0 | J44: 0.07039732 | K44: 0.16831144 | L44: 0.179441 | M44: 0.24733542 | N44: 0.32289092 | O44: 0.20296578 | P44: 0.15752306 | Q44: 0.15517378 | R44: 0.13417546 | S44: 0.16606518 | T44: 0.14251668 | U44: 0.0371785 | V44: 0.13960998 | W44: 0.02797352 | X44: 0.02797352 | Y44: 0 | Z44: 0.1109142 | AA44: 0.18979903 | AB44: 0.062542033 | AC44: 0.12108509 | AD44: 0.090813815
A45: 97.1 - BABEL | B45: 0.16359462 | C45: 0.10411748 | D45: 0.0874007 | E45: 0.07167302 | F45: 0.07167302 | G45: 0.13119244 | H45: 0.21299452 | I45: 0.54099706 | J45: 0.63564942 | K45: 0.93862034 | L45: 0.91492244 | M45: 0.75053312 | N45: 0.79734016 | O45: 0.86153134 | P45: 0.65696136 | Q45: 0.45711198 | R45: 0.40807164 | S45: 0.40100504 | T45: 0.3040562 | U45: 0.36067588 | V45: 0.29263962 | W45: 0.14392204 | X45: 0.0724997 | Y45: 0.1625023 | Z45: 0.66561948 | AA45: 0.59700359 | AB45: 0.22271596 | AC45: 0.49511301 | AD45: 0.39757023
A46: 97.9 - M24 | B46: 0.07002356 | C46: 0.02494268 | D46: 0.1060732 | E46: 0.00756938 | F46: 0.03962404 | G46: 0.07639532 | H46: 0.34736026 | I46: 1.1469634 | J46: 1.197229 | K46: 1.4237258 | L46: 1.313851 | M46: 1.1909766 | N46: 0.99415448 | O46: 0.75121212 | P46: 0.64703978 | Q46: 0.78155368 | R46: 0.68238014 | S46: 0.43529926 | T46: 0.26886256 | U46: 0.18491374 | V46: 0.04420278 | W46: 0.1840524 | X46: 0.18488186 | Y46: 0.12547206 | Z46: 1.103351 | AA46: 0.71527324 | AB46: 0.16539757 | AC46: 0.66134061 | AD46: 0.50953163
... A62: RATING GENERAL | B62: 6.5224872 | C62: 3.6984753 | D62: 2.6883593 | E62: 2.1243633 | F62: 2.6296125 | G62: 5.8757107 | H62: 13.38183 | I62: 29.637463 | J62: 41.004843 | K62: 52.788059 | L62: 54.729971 | M62: 51.173902 | N62: 43.480945 | O62: 42.387044 | P62: 42.032571 | Q62: 43.497355 | R62: 40.692364 | S62: 37.29531 | T62: 30.849587 | U62: 22.974351 | V62: 15.910853 | W62: 12.969102 | X62: 7.1410512 | Y62: 5.0519012 | Z62: 40.452678 | AA62: 41.564265 | AB62: 15.816141 | AC62: 32.611028 | AD62: 25.439063

Sheet RatxHoraxSD
A1: CUADRO 7: RESUMEN DE RATING POR HORA | AM | SABADO A DOMINGO
A2: RADIOS | B2: HORAS | Z2: PROMEDIO
B3: 00:00 - 00:59 | C3: 01:00 - 01:59 | D3: 02:00 - 02:59 | E3: 03:00 - 03:59 | F3: 04:00 - 04:59 | G3: 05:00 - 05:59 | H3: 06:00 - 06:59 | I3: 07:00 - 07:59 | J3: 08:00 - 08:59 | K3: 09:00 - 09:59 | L3: 10:00 - 10:59 | M3: 11:00 - 11:59 | N3: 12:00 - 12:59 | O3: 13:00 - 13:59 | P3: 14:00 - 14:59 | Q3: 15:00 - 15:59 | R3: 16:00 - 16:59 | S3: 17:00 - 17:59 | T3: 18:00 - 18:59 | U3: 19:00 - 19:59 | V3: 20:00 - 20:59 | W3: 21:00 - 21:59 | X3: 22:00 - 22:59 | Y3: 23:00 - 23:59 | Z3: 06:00 - 11:59 | AA3: 12:00 - 17:59 | AB3: 18:00 - 23:59 | AC3: 06:00 - 23:59 | AD3: 00:00 - 24:00
A4: 610 - CX4 RURAL | B4: 0.07867925 | C4: 0.2684467 | D4: 0.13337065 | E4: 0 | F4: 0 | G4: 0.1021989 | H4: 0.33287175 | I4: 0.4154933 | J4: 0.50296145 | K4: 0.3450414 | L4: 0.30668725 | M4: 0.1877241 | N4: 0.1877241 | O4: 0.7189894 | P4: 0.2555878 | Q4: 0.2555878 | R4: 0.1877241 | S4: 0.1877241 | T4: 0.23882355 | U4: 0.1877241 | V4: 0.3005027 | W4: 0.56451015 | X4: 0.24260895 | Y4: 0.24260895 | Z4: 0.34846321 | AA4: 0.29888955 | AB4: 0.29612973 | AC4: 0.31449416 | AD4: 0.2601496
A5: 650 - CX6 CLÁSICA | B5: 0 | C5: 0.0640835 | D5: 0.0640835 | E5: 0 | F5: 0 | G5: 0 | H5: 0.0589231 | I5: 0.08343445 | J5: 0 | K5: 0.08733835 | L5: 0.08733835 | M5: 0.08733835 | N5: 0 | O5: 0 | P5: 0 | Q5: 0 | R5: 0 | S5: 0 | T5: 0 | U5: 0 | V5: 0 | W5: 0.02031045 | X5: 0 | Y5: 0 | Z5: 0.067395433 | AA5: 0 | AB5: 0.003385075 | AC5: 0.023593503 | AD5: 0.023035419
A6: 690 - CX8 SARANDI | B6: 0.17031605 | C6: 0.12040995 | D6: 0.0431639 | E6: 0 | F6: 0 | G6: 0.6249077 | H6: 1.8592452 | I6: 4.02969 | J6: 3.8607112 | K6: 3.8164358 | L6: 2.4241994 | M6: 1.7510537 | N6: 1.3215516 | O6: 0.52427065 | P6: 0.58724895 | Q6: 0.68260205 | R6: 0.69048235 | S6: 0.7726072 | T6: 0.4979153 | U6: 0.3892722 | V6: 0.1962767 | W6: 0.3981357 | X6: 0.3934354 | Y6: 0.29295585 | Z6: 2.9568892 | AA6: 0.76312713 | AB6: 0.36133186 | AC6: 1.3604494 | AD6: 1.0602869
A7: 730 - CX10 CONTINENTE | B7: 0 | C7: 0 | D7: 0 | E7: 0 | F7: 0 | G7: 0 | H7: 0.0278834 | I7: 0.08826175 | J7: 0.2507165 | K7: 0.1149409 | L7: 0.05456255 | M7: 0 | N7: 0 | O7: 0 | P7: 0 | Q7: 0 | R7: 0.19033815 | S7: 0.19033815 | T7: 0.0278834 | U7: 0.5591487 | V7: 0.0278834 | W7: 0.0278834 | X7: 0 | Y7: 0 | Z7: 0.089394183 | AA7: 0.06344605 | AB7: 0.10713315 | AC7: 0.086657794 | AD7: 0.064993346
A8: 770 - CX12 ORIENTAL | B8: 0 | C8: 0 | D8: 0 | E8: 0.0149029 | F8: 0.0149029 | G8: 0.0511518 | H8: 0.04838525 | I8: 0.17919245 | J8: 0.17548765 | K8: 0.0589231 | L8: 0.1396207 | M8: 0.0806976 | N8: 0.0300003 | O8: 0.03117835 | P8: 0.07566595 | Q8: 0.3149456 | R8: 0.20984305 | S8: 0.16535545 | T8: 0 | U8: 0.0298481 | V8: 0.0298481 | W8: 0.16815125 | X8: 0.13891435 | Y8: 0.0767011 | Z8: 0.11371779 | AA8: 0.13783145 | AB8: 0.073910483 | AC8: 0.10848657 | AD8: 0.084738165
A9: 810 - CX14 EL ESPECTADOR | B9: 0.24664055 | C9: 0.1519564 | D9: 0.0623878 | E9: 0.08487945 | F9: 0 | G9: 0 | H9: 0.0545784 | I9: 0.2464862 | J9: 0.54236035 | K9: 0.6552821 | L9: 0.61783855 | M9: 0.69917935 | N9: 0.45087 | O9: 0.53106785 | P9: 0.72984505 | Q9: 0.67773865 | R9: 0.43709695 | S9: 0.3199009 | T9: 0 | U9: 0.1211358 | V9: 0.11232995 | W9: 0.1223727 | X9: 0.0515736 | Y9: 0.290831 | Z9: 0.46928749 | AA9: 0.5244199 | AB9: 0.11637384 | AC9: 0.37002708 | AD9: 0.30026465
A10: 850 - CX16 CARVE | B10: 0.4133546 | C10: 0.45481455 | D10: 0.4452061 | E10: 0.31386345 | F10: 0.20108485 | G10: 0.3357344 | H10: 0.4823278 | I10: 1.0113543 | J10: 0.8580455 | K10: 0.5092 | L10: 0.35069225 | M10: 0.33459395 | N10: 0.2742427 | O10: 0.2037843 | P10: 0.4560032 | Q10: 0.42882395 | R10: 0.42882395 | S10: 0.17477815 | T10: 0.1275353 | U10: 0.1966175 | V10: 0.1966175 | W10: 0.41179955 | X10: 0.4472908 | Y10: 0.19567415 | Z10: 0.59103564 | AA10: 0.32774271 | AB10: 0.26258913 | AC10: 0.39378916 | AD10: 0.38551095
A11: 890 - CX18 SPORT 890 | B11: 0 | C11: 0.01892345 | D11: 0 | E11: 0 | F11: 0 | G11: 0.03549125 | H11: 0.05187885 | I11: 0.99970785 | J11: 1.590488 | K11: 1.3678921 | L11: 1.2763035 | M11: 1.2929112 | N11: 0.70485085 | O11: 0.81414485 | P11: 0.91492255 | Q11: 0.6472372 | R11: 0.6787719 | S11: 0.5500787 | T11: 0.5125961 | U11: 0.6162712 | V11: 0.36832025 | W11: 0.3742177 | X11: 0.1105889 | Y11: 0.0864494 | Z11: 1.0965303 | AA11: 0.71833434 | AB11: 0.34474059 | AC11: 0.7198684 | AD11: 0.54216858
A12: 930 - CX20 MONTECARLO | B12: 0.3141279 | C12: 0.0520401 | D12: 0.0520401 | E12: 0.09226855 | F12: 0.09226855 | G12: 0.65040255 | H12: 1.6125388 | I12: 2.1265396 | J12: 3.802089 | K12: 4.4774419 | L12: 4.6791531 | M12: 4.1313481 | N12: 3.0571777 | O12: 3.0297386 | P12: 2.1904582 | Q12: 1.6351319 | R12: 1.3325364 | S12: 1.2766277 | T12: 1.2923025 | U12: 1.1578119 | V12: 1.3778873 | W12: 1.0663026 | X12: 0.6101222 | Y12: 0.41782355 | Z12: 3.4715184 | AA12: 2.0869451 | AB12: 0.98704167 | AC12: 2.1818351 | AD12: 1.6885908
A13: 970 - CX22 UNIVERSAL | B13: 0.22903305 | C13: 0.070538 | D13: 0.0803324 | E13: 0.0945855 | F13: 0.1468391 | G13: 0.0228792 | H13: 0 | I13: 0.1877241 | J13: 0.61313635 | K13: 0.6261103 | L13: 0.56824565 | M13: 0.3522579 | N13: 0.7125544 | O13: 0.66986985 | P13: 0.7497927 | Q13: 0.61127565 | R13: 0.7982084 | S13: 0.6974227 | T13: 0.6825198 | U13: 0.54085525 | V13: 0.47841385 | W13: 0.41476535 | X13: 0 | Y13: 0 | Z13: 0.39124572 | AA13: 0.70652062 | AB13: 0.35275904 | AC13: 0.48350846 | AD13: 0.38947331
A14: 1010 - CX24 LA 1010 AM | B14: 0 | C14: 0 | D14: 0 | E14: 0 | F14: 0 | G14: 0 | H14: 0 | I14: 0.14063295 | J14: 0.3437435 | K14: 0.37039735 | L14: 0.37039735 | M14: 0.215882 | N14: 0.3976024 | O14: 0.49187525 | P14: 0.2646842 | Q14: 0.66649675 | R14: 0.1566569 | S14: 0.13523145 | T14: 0.5219745 | U14: 0.297317 | V14: 0.09284845 | W14: 0 | X14: 0 | Y14: 0.0681241 | Z14: 0.24017552 | AA14: 0.35209116 | AB14: 0.16337734 | AC14: 0.25188134 | AD14: 0.18891101
A15: 1050 - CX26 RADIO URUGUAY | B15: 0 | C15: 0 | D15: 0.01892345 | E15: 0 | F15: 0 | G15: 0 | H15: 0 | I15: 0.191686 | J15: 0.21060945 | K15: 0.30107795 | L15: 0.3255893 | M15: 0.2440351 | N15: 0.0949014 | O15: 0.1388705 | P15: 0.16015295 | Q15: 0.124385 | R15: 0.04606665 | S15: 0.03957215 | T15: 0.05204805 | U15: 0 | V15: 0 | W15: 0.01892345 | X15: 0 | Y15: 0 | Z15: 0.2121663 | AA15: 0.10065811 | AB15: 0.011828583 | AC15: 0.10821766 | AD15: 0.081951725
... A30: RATING GENERAL | B30: 3.4811817 | C30: 2.5436069 | D30: 1.7554076 | E30: 1.6414239 | F30: 1.8804376 | G30: 4.0224306 | H30: 9.7992848 | I30: 22.142582 | J30: 33.669897 | K30: 41.15029 | L30: 43.496763 | M30: 42.781223 | N30: 37.305573 | O30: 36.071859 | P30: 34.79478 | Q30: 35.808692 | R30: 34.705726 | S30: 30.541984 | T30: 26.800261 | U30: 19.505653 | V30: 13.98999 | W30: 11.459452 | X30: 6.4900191 | Y30: 4.3179685 | Z30: 32.17334 | AA30: 34.871435 | AB30: 13.760557 | AC30: 26.935111 | AD30: 20.839854
A32: CUADRO 8: RESUMEN DE RATING POR HORA | FM | SABADO A DOMINGO
A33: RADIOS | B33: HORAS | Z33: PROMEDIO
B34: 00:00 - 00:59 | C34: 01:00 - 01:59 | D34: 02:00 - 02:59 | E34: 03:00 - 03:59 | F34: 04:00 - 04:59 | G34: 05:00 - 05:59 | H34: 06:00 - 06:59 | I34: 07:00 - 07:59 | J34: 08:00 - 08:59 | K34: 09:00 - 09:59 | L34: 10:00 - 10:59 | M34: 11:00 - 11:59 | N34: 12:00 - 12:59 | O34: 13:00 - 13:59 | P34: 14:00 - 14:59 | Q34: 15:00 - 15:59 | R34: 16:00 - 16:59 | S34: 17:00 - 17:59 | T34: 18:00 - 18:59 | U34: 19:00 - 19:59 | V34: 20:00 - 20:59 | W34: 21:00 - 21:59 | X34: 22:00 - 22:59 | Y34: 23:00 - 23:59 | Z34: 06:00 - 11:59 | AA34: 12:00 - 17:59 | AB34: 18:00 - 23:59 | AC34: 06:00 - 23:59 | AD34: 00:00 - 24:00
A35: 88.3 - LACOSTA | B35: 0 | C35: 0 | D35: 0 | E35: 0 | F35: 0.028456 | G35: 0 | H35: 0.08090345 | I35: 0.1550903 | J35: 0.630369 | K35: 0.33829275 | L35: 0.3538732 | M35: 0.36206915 | N35: 0.07120855 | O35: 0.11508115 | P35: 0.68696065 | Q35: 0.1224898 | R35: 0.37790475 | S35: 0.4491133 | T35: 0.7441971 | U35: 0.2508628 | V35: 0.18149745 | W35: 0.2564509 | X35: 0.51292685 | Y35: 0 | Z35: 0.32009964 | AA35: 0.30379303 | AB35: 0.32432252 | AC35: 0.31607173 | AD35: 0.23823946
A36: 90.3 - FM HIT (OLDIES) | B36: 0.18910215 | C36: 0 | D36: 0 | E36: 0 | F36: 0.03519005 | G36: 0.1683017 | H36: 0.1683017 | I36: 0.44659965 | J36: 0.50360605 | K36: 0.87818295 | L36: 0.88368155 | M36: 0.8152305 | N36: 0.60618825 | O36: 0.7742755 | P36: 1.2533881 | Q36: 1.0957184 | R36: 0.8475484 | S36: 0.50254505 | T36: 0.24971445 | U36: 0.3671125 | V36: 0.1848124 | W36: 0.3097899 | X36: 0.23448225 | Y36: 0.0287804 | Z36: 0.61593373 | AA36: 0.84661062 | AB36: 0.22911532 | AC36: 0.56388656 | AD36: 0.439273
A37: 91.1 - RADIO FUTURA | B37: 0 | C37: 0 | D37: 0 | E37: 0 | F37: 0 | G37: 0.14747135 | H37: 0.4535031 | I37: 0.4339817 | J37: 0.29664725 | K37: 0.7841837 | L37: 1.201843 | M37: 1.4076337 | N37: 1.3129325 | O37: 1.3669519 | P37: 1.24509 | Q37: 1.2338577 | R37: 1.2088688 | S37: 1.5245641 | T37: 1.0804456 | U37: 0.7785881 | V37: 0.81561745 | W37: 0.5464971 | X37: 0.150612 | Y37: 0.150612 | Z37: 0.76296541 | AA37: 1.3153775 | AB37: 0.58706204 | AC37: 0.88846832 | AD37: 0.67249588
A38: 91.9 - FM LIKE | B38: 0.03445365 | C38: 0.03445365 | D38: 0.03445365 | E38: 0.03445365 | F38: 0 | G38: 0 | H38: 0.1252664 | I38: 0.1252664 | J38: 1.0271565 | K38: 1.067212 | L38: 1.7610825 | M38: 1.7979816 | N38: 1.7876507 | O38: 1.7048911 | P38: 1.1771058 | Q38: 1.0838111 | R38: 1.6259248 | S38: 1.6082249 | T38: 1.5199593 | U38: 0.75871635 | V38: 0.3934472 | W38: 0.361697 | X38: 0.10118 | Y38: 0 | Z38: 0.98399423 | AA38: 1.4979347 | AB38: 0.52249997 | AC38: 1.0014763 | AD38: 0.75684951
A39: 92.5 - URBANA FM | B39: 0 | C39: 0 | D39: 0 | E39: 0 | F39: 0 | G39: 0 | H39: 0 | I39: 0.05243445 | J39: 0.47068155 | K39: 0.6244784 | L39: 0.6895407 | M39: 1.0604587 | N39: 1.0804961 | O39: 0.83805175 | P39: 0.628982 | Q39: 0.47711595 | R39: 0.85623805 | S39: 0.7341152 | T39: 0.30804945 | U39: 0.0588688 | V39: 0 | W39: 0 | X39: 0.10074955 | Y39: 0 | Z39: 0.48293231 | AA39: 0.7691665 | AB39: 0.077944633 | AC39: 0.44334781 | AD39: 0.33251086
A40: 93.1 - INOLVIDABLE | B40: 0.1338257 | C40: 0.1594558 | D40: 0.06999685 | E40: 0.1143636 | F40: 0.39302885 | G40: 0.12352375 | H40: 0.3949222 | I40: 0.94492585 | J40: 1.6487866 | K40: 2.3807572 | L40: 2.8323144 | M40: 3.5043793 | N40: 2.9885369 | O40: 2.8369969 | P40: 2.9865172 | Q40: 3.7889094 | R40: 3.6085307 | S40: 2.8038544 | T40: 2.8217712 | U40: 1.8944985 | V40: 1.1834674 | W40: 0.6536323 | X40: 0.4840097 | Y40: 0.23588105 | Z40: 1.9510142 | AA40: 3.1688909 | AB40: 1.21221 | AC40: 2.110705 | AD40: 1.6244536
A41: 93.9 - OCEANO | B41: 0 | C41: 0 | D41: 0 | E41: 0.01892345 | F41: 0.04838525 | G41: 0.04838525 | H41: 0.15186685 | I41: 0.3282105 | J41: 0.72565275 | K41: 0.81849635 | L41: 1.2590561 | M41: 1.344988 | N41: 1.2090736 | O41: 1.1736206 | P41: 0.9744809 | Q41: 0.83932885 | R41: 0.88764235 | S41: 0.7291771 | T41: 0.54539555 | U41: 0.6081477 | V41: 0.24292685 | W41: 0.0360217 | X41: 0.02031045 | Y41: 0 | Z41: 0.77137842 | AA41: 0.96888724 | AB41: 0.24213371 | AC41: 0.66079979 | AD41: 0.50042042
A42: 94.7 - DEL SUR | B42: 0 | C42: 0 | D42: 0 | E42: 0 | F42: 0 | G42: 0.1306878 | H42: 0.16617905 | I42: 0.16617905 | J42: 0.2332838 | K42: 0.0275367 | L42: 0.04331915 | M42: 0.1053059 | N42: 0.1465032 | O42: 0.05613155 | P42: 0.1593156 | Q42: 0.098637 | R42: 0.06745865 | S42: 0.1641604 | T42: 0.080779 | U42: 0.03117835 | V42: 0.03117835 | W42: 0.08934855 | X42: 0.08934855 | Y42: 0.20365275 | Z42: 0.12363394 | AA42: 0.11536773 | AB42: 0.087580925 | AC42: 0.10886087 | AD42: 0.087090975
A43: 95.5 - DEL PLATA | B43: 0.0577029 | C43: 0 | D43: 0 | E43: 0.13804905 | F43: 0.13804905 | G43: 0.04409725 | H43: 0.290311 | I43: 0.38550505 | J43: 0.8466725 | K43: 1.4251885 | L43: 2.0929871 | M43: 2.2630967 | N43: 2.3028462 | O43: 2.2148376 | P43: 1.9097461 | Q43: 1.7533902 | R43: 1.6178859 | S43: 1.4629382 | T43: 1.4220133 | U43: 0.98396515 | V43: 0.64331215 | W43: 0.4674725 | X43: 0.24245635 | Y43: 0.1374328 | Z43: 1.2172935 | AA43: 1.8769407 | AB43: 0.64944203 | AC43: 1.2478921 | AD43: 0.95166481
A44: 96.3 - ALFA | B44: 0.01892345 | C44: 0 | D44: 0 | E44: 0 | F44: 0 | G44: 0 | H44: 0 | I44: 0.01892345 | J44: 0.0689107 | K44: 0.0689107 | L44: 0.17689165 | M44: 0.25113635 | N44: 0.2913136 | O44: 0.18333265 | P44: 0.18366585 | Q44: 0.11784645 | R44: 0.13274935 | S44: 0.2047078 | T44: 0.0908819 | U44: 0.02581155 | V44: 0 | W44: 0 | X44: 0.01892345 | Y44: 0 | Z44: 0.097462142 | AA44: 0.18560262 | AB44: 0.022602817 | AC44: 0.10188919 | AD44: 0.077205371
A45: 97.1 - BABEL | B45: 0 | C45: 0 | D45: 0 | E45: 0 | F45: 0 | G45: 0 | H45: 0.03549125 | I45: 0.22314535 | J45: 0.2434558 | K45: 0.64700855 | L45: 0.7616072 | M45: 0.7262348 | N45: 0.6784809 | O45: 0.624121 | P45: 0.39835775 | Q45: 0.4033294 | R45: 0.32705355 | S45: 0.2531802 | T45: 0.43189105 | U45: 0.60638135 | V45: 0.675858 | W45: 0.3388873 | X45: 0.2241299 | Y45: 0.17474915 | Z45: 0.43949049 | AA45: 0.44742047 | AB45: 0.40864946 | AC45: 0.43185347 | AD45: 0.3238901
A46: 97.9 - M24 | B46: 0.03117835 | C46: 0.03117835 | D46: 0.03117835 | E46: 0 | F46: 0 | G46: 0.10971805 | H46: 0.3079251 | I46: 0.8656121 | J46: 1.3998466 | K46: 1.2786224 | L46: 1.2319715 | M46: 1.156283 | N46: 0.85668905 | O46: 0.4813885 | P46: 0.5131239 | Q46: 0.5552577 | R46: 0.48651995 | S46: 0.24218025 | T46: 0.2875236 | U46: 0.20339015 | V46: 0.06040515 | W46: 0.03188085 | X46: 0.03188085 | Y46: 0.0792089 | Z46: 1.0400434 | AA46: 0.52252656 | AB46: 0.11571492 | AC46: 0.55942831 | AD46: 0.42804011
... A62: RATING GENERAL | B62: 3.4811817 | C62: 2.5436069 | D62: 1.7554076 | E62: 1.6414239 | F62: 1.8804376 | G62: 4.0224306 | H62: 9.7992848 | I62: 22.142582 | J62: 33.669897 | K62: 41.15029 | L62: 43.496763 | M62: 42.781223 | N62: 37.305573 | O62: 36.071859 | P62: 34.79478 | Q62: 35.808692 | R62: 34.705726 | S62: 30.541984 | T62: 26.800261 | U62: 19.505653 | V62: 13.98999 | W62: 11.459452 | X62: 6.4900191 | Y62: 4.3179685 | Z62: 32.17334 | AA62: 34.871435 | AB62: 13.760557 | AC62: 26.935111 | AD62: 20.839854

Sheet RatxLDxABC1
A1: CUADRO 9: RESUMEN DE RATING POR HORA - SEGMENTO ABC1 | AM | LUNES A DOMINGO
A2: RADIOS | B2: HORAS | Z2: PROMEDIO
B3: 00:00 - 00:59 | C3: 01:00 - 01:59 | D3: 02:00 - 02:59 | E3: 03:00 - 03:59 | F3: 04:00 - 04:59 | G3: 05:00 - 05:59 | H3: 06:00 - 06:59 | I3: 07:00 - 07:59 | J3: 08:00 - 08:59 | K3: 09:00 - 09:59 | L3: 10:00 - 10:59 | M3: 11:00 - 11:59 | N3: 12:00 - 12:59 | O3: 13:00 - 13:59 | P3: 14:00 - 14:59 | Q3: 15:00 - 15:59 | R3: 16:00 - 16:59 | S3: 17:00 - 17:59 | T3: 18:00 - 18:59 | U3: 19:00 - 19:59 | V3: 20:00 - 20:59 | W3: 21:00 - 21:59 | X3: 22:00 - 22:59 | Y3: 23:00 - 23:59 | Z3: 06:00 - 11:59 | AA3: 12:00 - 17:59 | AB3: 18:00 - 23:59 | AC3: 06:00 - 23:59 | AD3: 00:00 - 24:00
A4: 610 - CX4 RURAL | B4: 0.24233382 | C4: 0.19265347 | D4: 0.16816829 | E4: 0 | F4: 0.10688131 | G4: 0 | H4: 0.17931212 | I4: 0.15948752 | J4: 0.13567993 | K4: 0.078396805 | L4: 0.018120615 | M4: 0 | N4: 0 | O4: 0 | P4: 0 | Q4: 0 | R4: 0 | S4: 0 | T4: 0 | U4: 0 | V4: 0 | W4: 0 | X4: 0 | Y4: 0 | Z4: 0.095166164 | AA4: 0 | AB4: 0 | AC4: 0.031722055 | AD4: 0.053376411
A5: 650 - CX6 CLÁSICA | B5: 0.096742013 | C5: 0.10030567 | D5: 0.16109319 | E5: 0.066514888 | F5: 0 | G5: 0 | H5: 0.16087034 | I5: 0.10058403 | J5: 0 | K5: 0.10529036 | L5: 0.10529036 | M5: 0.10529036 | N5: 0 | O5: 0 | P5: 0 | Q5: 0 | R5: 0 | S5: 0 | T5: 0 | U5: 0 | V5: 0 | W5: 0.024485172 | X5: 0 | Y5: 0 | Z5: 0.096220906 | AA5: 0 | AB5: 0.004080862 | AC5: 0.033433923 | AD5: 0.042769432
A6: 690 - CX8 SARANDI | B6: 0 | C6: 0 | D6: 0 | E6: 0 | F6: 0.22402887 | G6: 1.0137604 | H6: 3.9321699 | I6: 6.2103292 | J6: 6.554422 | K6: 6.0075209 | L6: 5.4297961 | M6: 4.21176 | N6: 2.6817286 | O6: 1.0074008 | P6: 0.71404382 | Q6: 0.6546836 | R6: 0.34987058 | S6: 0.13518222 | T6: 0.89715286 | U6: 0.75270319 | V6: 0.063784027 | W6: 0.35992502 | X6: 0.56848674 | Y6: 0.48447143 | Z6: 5.3909997 | AA6: 0.92381827 | AB6: 0.52108721 | AC6: 2.2786351 | AD6: 1.7605508
A7: 730 - CX10 CONTINENTE | B7: 0 | C7: 0 | D7: 0 | E7: 0 | F7: 0 | G7: 0 | H7: 0 | I7: 0.10885057 | J7: 0.10885057 | K7: 0.17462821 | L7: 0.17462821 | M7: 0.10885057 | N7: 0.10885057 | O7: 0.10885057 | P7: 0 | Q7: 0 | R7: 0 | S7: 0 | T7: 0 | U7: 0 | V7: 0 | W7: 0 | X7: 0 | Y7: 0 | Z7: 0.11263469 | AA7: 0.036283524 | AB7: 0 | AC7: 0.049639405 | AD7: 0.037229553
A8: 770 - CX12 ORIENTAL | B8: 0.24066112 | C8: 0.04931736 | D8: 0.04931736 | E8: 0 | F8: 0 | G8: 0.022137734 | H8: 0.11380175 | I8: 0.67157511 | J8: 0.66611368 | K8: 0.26834792 | L8: 0.2863657 | M8: 0.31615877 | N8: 0.16042128 | O8: 0.10837119 | P8: 0.058817601 | Q8: 0.3847642 | R8: 0.068587342 | S8: 0 | T8: 0 | U8: 0.10189379 | V8: 0.10189379 | W8: 0.68233834 | X8: 0.63121905 | Y8: 0.11378475 | Z8: 0.38706049 | AA8: 0.13016027 | AB8: 0.27185495 | AC8: 0.26302524 | AD8: 0.21232866
A9: 810 - CX14 EL ESPECTADOR | B9: 0.25337113 | C9: 0.32778837 | D9: 0.11504828 | E9: 0.03983695 | F9: 0 | G9: 0 | H9: 0.065796745 | I9: 1.1070365 | J9: 1.8488539 | K9: 1.8705166 | L9: 1.5534866 | M9: 1.451493 | N9: 1.1170668 | O9: 2.2317508 | P9: 3.8054371 | Q9: 4.1612095 | R9: 1.2503912 | S9: 0.33159168 | T9: 0.29311483 | U9: 0.36307752 | V9: 0 | W9: 0.26202158 | X9: 0.16209482 | Y9: 0.16209482 | Z9: 1.3161972 | AA9: 2.1495745 | AB9: 0.20706726 | AC9: 1.2242797 | AD9: 0.94887828
A10: 850 - CX16 CARVE | B10: 0.31274129 | C10: 0.31274129 | D10: 0.13712688 | E10: 0 | F10: 0 | G10: 0.27258945 | H10: 0.75485901 | I10: 2.1530693 | J10: 0.68316769 | K10: 0.73442688 | L10: 0.43117752 | M10: 0.51783894 | N10: 0.51783894 | O10: 0.70635166 | P10: 0.74532321 | Q10: 0.61552176 | R10: 0.36545666 | S10: 0.1716308 | T10: 0.064431766 | U10: 0 | V10: 0 | W10: 0.28883357 | X10: 0.072098071 | Y10: 0.45527384 | Z10: 0.87908989 | AA10: 0.52035384 | AB10: 0.14677288 | AC10: 0.51540554 | AD10: 0.42968744
A11: 890 - CX18 SPORT 890 | B11: 0 | C11: 0 | D11: 0.10495708 | E11: 0.11984762 | F11: 0.11903532 | G11: 0.31543629 | H11: 0.14584641 | I11: 1.171648 | J11: 2.2667474 | K11: 1.6510726 | L11: 0.94504479 | M11: 0.77251959 | N11: 1.132687 | O11: 0.75663719 | P11: 0.82749078 | Q11: 0.90142574 | R11: 0.76490549 | S11: 0.13711646 | T11: 0.4433956 | U11: 0.12361597 | V11: 0.15591019 | W11: 0.24190133 | X11: 0.17478957 | Y11: 0.070756118 | Z11: 1.1588131 | AA11: 0.75337711 | AB11: 0.20172813 | AC11: 0.70463946 | AD11: 0.55594944
A12: 930 - CX20 MONTECARLO | B12: 0 | C12: 0 | D12: 0 | E12: 0 | F12: 0 | G12: 0.55929409 | H12: 0.99600952 | I12: 1.5437813 | J12: 1.4537885 | K12: 1.2321075 | L12: 1.4356926 | M12: 1.2167178 | N12: 1.0444115 | O12: 0.79755992 | P12: 0.41669289 | Q12: 0.27976884 | R12: 0.10583906 | S12: 0.45525841 | T12: 0.092906992 | U12: 0.092906992 | V12: 0 | W12: 0 | X12: 0.31653412 | Y12: 0.29420512 | Z12: 1.3130162 | AA12: 0.51658843 | AB12: 0.13275887 | AC12: 0.65412117 | AD12: 0.5138948
A13: 970 - CX22 UNIVERSAL | B13: 0.32727914 | C13: 0 | D13: 0 | E13: 0 | F13: 0 | G13: 0.081318083 | H13: 0 | I13: 0 | J13: 0 | K13: 0.1391701 | L13: 0.26982345 | M13: 0 | N13: 0.15503177 | O13: 0.59502514 | P13: 0 | Q13: 0.098653285 | R13: 0 | S13: 0 | T13: 0 | U13: 0 | V13: 0 | W13: 0 | X13: 0 | Y13: 0 | Z13: 0.068165592 | AA13: 0.1414517 | AB13: 0 | AC13: 0.06987243 | AD13: 0.069429207
A14: 1010 - CX24 LA 1010 AM | B14: 0 | C14: 0 | D14: 0 | E14: 0 | F14: 0 | G14: 0.12262767 | H14: 0.12262767 | I14: 0.38372333 | J14: 0.38372333 | K14: 0.03983695 | L14: 0 | M14: 0 | N14: 0.78746136 | O14: 0.48191561 | P14: 0.031818867 | Q14: 0.031818867 | R14: 0.24466287 | S14: 0.28281007 | T14: 1.3618455 | U14: 0.95502327 | V14: 0.47327932 | W14: 0 | X14: 0 | Y14: 0 | Z14: 0.15498521 | AA14: 0.31008127 | AB14: 0.46502468 | AC14: 0.31003039 | AD14: 0.23763228
A15: 1050 - CX26 RADIO URUGUAY | B15: 0 | C15: 0 | D15: 0 | E15: 0 | F15: 0 | G15: 0 | H15: 0 | I15: 0.11431712 | J15: 0.13203882 | K15: 0.13378541 | L15: 0.50708487 | M15: 0.13658119 | N15: 0.13292429 | O15: 0.37329946 | P15: 0.32756986 | Q15: 0.32756986 | R15: 0.37329946 | S15: 0.029311754 | T15: 0.54437661 | U15: 0.16386631 | V15: 0.16386631 | W15: 0.16386631 | X15: 0 | Y15: 0 | Z15: 0.17063457 | AA15: 0.26066245 | AB15: 0.17266259 | AC15: 0.20131987 | AD15: 0.1509899
... A30: RATING GENERAL | B30: 2.7609445 | C30: 1.2535135 | D30: 1.1407741 | E30: 0.31740464 | F30: 0.62298523 | G30: 3.3906333 | H30: 11.256625 | I30: 31.489722 | J30: 43.654334 | K30: 53.218969 | L30: 50.603781 | M30: 43.281258 | N30: 34.516666 | O30: 31.983402 | P30: 35.313755 | Q30: 38.23987 | R30: 33.626679 | S30: 26.619284 | T30: 25.912336 | U30: 18.459313 | V30: 10.024024 | W30: 8.6656585 | X30: 5.6021146 | Y30: 3.748583 | Z30: 38.917448 | AA30: 33.383276 | AB30: 12.068671 | AC30: 28.123132 | AD30: 21.48761
A32: CUADRO 10: RESUMEN DE RATING POR HORA - SEGMENTO ABC1 | FM | LUNES A DOMINGO
A33: RADIOS | B33: HORAS | Z33: PROMEDIO
